Workbook

Sheet 0 목차
A1: 게임전략_MVP_마케팅.xlsx — 목차
A2: 이 파일: 게임전략_MVP_마케팅.xlsx / 짝 파일: 시장조사.xlsx (시장·지역·매출·벤치마크 숫자 자료) · 시트 이름을 누르면 그 시트로 이동합니다. 회색 줄은 다음 단계에서 만들 '예정' 시트입니다.
A4: 그룹 | B4: 시트 이름 | C4: 한 줄 설명 | D4: 상태 | E4: 비고
A5: 0 안내 | B5: 0 목차 | C5: 이 시트 | D5: 완료
A6: 0 안내 | B6: 0-1 개요 | C6: 분석 범위·기준일·출처 모음 (시장조사 파일과 같은 내용) | D6: 완료
A7: 1 성공 비결 | B7: 1-1 점수 기준 | C7: 성공 점수 배점 가정값 (바꾸면 점수표가 자동 재계산) | D7: 완료
A8: 1 성공 비결 | B8: 1-2 성공 점수표 | C8: 12개 게임의 순위 기반 성공 점수 (수식 자동 계산) | D8: 완료
A9: 1 성공 비결 | B9: 1-3 성적표 카드 | C9: 게임별 쉬운 설명과 별점 카드 | D9: 완료
A10: 1 성공 비결 | B10: 1-4 성공 비결 해부 | C10: 12개 게임의 재미 루프·첫 1분·다시 오게 하는 장치 | D10: 완료
A11: 1 성공 비결 | B11: 1-5 성공 비결 확장 | C11: 장르 그룹별로 넓힌 게임 목록과 차트 근거 | D11: 완료
A12: 1 성공 비결 | B12: 1-6 공통점 분석 | C12: 26개 게임의 공통 요소 표와 요약 | D12: 완료
A13: 1 성공 비결 | B13: 1-7 성공 공식 TOP5 | C13: 공통점에서 뽑은 성공 공식 5가지 | D13: 완료
A14: 2 MVP | B14: 2-1 MVP 명세 | C14: 게임별 꼭 필요/있으면 좋음/나중에 기능 | D14: 완료
A15: 2 MVP | B15: 2-2 MVP 검증 목표 | C15: 리텐션 합격선·목표 (4-1 지역 벤치마크(참조)에서 가져옴) | D15: 완료
A16: 2 MVP | B16: 2-3 장르 연결(추정) | C16: 우리 장르 그룹 ↔ GameAnalytics 장르 연결 (4-3에서 가져옴) | D16: 완료
A17: 2 MVP | B17: 2-4 2인 개발 MVP 판단 | C17: 매출 Top100 + ③ 다운로드만 높은 게임 중 2명이 만들 수 있는 MVP 후보 (세부 장르 점수 → 게임 판정, 수식) | D17: 완료 | E17: 6단계-3에서 만듦
A18: 3 마케팅 | B18: 3-1 광고 대비 유입 | C18: 광고비 → 설치 수 → D1/D7/D30에 남는 사람 수 계산표 (CPI 출처표 + 4-1 리텐션) | D18: 완료 | E18: 6단계-3에서 만듦
A19: 3 마케팅 | B19: 3-2 광고 채널 분석 | C19: 유튜브·인스타·페이스북·틱톡·인플루언서 비교 (공개 자료 + 2인 팀 점수표) | D19: 완료 | E19: 6단계-3에서 만듦
A20: 3 마케팅 | B20: 3-3 후킹 영상 분석 | C20: Royal Match·MONOPOLY GO!·Magic Sort! 메타 광고의 후킹 유형·형식 빈도 (AdWhispr 분류) | D20: 완료 | E20: 6단계-3에서 만듦 · 처음 3초는 메타 광고 라이브러리 화면 판독(분석자)
A21: 3 마케팅 | B21: 3-4 마케팅 실행안 | C21: 우리 MVP용 단계별 지역·OS·채널·예산·소재·측정 지표 (분석자 제안) | D21: 완료 | E21: 6단계-3에서 만듦
A22: 3 마케팅 | B22: 3-5 광고 소재 해부 | C22: 영상 12개의 도파민(보상·긴장) 요소·영상 효과·구성 판독 + 사운드 체크리스트(사용자 기입) | D22: 완료 | E22: 6단계-3에서 만듦
A23: 3 마케팅 | B23: 3-6 광고 MVP 구성표 | C23: 우리 정렬 퍼즐용 15초·30초 광고 구간별 구성안 (분석자 제안) | D23: 완료 | E23: 6단계-3에서 만듦
A24: 4 참조용 복사본 | B24: 4-1 지역 벤치마크(참조) | C24: 2-2 MVP 검증 목표가 쓰는 표의 복사본 | D24: 완료 | E24: 원본: 시장조사.xlsx › 4-2 지역 벤치마크
A25: 4 참조용 복사본 | B25: 4-2 장르 차트 판독값(참조) | C25: 4-3이 계산에 쓰는 판독값의 복사본 | D25: 완료 | E25: 원본: 시장조사.xlsx › 4-3 장르 차트 판독값
A26: 4 참조용 복사본 | B26: 4-3 장르 판독 요약(참조) | C26: 2-3 장르 연결(추정)이 쓰는 표의 복사본 | D26: 완료 | E26: 원본: 시장조사.xlsx › 4-4 장르 판독 요약
A27: 4 참조용 복사본 | B27: 4-4 Google Play Top100(참조) | C27: 2-4가 세부 장르를 찾는 무료 Top100 표의 복사본 | D27: 완료 | E27: 원본: 시장조사.xlsx › 1-2 Google Play Top100
A28: 4 참조용 복사본 | B28: 4-5 매출 Top100(참조) | C28: 2-4가 쓰는 매출 Top100 장르 표의 복사본 | D28: 완료 | E28: 원본: 시장조사.xlsx › 3-2 매출 Top100
... A30: 4 참조용 복사본 | B30: 4-7 대륙별 OS 분포(참조) | C30: 3-4가 쓰는 OS 점유율·OS 출시 우선순위 표의 복사본 | D30: 완료 | E30: 원본: 시장조사.xlsx › 2-6 대륙별 OS 분포

Sheet 0-1 개요
A1: 모바일 게임 시장 분석 — 장르 분류 · 지역 비교 · 성공 비결 & MVP · 벤치마크
A3: 항목 | B3: 내용
A4: 분석 범위 | B4: 미국 App Store / Google Play 게임 카테고리 Top Free 1~100위
A5: App Store 기준일 | B5: 2026-10-03
A6: App Store 출처 | B6: GameDropDaily (Apple 공개 iTunes RSS 차트 기반) https://gamedropdaily.com/mobile/ · 퍼블리셔·국가 교차 확인: AppBrain https://www.appbrain.com/stats/appstore-rankings
A7: Google Play 기준일 | B7: 2026-10-04
A8: Google Play 출처 | B8: AppBrain 미국 Top Free Games https://www.appbrain.com/stats/google-play-rankings/top_free/game/us · 교차 확인: GameDropDaily https://gamedropdaily.com/android/
A9: 참고 | B9: 수집 시점 차이로 출처 간 순위가 1~5계단 다를 수 있음. Google Play 80위는 출처 페이지에서 누락되어 '확인 불가'로 표시.
A10: 장르 분류 | B10: 게임명, 스토어 카테고리, 공개 게임 정보 기반의 분석자 판단. 확신이 낮은 항목은 '비고'에 '확인 필요'로 표시하고 노란색으로 강조.
A11: 수정 방법 | B11: 시장조사.xlsx의 '1-1 App Store Top100' / '1-2 Google Play Top100' 시트의 '대분류', '세부 장르' 열을 수정하면 '1-3 장르 분포' 시트(시장조사.xlsx) 집계가 자동으로 갱신됨(COUNTIF 수식).
A12: 시트 구성 | B12: [0 안내] 0-1 개요 / [1 성공 비결] 1-1 점수 기준 · 1-2 성공 점수표 · 1-3 성적표 카드 · 1-4 성공 비결 해부 · 1-5 성공 비결 확장 · 1-6 공통점 분석 · 1-7 성공 공식 TOP5 / [2 MVP] 2-1 MVP 명세 · 2-2 MVP 검증 목표 · 2-3 장르 연결(추정) · 2-4 2인 개발 MVP 판단 / [3 마케팅] 3-1 광고 대비 유입 · 3-2 광고 채널 분석 · 3-3 후킹 영상 분석 · 3-4 마케팅 실행안 · 3-5 광고 소재 해부 · 3-6 광고 MVP 구성표 / [4 참조용 복사본] 4-1 지역 벤치마크(참조) · 4-2 장르 차트 판독값(참조) · 4-3 장르 판독 요약(참조) · 4-4 Google Play Top100(참조) · 4-5 매출 Top100(참조) · 4-6 매출-다운로드 비교(참조) · 4-7 대륙별 OS 분포(참조) ※ 시장·지역·매출·벤치마크 숫자 자료은(는) '시장조사.xlsx' 파일에 있음 (파일 사이 수식 연결 없음)
A13: 3단계 출처 | B13: GameAnalytics 2026·2025 벤치마크, AppsFlyer State of App Monetization 2026·Gaming App Marketing 2024, Appodeal Mobile Casual Benchmarks 2025. 출처 없는 수치는 '제외한 자료'에 기록.
A14: 2단계 출처 | B14: AppBrain 구글 플레이 매출 순위: 미국·한국 2026-10-03, 일본 2026-10-04, 브라질 2026-10-01. 외부 자료: Wikipedia(Free Fire). 별점·MVP 규모·인원·기간·게임 방식 일부는 분석자 추정.
... A22: 6단계-4 한계 | B22: App Store 매출 89~100위는 확인 불가(페이지에 없음). App Store 매출(10-06)과 구글 매출(10-04)은 날짜가 2일 다름. AppBrain이 옮겨 적은 설치 구간은 Google Play보다 늦을 수 있음(2026년 출시 10개 대조 중 3개 다름, 노란 칸). Tiki Smash!의 등록 월은 확인 불가. 2-6 표 B·C(대륙별 게이머 OS 비율·스토어별 매출)와 동남아 4개국 Top20은 다시 찾아봤지만 공개 자료가 없어 그대로 '확인 불가'. '확인 필요' 칸은 같은 부류끼리 묶어 원래 칸에 반영(0-2 I열) — 세부 장르가 분석자 판단인 칸은 노란색 유지.

Sheet 1-1 점수 기준
A1: 항목 | B1: 값 | C1: 설명
A2: 인기(무료 순위) 배점 | B2: 25 | C2: 6개국(미국·캐나다·브라질·멕시코·일본·한국) 구글 플레이 무료 순위
A3: 돈 버는 힘(매출 순위) 배점 | B3: 25 | C3: 4개국(미국·브라질·일본·한국) 구글 플레이 매출 순위
A4: 규모(누적 설치) 배점 | B4: 15 | C4: 10만 설치=0점, 10억 설치 이상=만점 (로그 비례)
A5: 만족도(평점) 배점 | B5: 15 | C5: 평점 3.5 이하=0점, 5.0=만점. 평점 미표시는 중간값(50%)
A6: 오래가는 힘 배점 | B6: 10 | C6: 출시 후 5년 이상 차트 유지 시 만점(1년당 20%)
A7: 따라 만들기 쉬움 배점 | B7: 10 | C7: MVP 규모 점수표(아래)를 따름
A8: 최고 시장 반영 비중 | B8: 0.6 | C8: 순위 점수 = 최고 시장 점수×0.6 + 전체 평균×0.4 (지역 챔피언이 손해 보지 않도록)
A9: 기준 연도 | B9: 2026 | C9: 오래가는 힘 계산 기준
A10: A+ 전설 기준(이상) | B10: 80 | C10: 초기 가이드의 90점은 모든 지역을 석권한 게임이 없어 80점으로 조정
A11: A 강자 기준(이상) | B11: 70 | C11: 초기 가이드의 75점에서 조정
A12: B 유망 기준(이상) | B12: 60 | C12: 그 미만은 C 도전자
A13: MVP 규모 S 점수 | B13: 10 | C13: 소규모: 2~4명, 2~3개월 내외(추정)
... A16: MVP 규모 XL 점수 | B16: 1 | C16: 초대형: 30명 이상, 1.5년 이상·서버/라이브 운영 필수(추정)
A18: 파란 글씨·노란 칸은 바꿀 수 있는 가정값입니다. 바꾸면 '성공 점수표'가 자동으로 다시 계산됩니다.

Sheet 1-2 성공 점수표
D1: 무료 순위 (구글 플레이, 빈칸=Top100 밖) | J1: 매출 순위 (구글 플레이, 빈칸=Top100 밖) | N1: 기본 정보 | R1: 점수 (자동 계산)
A2: 게임 | B2: 퍼블리셔 | C2: 장르 | D2: 미국 | E2: 캐나다 | F2: 브라질 | G2: 멕시코 | H2: 일본 | I2: 한국 | J2: 미국 | K2: 브라질 | L2: 일본 | M2: 한국 | N2: 누적 설치(GP) | O2: 평점 | P2: 출시연도(추정) | Q2: MVP 규모 | R2: 인기 /25 | S2: 돈 버는 힘 /25 | T2: 규모 /15 | U2: 만족도 /15 | V2: 오래가는 힘 /10 | W2: 따라 만들기 /10 | X2: 총점 /100 | Y2: 등급 | Z2: 순위
A3: Meowdoku | B3: Oakever Games | C3: 퍼즐 · 로직 | D3: 2 | E3: 1 | F3: 4 | G3: 39 | H3: 1 | I3: 18 | N3: 21000000 | O3: 4.7 | P3: 2026 | Q3: S | R3: ='1-1 점수 기준'!$B$2*('1-1 점수 기준'!$B$8*IF(COUNT(D3:I3)=0,0,(101-MIN(D3:I3))/100)+(1-'1-1 점수 기준'!$B$8)*(COUNT(D3:I3)*101-SUM(D3:I3))/100/6) -> 24.016667 | S3: ='1-1 점수 기준'!$B$3*('1-1 점수 기준'!$B$8*IF(COUNT(J3:M3)=0,0,(101-MIN(J3:M3))/100)+(1-'1-1 점수 기준'!$B$8)*(COUNT(J3:M3)*101-SUM(J3:M3))/100/4) -> 0 | T3: ='1-1 점수 기준'!$B$4*MAX(0,MIN(1,LOG10(N3/100000)/4)) -> 8.7083224 | U3: ='1-1 점수 기준'!$B$5*IF(O3="",0.5,MAX(0,MIN(1,(O3-3.5)/1.5))) -> 12 | V3: ='1-1 점수 기준'!$B$6*MAX(0,MIN(1,('1-1 점수 기준'!$B$9-P3)/5)) -> 0 | W3: ='1-1 점수 기준'!$B$7*INDEX('1-1 점수 기준'!$B$13:$B$16,MATCH("MVP 규모 "&Q3&" 점수",'1-1 점수 기준'!$A$13:$A$16,0))/10 -> 10 | X3: =SUM(R3:W3) -> 54.724989 | Y3: =IF(X3>='1-1 점수 기준'!$B$10,"A+ 전설",IF(X3>='1-1 점수 기준'!$B$11,"A 강자",IF(X3>='1-1 점수 기준'!$B$12,"B 유망","C 도전자"))) -> C 도전자 | Z3: =RANK(X3,$X$3:$X$14) -> 8
A4: Rotate Rings | B4: Nebula Studio | C4: 퍼즐 · 정렬 | D4: 1 | E4: 2 | F4: 8 | H4: 2 | I4: 5 | N4: 1900000 | O4: 4.8 | P4: 2026 | Q4: S | R4: ='1-1 점수 기준'!$B$2*('1-1 점수 기준'!$B$8*IF(COUNT(D4:I4)=0,0,(101-MIN(D4:I4))/100)+(1-'1-1 점수 기준'!$B$8)*(COUNT(D4:I4)*101-SUM(D4:I4))/100/6) -> 23.116667 | S4: ='1-1 점수 기준'!$B$3*('1-1 점수 기준'!$B$8*IF(COUNT(J4:M4)=0,0,(101-MIN(J4:M4))/100)+(1-'1-1 점수 기준'!$B$8)*(COUNT(J4:M4)*101-SUM(J4:M4))/100/4) -> 0 | T4: ='1-1 점수 기준'!$B$4*MAX(0,MIN(1,LOG10(N4/100000)/4)) -> 4.795326 | U4: ='1-1 점수 기준'!$B$5*IF(O4="",0.5,MAX(0,MIN(1,(O4-3.5)/1.5))) -> 13 | V4: ='1-1 점수 기준'!$B$6*MAX(0,MIN(1,('1-1 점수 기준'!$B$9-P4)/5)) -> 0 | W4: ='1-1 점수 기준'!$B$7*INDEX('1-1 점수 기준'!$B$13:$B$16,MATCH("MVP 규모 "&Q4&" 점수",'1-1 점수 기준'!$A$13:$A$16,0))/10 -> 10 | X4: =SUM(R4:W4) -> 50.911993 | Y4: =IF(X4>='1-1 점수 기준'!$B$10,"A+ 전설",IF(X4>='1-1 점수 기준'!$B$11,"A 강자",IF(X4>='1-1 점수 기준'!$B$12,"B 유망","C 도전자"))) -> C 도전자 | Z4: =RANK(X4,$X$3:$X$14) -> 10
A5: Block Blast! | B5: Hungry Studio | C5: 퍼즐 · 블록 | D5: 7 | E5: 7 | F5: 9 | G5: 4 | H5: 3 | I5: 8 | N5: 1100000000 | O5: 4.8 | P5: 2022 | Q5: S | R5: ='1-1 점수 기준'!$B$2*('1-1 점수 기준'!$B$8*IF(COUNT(D5:I5)=0,0,(101-MIN(D5:I5))/100)+(1-'1-1 점수 기준'!$B$8)*(COUNT(D5:I5)*101-SUM(D5:I5))/100/6) -> 24.166667 | S5: ='1-1 점수 기준'!$B$3*('1-1 점수 기준'!$B$8*IF(COUNT(J5:M5)=0,0,(101-MIN(J5:M5))/100)+(1-'1-1 점수 기준'!$B$8)*(COUNT(J5:M5)*101-SUM(J5:M5))/100/4) -> 0 | T5: ='1-1 점수 기준'!$B$4*MAX(0,MIN(1,LOG10(N5/100000)/4)) -> 15 | U5: ='1-1 점수 기준'!$B$5*IF(O5="",0.5,MAX(0,MIN(1,(O5-3.5)/1.5))) -> 13 | V5: ='1-1 점수 기준'!$B$6*MAX(0,MIN(1,('1-1 점수 기준'!$B$9-P5)/5)) -> 8 | W5: ='1-1 점수 기준'!$B$7*INDEX('1-1 점수 기준'!$B$13:$B$16,MATCH("MVP 규모 "&Q5&" 점수",'1-1 점수 기준'!$A$13:$A$16,0))/10 -> 10 | X5: =SUM(R5:W5) -> 70.166667 | Y5: =IF(X5>='1-1 점수 기준'!$B$10,"A+ 전설",IF(X5>='1-1 점수 기준'!$B$11,"A 강자",IF(X5>='1-1 점수 기준'!$B$12,"B 유망","C 도전자"))) -> A 강자 | Z5: =RANK(X5,$X$3:$X$14) -> 4
A6: Magic Sort! | B6: Grand Games | C6: 퍼즐 · 정렬 | D6: 11 | E6: 4 | F6: 50 | G6: 33 | H6: 36 | I6: 7 | J6: 56 | N6: 40000000 | O6: 4.5 | P6: 2024 | Q6: S | R6: ='1-1 점수 기준'!$B$2*('1-1 점수 기준'!$B$8*IF(COUNT(D6:I6)=0,0,(101-MIN(D6:I6))/100)+(1-'1-1 점수 기준'!$B$8)*(COUNT(D6:I6)*101-SUM(D6:I6))/100/6) -> 22.3 | S6: ='1-1 점수 기준'!$B$3*('1-1 점수 기준'!$B$8*IF(COUNT(J6:M6)=0,0,(101-MIN(J6:M6))/100)+(1-'1-1 점수 기준'!$B$8)*(COUNT(J6:M6)*101-SUM(J6:M6))/100/4) -> 7.875 | T6: ='1-1 점수 기준'!$B$4*MAX(0,MIN(1,LOG10(N6/100000)/4)) -> 9.757725 | U6: ='1-1 점수 기준'!$B$5*IF(O6="",0.5,MAX(0,MIN(1,(O6-3.5)/1.5))) -> 10 | V6: ='1-1 점수 기준'!$B$6*MAX(0,MIN(1,('1-1 점수 기준'!$B$9-P6)/5)) -> 4 | W6: ='1-1 점수 기준'!$B$7*INDEX('1-1 점수 기준'!$B$13:$B$16,MATCH("MVP 규모 "&Q6&" 점수",'1-1 점수 기준'!$A$13:$A$16,0))/10 -> 10 | X6: =SUM(R6:W6) -> 63.932725 | Y6: =IF(X6>='1-1 점수 기준'!$B$10,"A+ 전설",IF(X6>='1-1 점수 기준'!$B$11,"A 강자",IF(X6>='1-1 점수 기준'!$B$12,"B 유망","C 도전자"))) -> B 유망 | Z6: =RANK(X6,$X$3:$X$14) -> 6
A7: Bus Fever Party! | B7: Lumi Games | C7: 퍼즐 · 버스잼 | D7: 8 | E7: 6 | F7: 3 | G7: 2 | H7: 10 | I7: 38 | N7: 11000000 | O7: 4.3 | P7: 2025 | Q7: S | R7: ='1-1 점수 기준'!$B$2*('1-1 점수 기준'!$B$8*IF(COUNT(D7:I7)=0,0,(101-MIN(D7:I7))/100)+(1-'1-1 점수 기준'!$B$8)*(COUNT(D7:I7)*101-SUM(D7:I7))/100/6) -> 23.833333 | S7: ='1-1 점수 기준'!$B$3*('1-1 점수 기준'!$B$8*IF(COUNT(J7:M7)=0,0,(101-MIN(J7:M7))/100)+(1-'1-1 점수 기준'!$B$8)*(COUNT(J7:M7)*101-SUM(J7:M7))/100/4) -> 0 | T7: ='1-1 점수 기준'!$B$4*MAX(0,MIN(1,LOG10(N7/100000)/4)) -> 7.6552226 | U7: ='1-1 점수 기준'!$B$5*IF(O7="",0.5,MAX(0,MIN(1,(O7-3.5)/1.5))) -> 8 | V7: ='1-1 점수 기준'!$B$6*MAX(0,MIN(1,('1-1 점수 기준'!$B$9-P7)/5)) -> 2 | W7: ='1-1 점수 기준'!$B$7*INDEX('1-1 점수 기준'!$B$13:$B$16,MATCH("MVP 규모 "&Q7&" 점수",'1-1 점수 기준'!$A$13:$A$16,0))/10 -> 10 | X7: =SUM(R7:W7) -> 51.488556 | Y7: =IF(X7>='1-1 점수 기준'!$B$10,"A+ 전설",IF(X7>='1-1 점수 기준'!$B$11,"A 강자",IF(X7>='1-1 점수 기준'!$B$12,"B 유망","C 도전자"))) -> C 도전자 | Z7: =RANK(X7,$X$3:$X$14) -> 9
A8: Royal Match | B8: Dream Games | C8: 퍼즐 · 매치3+꾸미기 | D8: 42 | E8: 25 | H8: 16 | I8: 21 | J8: 4 | K8: 7 | L8: 23 | M8: 14 | N8: 370000000 | O8: 4.6 | P8: 2021 | Q8: M | R8: ='1-1 점수 기준'!$B$2*('1-1 점수 기준'!$B$8*IF(COUNT(D8:I8)=0,0,(101-MIN(D8:I8))/100)+(1-'1-1 점수 기준'!$B$8)*(COUNT(D8:I8)*101-SUM(D8:I8))/100/6) -> 17.75 | S8: ='1-1 점수 기준'!$B$3*('1-1 점수 기준'!$B$8*IF(COUNT(J8:M8)=0,0,(101-MIN(J8:M8))/100)+(1-'1-1 점수 기준'!$B$8)*(COUNT(J8:M8)*101-SUM(J8:M8))/100/4) -> 23.45 | T8: ='1-1 점수 기준'!$B$4*MAX(0,MIN(1,LOG10(N8/100000)/4)) -> 13.380756 | U8: ='1-1 점수 기준'!$B$5*IF(O8="",0.5,MAX(0,MIN(1,(O8-3.5)/1.5))) -> 11 | V8: ='1-1 점수 기준'!$B$6*MAX(0,MIN(1,('1-1 점수 기준'!$B$9-P8)/5)) -> 10 | W8: ='1-1 점수 기준'!$B$7*INDEX('1-1 점수 기준'!$B$13:$B$16,MATCH("MVP 규모 "&Q8&" 점수",'1-1 점수 기준'!$A$13:$A$16,0))/10 -> 7 | X8: =SUM(R8:W8) -> 82.580756 | Y8: =IF(X8>='1-1 점수 기준'!$B$10,"A+ 전설",IF(X8>='1-1 점수 기준'!$B$11,"A 강자",IF(X8>='1-1 점수 기준'!$B$12,"B 유망","C 도전자"))) -> A+ 전설 | Z8: =RANK(X8,$X$3:$X$14) -> 1
A9: Gossip Harbor | B9: Microfun | C9: 퍼즐 · 머지+스토리 | D9: 17 | E9: 13 | G9: 25 | H9: 8 | I9: 20 | J9: 5 | K9: 4 | L9: 16 | M9: 12 | N9: 91000000 | O9: 4.3 | P9: 2022 | Q9: L | R9: ='1-1 점수 기준'!$B$2*('1-1 점수 기준'!$B$8*IF(COUNT(D9:I9)=0,0,(101-MIN(D9:I9))/100)+(1-'1-1 점수 기준'!$B$8)*(COUNT(D9:I9)*101-SUM(D9:I9))/100/6) -> 20.983333 | S9: ='1-1 점수 기준'!$B$3*('1-1 점수 기준'!$B$8*IF(COUNT(J9:M9)=0,0,(101-MIN(J9:M9))/100)+(1-'1-1 점수 기준'!$B$8)*(COUNT(J9:M9)*101-SUM(J9:M9))/100/4) -> 23.725 | T9: ='1-1 점수 기준'!$B$4*MAX(0,MIN(1,LOG10(N9/100000)/4)) -> 11.096405 | U9: ='1-1 점수 기준'!$B$5*IF(O9="",0.5,MAX(0,MIN(1,(O9-3.5)/1.5))) -> 8 | V9: ='1-1 점수 기준'!$B$6*MAX(0,MIN(1,('1-1 점수 기준'!$B$9-P9)/5)) -> 8 | W9: ='1-1 점수 기준'!$B$7*INDEX('1-1 점수 기준'!$B$13:$B$16,MATCH("MVP 규모 "&Q9&" 점수",'1-1 점수 기준'!$A$13:$A$16,0))/10 -> 4 | X9: =SUM(R9:W9) -> 75.804739 | Y9: =IF(X9>='1-1 점수 기준'!$B$10,"A+ 전설",IF(X9>='1-1 점수 기준'!$B$11,"A 강자",IF(X9>='1-1 점수 기준'!$B$12,"B 유망","C 도전자"))) -> A 강자 | Z9: =RANK(X9,$X$3:$X$14) -> 2
A10: MONOPOLY GO! | B10: Scopely | C10: 보드 · 주사위 소셜 | D10: 26 | E10: 21 | J10: 1 | K10: 73 | N10: 130000000 | O10: 4.6 | P10: 2023 | Q10: L | R10: ='1-1 점수 기준'!$B$2*('1-1 점수 기준'!$B$8*IF(COUNT(D10:I10)=0,0,(101-MIN(D10:I10))/100)+(1-'1-1 점수 기준'!$B$8)*(COUNT(D10:I10)*101-SUM(D10:I10))/100/6) -> 14.583333 | S10: ='1-1 점수 기준'!$B$3*('1-1 점수 기준'!$B$8*IF(COUNT(J10:M10)=0,0,(101-MIN(J10:M10))/100)+(1-'1-1 점수 기준'!$B$8)*(COUNT(J10:M10)*101-SUM(J10:M10))/100/4) -> 18.2 | T10: ='1-1 점수 기준'!$B$4*MAX(0,MIN(1,LOG10(N10/100000)/4)) -> 11.677288 | U10: ='1-1 점수 기준'!$B$5*IF(O10="",0.5,MAX(0,MIN(1,(O10-3.5)/1.5))) -> 11 | V10: ='1-1 점수 기준'!$B$6*MAX(0,MIN(1,('1-1 점수 기준'!$B$9-P10)/5)) -> 6 | W10: ='1-1 점수 기준'!$B$7*INDEX('1-1 점수 기준'!$B$13:$B$16,MATCH("MVP 규모 "&Q10&" 점수",'1-1 점수 기준'!$A$13:$A$16,0))/10 -> 4 | X10: =SUM(R10:W10) -> 65.460621 | Y10: =IF(X10>='1-1 점수 기준'!$B$10,"A+ 전설",IF(X10>='1-1 점수 기준'!$B$11,"A 강자",IF(X10>='1-1 점수 기준'!$B$12,"B 유망","C 도전자"))) -> B 유망 | Z10: =RANK(X10,$X$3:$X$14) -> 5
A11: Whiteout Survival | B11: Century Games | C11: 전략 · 4X | D11: 63 | H11: 28 | I11: 48 | J11: 10 | K11: 23 | L11: 9 | M11: 6 | N11: 100000000 | O11: 4.1 | P11: 2023 | Q11: XL | R11: ='1-1 점수 기준'!$B$2*('1-1 점수 기준'!$B$8*IF(COUNT(D11:I11)=0,0,(101-MIN(D11:I11))/100)+(1-'1-1 점수 기준'!$B$8)*(COUNT(D11:I11)*101-SUM(D11:I11))/100/6) -> 13.683333 | S11: ='1-1 점수 기준'!$B$3*('1-1 점수 기준'!$B$8*IF(COUNT(J11:M11)=0,0,(101-MIN(J11:M11))/100)+(1-'1-1 점수 기준'!$B$8)*(COUNT(J11:M11)*101-SUM(J11:M11))/100/4) -> 23.15 | T11: ='1-1 점수 기준'!$B$4*MAX(0,MIN(1,LOG10(N11/100000)/4)) -> 11.25 | U11: ='1-1 점수 기준'!$B$5*IF(O11="",0.5,MAX(0,MIN(1,(O11-3.5)/1.5))) -> 6 | V11: ='1-1 점수 기준'!$B$6*MAX(0,MIN(1,('1-1 점수 기준'!$B$9-P11)/5)) -> 6 | W11: ='1-1 점수 기준'!$B$7*INDEX('1-1 점수 기준'!$B$13:$B$16,MATCH("MVP 규모 "&Q11&" 점수",'1-1 점수 기준'!$A$13:$A$16,0))/10 -> 1 | X11: =SUM(R11:W11) -> 61.083333 | Y11: =IF(X11>='1-1 점수 기준'!$B$10,"A+ 전설",IF(X11>='1-1 점수 기준'!$B$11,"A 강자",IF(X11>='1-1 점수 기준'!$B$12,"B 유망","C 도전자"))) -> B 유망 | Z11: =RANK(X11,$X$3:$X$14) -> 7
A12: Free Fire | B12: Garena | C12: 액션 · 배틀로얄 | D12: 97 | F12: 2 | G12: 3 | J12: 22 | K12: 1 | N12: 2200000000 | O12: 4.3 | P12: 2017 | Q12: XL | R12: ='1-1 점수 기준'!$B$2*('1-1 점수 기준'!$B$8*IF(COUNT(D12:I12)=0,0,(101-MIN(D12:I12))/100)+(1-'1-1 점수 기준'!$B$8)*(COUNT(D12:I12)*101-SUM(D12:I12))/100/6) -> 18.2 | S12: ='1-1 점수 기준'!$B$3*('1-1 점수 기준'!$B$8*IF(COUNT(J12:M12)=0,0,(101-MIN(J12:M12))/100)+(1-'1-1 점수 기준'!$B$8)*(COUNT(J12:M12)*101-SUM(J12:M12))/100/4) -> 19.475 | T12: ='1-1 점수 기준'!$B$4*MAX(0,MIN(1,LOG10(N12/100000)/4)) -> 15 | U12: ='1-1 점수 기준'!$B$5*IF(O12="",0.5,MAX(0,MIN(1,(O12-3.5)/1.5))) -> 8 | V12: ='1-1 점수 기준'!$B$6*MAX(0,MIN(1,('1-1 점수 기준'!$B$9-P12)/5)) -> 10 | W12: ='1-1 점수 기준'!$B$7*INDEX('1-1 점수 기준'!$B$13:$B$16,MATCH("MVP 규모 "&Q12&" 점수",'1-1 점수 기준'!$A$13:$A$16,0))/10 -> 1 | X12: =SUM(R12:W12) -> 71.675 | Y12: =IF(X12>='1-1 점수 기준'!$B$10,"A+ 전설",IF(X12>='1-1 점수 기준'!$B$11,"A 강자",IF(X12>='1-1 점수 기준'!$B$12,"B 유망","C 도전자"))) -> A 강자 | Z12: =RANK(X12,$X$3:$X$14) -> 3
A13: 치이카와 포켓 | B13: Applibot | C13: 캐릭터 IP | H13: 20 | I13: 39 | L13: 81 | N13: 1100000 | P13: 2025 | Q13: L | R13: ='1-1 점수 기준'!$B$2*('1-1 점수 기준'!$B$8*IF(COUNT(D13:I13)=0,0,(101-MIN(D13:I13))/100)+(1-'1-1 점수 기준'!$B$8)*(COUNT(D13:I13)*101-SUM(D13:I13))/100/6) -> 14.533333 | S13: ='1-1 점수 기준'!$B$3*('1-1 점수 기준'!$B$8*IF(COUNT(J13:M13)=0,0,(101-MIN(J13:M13))/100)+(1-'1-1 점수 기준'!$B$8)*(COUNT(J13:M13)*101-SUM(J13:M13))/100/4) -> 3.5 | T13: ='1-1 점수 기준'!$B$4*MAX(0,MIN(1,LOG10(N13/100000)/4)) -> 3.9052226 | U13: ='1-1 점수 기준'!$B$5*IF(O13="",0.5,MAX(0,MIN(1,(O13-3.5)/1.5))) -> 7.5 | V13: ='1-1 점수 기준'!$B$6*MAX(0,MIN(1,('1-1 점수 기준'!$B$9-P13)/5)) -> 2 | W13: ='1-1 점수 기준'!$B$7*INDEX('1-1 점수 기준'!$B$13:$B$16,MATCH("MVP 규모 "&Q13&" 점수",'1-1 점수 기준'!$A$13:$A$16,0))/10 -> 4 | X13: =SUM(R13:W13) -> 35.438556 | Y13: =IF(X13>='1-1 점수 기준'!$B$10,"A+ 전설",IF(X13>='1-1 점수 기준'!$B$11,"A 강자",IF(X13>='1-1 점수 기준'!$B$12,"B 유망","C 도전자"))) -> C 도전자 | Z13: =RANK(X13,$X$3:$X$14) -> 12
A14: 후더덕 서바이벌 | B14: Joy Nice Games | C14: 방치형 RPG | I14: 2 | M14: 20 | N14: 190000 | P14: 2026 | Q14: M | R14: ='1-1 점수 기준'!$B$2*('1-1 점수 기준'!$B$8*IF(COUNT(D14:I14)=0,0,(101-MIN(D14:I14))/100)+(1-'1-1 점수 기준'!$B$8)*(COUNT(D14:I14)*101-SUM(D14:I14))/100/6) -> 16.5 | S14: ='1-1 점수 기준'!$B$3*('1-1 점수 기준'!$B$8*IF(COUNT(J14:M14)=0,0,(101-MIN(J14:M14))/100)+(1-'1-1 점수 기준'!$B$8)*(COUNT(J14:M14)*101-SUM(J14:M14))/100/4) -> 14.175 | T14: ='1-1 점수 기준'!$B$4*MAX(0,MIN(1,LOG10(N14/100000)/4)) -> 1.045326 | U14: ='1-1 점수 기준'!$B$5*IF(O14="",0.5,MAX(0,MIN(1,(O14-3.5)/1.5))) -> 7.5 | V14: ='1-1 점수 기준'!$B$6*MAX(0,MIN(1,('1-1 점수 기준'!$B$9-P14)/5)) -> 0 | W14: ='1-1 점수 기준'!$B$7*INDEX('1-1 점수 기준'!$B$13:$B$16,MATCH("MVP 규모 "&Q14&" 점수",'1-1 점수 기준'!$A$13:$A$16,0))/10 -> 7 | X14: =SUM(R14:W14) -> 46.220326 | Y14: =IF(X14>='1-1 점수 기준'!$B$10,"A+ 전설",IF(X14>='1-1 점수 기준'!$B$11,"A 강자",IF(X14>='1-1 점수 기준'!$B$12,"B 유망","C 도전자"))) -> C 도전자 | Z14: =RANK(X14,$X$3:$X$14) -> 11
A16: 출처: AppBrain 국가별 Google Play 순위 — 무료: 미국·캐나다·브라질·일본 2026-10-04, 한국 10-03, 멕시코 09-25 / 매출: 미국·한국 10-03, 일본 10-04, 브라질 10-01.
A17: 누적 설치·평점: AppBrain 표기값(구글 플레이). 치이카와 포켓은 일본판 기준, 평점 미표시(빈칸)는 만족도 중간값 처리.
A18: 출시연도는 공개 정보·앱 ID 기반 추정치이며, MVP 규모는 분석자 판단(추정)입니다. 파란 글씨는 입력값입니다.

Sheet 1-3 성적표 카드
A1: 게임 | B1: 한 줄 설명 | C1: 이렇게 생각하면 쉬워요 | D1: 🎮 재미 | E1: 👶 쉬움 | F1: 🔁 또 오기 | G1: 👫 친구 | H1: 💰 용돈 벌기 | I1: 종합 등급 | J1: 총점 | K1: 이 게임의 비밀 한 줄 | L1: 재미(입력) | M1: 쉬움(입력) | N1: 또오기(입력) | O1: 친구(입력) | P1: 용돈(입력)
A2: Meowdoku | B2: 고양이 그림으로 칸을 채우는 스도쿠 같은 논리 퍼즐 (게임명·장르 기반 추정) | C2: 고양이 스티커로 하는 숫자 없는 스도쿠 | D2: =REPT("★",L2)&REPT("☆",5-L2) -> ★★★★☆ | E2: =REPT("★",M2)&REPT("☆",5-M2) -> ★★★★☆ | F2: =REPT("★",N2)&REPT("☆",5-N2) -> ★★★★☆ | G2: =REPT("★",O2)&REPT("☆",5-O2) -> ★☆☆☆☆ | H2: =REPT("★",P2)&REPT("☆",5-P2) -> ★★☆☆☆ | I2: =INDEX('1-2 성공 점수표'!$Y$3:$Y$14,MATCH(A2,'1-2 성공 점수표'!$A$3:$A$14,0)) -> C 도전자 | J2: =INDEX('1-2 성공 점수표'!$X$3:$X$14,MATCH(A2,'1-2 성공 점수표'!$A$3:$A$14,0)) -> 54.724989 | K2: 어려운 스도쿠를 귀여운 고양이로 포장해 문턱을 낮췄어요. 6개국 모두 상위권(일본·캐나다 1위). | L2: 4 | M2: 4 | N2: 4 | O2: 1 | P2: 2
A3: Rotate Rings | B3: 고리를 돌려 같은 색끼리 모으는 정렬 퍼즐 (게임명 기반 추정) | C3: 색깔 고리를 돌리는 큐브 맞추기 | D3: =REPT("★",L3)&REPT("☆",5-L3) -> ★★★★☆ | E3: =REPT("★",M3)&REPT("☆",5-M3) -> ★★★★★ | F3: =REPT("★",N3)&REPT("☆",5-N3) -> ★★★☆☆ | G3: =REPT("★",O3)&REPT("☆",5-O3) -> ★☆☆☆☆ | H3: =REPT("★",P3)&REPT("☆",5-P3) -> ★★☆☆☆ | I3: =INDEX('1-2 성공 점수표'!$Y$3:$Y$14,MATCH(A3,'1-2 성공 점수표'!$A$3:$A$14,0)) -> C 도전자 | J3: =INDEX('1-2 성공 점수표'!$X$3:$X$14,MATCH(A3,'1-2 성공 점수표'!$A$3:$A$14,0)) -> 50.911993 | K3: 손가락 하나로 돌리기만 하면 '착착 정리되는' 쾌감. 미국 구글 플레이 무료 1위. | L3: 4 | M3: 5 | N3: 3 | O3: 1 | P3: 2
A4: Block Blast! | B4: 8×8 판에 블록 조각을 놓아 줄을 지우는 퍼즐 | C4: 끝나지 않는 테트리스 조각 맞추기 | D4: =REPT("★",L4)&REPT("☆",5-L4) -> ★★★★★ | E4: =REPT("★",M4)&REPT("☆",5-M4) -> ★★★★★ | F4: =REPT("★",N4)&REPT("☆",5-N4) -> ★★★★☆ | G4: =REPT("★",O4)&REPT("☆",5-O4) -> ★☆☆☆☆ | H4: =REPT("★",P4)&REPT("☆",5-P4) -> ★★★☆☆ | I4: =INDEX('1-2 성공 점수표'!$Y$3:$Y$14,MATCH(A4,'1-2 성공 점수표'!$A$3:$A$14,0)) -> A 강자 | J4: =INDEX('1-2 성공 점수표'!$X$3:$X$14,MATCH(A4,'1-2 성공 점수표'!$A$3:$A$14,0)) -> 70.166667 | K4: 레벨도 이야기도 없이 '한 판 더'만으로 설치 11억. 대신 매출 순위에는 없어서 광고로 돈을 버는 것으로 보여요. | L4: 5 | M4: 5 | N4: 4 | O4: 1 | P4: 3
A5: Magic Sort! | B5: 병 속 색깔 물을 옮겨 같은 색끼리 모으는 퍼즐 | C5: 색깔 주스 나눠 담기 | D5: =REPT("★",L5)&REPT("☆",5-L5) -> ★★★★☆ | E5: =REPT("★",M5)&REPT("☆",5-M5) -> ★★★★★ | F5: =REPT("★",N5)&REPT("☆",5-N5) -> ★★★☆☆ | G5: =REPT("★",O5)&REPT("☆",5-O5) -> ★☆☆☆☆ | H5: =REPT("★",P5)&REPT("☆",5-P5) -> ★★★☆☆ | I5: =INDEX('1-2 성공 점수표'!$Y$3:$Y$14,MATCH(A5,'1-2 성공 점수표'!$A$3:$A$14,0)) -> B 유망 | J5: =INDEX('1-2 성공 점수표'!$X$3:$X$14,MATCH(A5,'1-2 성공 점수표'!$A$3:$A$14,0)) -> 63.932725 | K5: 검증된 '물 정렬'을 예쁜 연출로 업그레이드. 퍼즐 신작 중 미국 매출 Top 100(56위)에 들어간 유일한 게임. | L5: 4 | M5: 5 | N5: 3 | O5: 1 | P5: 3
A6: Bus Fever Party! | B6: 승객을 같은 색 버스에 태워 보내는 버스잼 퍼즐 | C6: 색깔별로 줄 세우는 반장 놀이 | D6: =REPT("★",L6)&REPT("☆",5-L6) -> ★★★★☆ | E6: =REPT("★",M6)&REPT("☆",5-M6) -> ★★★★★ | F6: =REPT("★",N6)&REPT("☆",5-N6) -> ★★★☆☆ | G6: =REPT("★",O6)&REPT("☆",5-O6) -> ★☆☆☆☆ | H6: =REPT("★",P6)&REPT("☆",5-P6) -> ★★☆☆☆ | I6: =INDEX('1-2 성공 점수표'!$Y$3:$Y$14,MATCH(A6,'1-2 성공 점수표'!$A$3:$A$14,0)) -> C 도전자 | J6: =INDEX('1-2 성공 점수표'!$X$3:$X$14,MATCH(A6,'1-2 성공 점수표'!$A$3:$A$14,0)) -> 51.488556 | K6: 말이 필요 없는 규칙이라 남미에서도 2~3위. 국경이 없는 게임이에요. | L6: 4 | M6: 5 | N6: 3 | O6: 1 | P6: 2
A7: Royal Match | B7: 같은 그림 3개를 맞춰 별을 모으고, 별로 왕의 성을 꾸미는 게임 | C7: 사탕 맞추기 + 내 성 꾸미기 | D7: =REPT("★",L7)&REPT("☆",5-L7) -> ★★★★★ | E7: =REPT("★",M7)&REPT("☆",5-M7) -> ★★★★☆ | F7: =REPT("★",N7)&REPT("☆",5-N7) -> ★★★★★ | G7: =REPT("★",O7)&REPT("☆",5-O7) -> ★★★☆☆ | H7: =REPT("★",P7)&REPT("☆",5-P7) -> ★★★★★ | I7: =INDEX('1-2 성공 점수표'!$Y$3:$Y$14,MATCH(A7,'1-2 성공 점수표'!$A$3:$A$14,0)) -> A+ 전설 | J7: =INDEX('1-2 성공 점수표'!$X$3:$X$14,MATCH(A7,'1-2 성공 점수표'!$A$3:$A$14,0)) -> 82.580756 | K7: 익숙한 퍼즐에 최고급 연출과 '꾸미는 재미'를 더해 미국 매출 4위, 4개국 매출 모두 Top 25. | L7: 5 | M7: 4 | N7: 5 | O7: 3 | P7: 5
A8: Gossip Harbor | B8: 물건을 2개씩 합쳐 주문을 해결하면 드라마 같은 이야기가 이어지는 게임 | C8: 레고 합체 + 다음 화가 궁금한 드라마 | D8: =REPT("★",L8)&REPT("☆",5-L8) -> ★★★★★ | E8: =REPT("★",M8)&REPT("☆",5-M8) -> ★★★★☆ | F8: =REPT("★",N8)&REPT("☆",5-N8) -> ★★★★★ | G8: =REPT("★",O8)&REPT("☆",5-O8) -> ★★☆☆☆ | H8: =REPT("★",P8)&REPT("☆",5-P8) -> ★★★★★ | I8: =INDEX('1-2 성공 점수표'!$Y$3:$Y$14,MATCH(A8,'1-2 성공 점수표'!$A$3:$A$14,0)) -> A 강자 | J8: =INDEX('1-2 성공 점수표'!$X$3:$X$14,MATCH(A8,'1-2 성공 점수표'!$A$3:$A$14,0)) -> 75.804739 | K8: '합치는 손맛'과 '다음 이야기 궁금증'의 조합. 4개국 매출 모두 Top 16(브라질 4위). | L8: 5 | M8: 4 | N8: 5 | O8: 2 | P8: 5
A9: MONOPOLY GO! | B9: 주사위를 굴려 보드판을 돌며 내 도시를 짓는 게임 | C9: 온 가족이 아는 부루마불 + 스티커 앨범 모으기 | D9: =REPT("★",L9)&REPT("☆",5-L9) -> ★★★★★ | E9: =REPT("★",M9)&REPT("☆",5-M9) -> ★★★★★ | F9: =REPT("★",N9)&REPT("☆",5-N9) -> ★★★★★ | G9: =REPT("★",O9)&REPT("☆",5-O9) -> ★★★★★ | H9: =REPT("★",P9)&REPT("☆",5-P9) -> ★★★★★ | I9: =INDEX('1-2 성공 점수표'!$Y$3:$Y$14,MATCH(A9,'1-2 성공 점수표'!$A$3:$A$14,0)) -> B 유망 | J9: =INDEX('1-2 성공 점수표'!$X$3:$X$14,MATCH(A9,'1-2 성공 점수표'!$A$3:$A$14,0)) -> 65.460621 | K9: 누구나 아는 이름(IP) + 친구와 함께하는 이벤트로 미국 매출 1위. 하지만 일본·한국에서는 순위 밖이에요. | L9: 5 | M9: 5 | N9: 5 | O9: 5 | P9: 5
A10: Whiteout Survival | B10: 눈보라 속 마을을 키우고 동맹과 함께 싸우는 전략 게임 | C10: 눈 오는 날 우리 마을 키우기 + 반 대항전 | D10: =REPT("★",L10)&REPT("☆",5-L10) -> ★★★★☆ | E10: =REPT("★",M10)&REPT("☆",5-M10) -> ★★★☆☆ | F10: =REPT("★",N10)&REPT("☆",5-N10) -> ★★★★★ | G10: =REPT("★",O10)&REPT("☆",5-O10) -> ★★★★★ | H10: =REPT("★",P10)&REPT("☆",5-P10) -> ★★★★★ | I10: =INDEX('1-2 성공 점수표'!$Y$3:$Y$14,MATCH(A10,'1-2 성공 점수표'!$A$3:$A$14,0)) -> B 유망 | J10: =INDEX('1-2 성공 점수표'!$X$3:$X$14,MATCH(A10,'1-2 성공 점수표'!$A$3:$A$14,0)) -> 61.083333 | K10: 다운로드는 많지 않아도 4개국 매출 모두 Top 25(한국 6위). 열심히 하는 소수가 큰돈을 써요. | L10: 4 | M10: 3 | N10: 5 | O10: 5 | P10: 5
A11: Free Fire | B11: 여러 명이 섬에 떨어져 마지막까지 살아남는 짧은 총싸움 게임 | C11: 10분짜리 서바이벌 술래잡기 | D11: =REPT("★",L11)&REPT("☆",5-L11) -> ★★★★★ | E11: =REPT("★",M11)&REPT("☆",5-M11) -> ★★★★☆ | F11: =REPT("★",N11)&REPT("☆",5-N11) -> ★★★★★ | G11: =REPT("★",O11)&REPT("☆",5-O11) -> ★★★★★ | H11: =REPT("★",P11)&REPT("☆",5-P11) -> ★★★★☆ | I11: =INDEX('1-2 성공 점수표'!$Y$3:$Y$14,MATCH(A11,'1-2 성공 점수표'!$A$3:$A$14,0)) -> A 강자 | J11: =INDEX('1-2 성공 점수표'!$X$3:$X$14,MATCH(A11,'1-2 성공 점수표'!$A$3:$A$14,0)) -> 71.675 | K11: 성능 낮은 휴대폰에서도 잘 돌아가게 만들어 브라질 무료 2위·매출 1위. | L11: 5 | M11: 4 | N11: 5 | O11: 5 | P11: 4
A12: 치이카와 포켓 | B12: 인기 캐릭터 '치이카와'가 나오는 게임 (세부 게임 방식은 확인 필요) | C12: 좋아하는 캐릭터 스티커북 | D12: =REPT("★",L12)&REPT("☆",5-L12) -> ★★★☆☆ | E12: =REPT("★",M12)&REPT("☆",5-M12) -> ★★★★★ | F12: =REPT("★",N12)&REPT("☆",5-N12) -> ★★★★☆ | G12: =REPT("★",O12)&REPT("☆",5-O12) -> ★★★☆☆ | H12: =REPT("★",P12)&REPT("☆",5-P12) -> ★★★★☆ | I12: =INDEX('1-2 성공 점수표'!$Y$3:$Y$14,MATCH(A12,'1-2 성공 점수표'!$A$3:$A$14,0)) -> C 도전자 | J12: =INDEX('1-2 성공 점수표'!$X$3:$X$14,MATCH(A12,'1-2 성공 점수표'!$A$3:$A$14,0)) -> 35.438556 | K12: 캐릭터 팬이 곧 홍보대사. 일본 무료 20위·매출 81위, 한국에서도 39위. | L12: 3 | M12: 5 | N12: 4 | O12: 3 | P12: 4
A13: 후더덕 서바이벌 | B13: 켜두기만 해도 캐릭터가 자라는 방치형 RPG로 추정 (확인 필요) | C13: 저절로 크는 다마고치 + 뽑기 | D13: =REPT("★",L13)&REPT("☆",5-L13) -> ★★★☆☆ | E13: =REPT("★",M13)&REPT("☆",5-M13) -> ★★★★★ | F13: =REPT("★",N13)&REPT("☆",5-N13) -> ★★★★☆ | G13: =REPT("★",O13)&REPT("☆",5-O13) -> ★★☆☆☆ | H13: =REPT("★",P13)&REPT("☆",5-P13) -> ★★★★★ | I13: =INDEX('1-2 성공 점수표'!$Y$3:$Y$14,MATCH(A13,'1-2 성공 점수표'!$A$3:$A$14,0)) -> C 도전자 | J13: =INDEX('1-2 성공 점수표'!$X$3:$X$14,MATCH(A13,'1-2 성공 점수표'!$A$3:$A$14,0)) -> 46.220326 | K13: 게임 이름에 '777뽑기 증정'을 넣어 이름 자체가 광고. 한국 무료 2위·매출 20위. | L13: 3 | M13: 5 | N13: 4 | O13: 2 | P13: 5
A15: 별점(1~5)은 분석자 평가이며 L~P열(파란 글씨)을 바꾸면 별 표시가 자동으로 바뀝니다. 종합 등급·총점은 '성공 점수표'에서 가져옵니다.

Sheet 1-4 성공 비결 해부
A1: 게임 | B1: ① 핵심 재미 루프 | C1: ② 첫 1분 경험 | D1: ③ 다시 오게 하는 장치 | E1: ④ 수익 모델(BM) | F1: ⑤ 마케팅 | G1: ⑥ 아트 컨셉 | H1: 근거 수준
A2: Meowdoku | B2: 칸 고르기 → 규칙에 맞는 고양이 배치 → 판 완성 | C2: 작은 판으로 규칙을 자연스럽게 익히는 튜토리얼(추정) | D2: 레벨 진행, 점점 커지는 판(추정) | E2: 광고 중심 추정 — 6개국 무료 상위권이지만 매출 Top 100 진입 없음 | F2: 6개국 동시 무료 상위권 → 대규모 글로벌 UA 추정. 같은 회사(Oakever)가 Amaze GO!·Jigsawcard 등 다수 동시 운영 | G2: 귀여운 고양이 캐릭터, 밝고 깔끔한 화면(추정) | H2: 차트 데이터 + 장르 추정
A3: Rotate Rings | B3: 고리 회전 → 같은 색 정렬 → 한 줄 정리되는 쾌감 | C3: 한 번 돌려보면 바로 이해되는 단순 조작(추정) | D3: 레벨 진행(추정) | E3: 광고 중심 추정 — 매출 Top 100 진입 없음 | F3: 미국 무료 1위 등 신작 집중 UA 추정. 같은 회사(Nebula)의 Mahjong Blast·GOGO! Blast와 포트폴리오 운영 | G3: 단색 고리 위주의 미니멀 그래픽(추정) | H3: 차트 데이터 + 게임명 추정
A4: Block Blast! | B4: 블록 3개 받기 → 판에 배치 → 줄 지우기·콤보 | C4: 설명 없이 바로 시작 가능한 한 판 구조 | D4: 최고 점수 갱신, 콤보 연출의 손맛 | E4: 광고 중심(매출 Top 100 진입 없음)으로 추정 | F4: 설치 11억(구글 플레이) — 오래 쌓인 입소문과 꾸준한 UA | G4: 나무·보석 느낌의 블록, 단순한 판 | H4: 차트·설치 데이터 + 공개 게임 방식
A5: Magic Sort! | B5: 병 고르기 → 색 옮기기 → 한 병 완성 | C5: 워터소트 규칙(누구나 아는 방식)으로 즉시 이해 | D5: 레벨 진행, 난이도 곡선 | E5: 광고 + 인앱결제 혼합 추정 — 미국 매출 56위 | F5: 같은 회사(Grand Games)의 Block Out!과 함께 미국 상위권 | G5: 반짝이는 액체·마법 연출 | H5: 차트 데이터 + 공개 게임 방식
A6: Bus Fever Party! | B6: 승객 탭 → 같은 색 버스 탑승 → 버스 출발 | C6: 첫 판에서 바로 이해되는 색 맞추기 | D6: 레벨 진행(추정) | E6: 광고 중심 추정 — 매출 Top 100 진입 없음 | F6: 미국·캐나다·브라질·멕시코·일본 Top 10 — 언어 없이 통하는 광고 소재 추정 | G6: 장난감 같은 3D 버스와 승객(추정) | H6: 차트 데이터 + 장르 추정
A7: Royal Match | B7: 3개 맞추기 → 레벨 클리어로 별 획득 → 성 꾸미기 | C7: 짧고 쉬운 초반 레벨로 바로 성공 경험 | D7: 성 꾸미기(메타), 이벤트, 팀(공개 정보 기반) | E7: 목숨·부스터·코인 인앱결제, 시즌 패스 계열(공개 정보 기반) | F7: 왕 캐릭터를 활용한 광고 — 미국 매출 4위 | G7: 고급스러운 3D 카툰, 밝은 왕국 테마 | H7: 매출·차트 데이터 + 공개 게임 방식
A8: Gossip Harbor | B8: 아이템 2개 합치기 → 주문 해결 → 이야기 진행 | C8: 합치기 조작과 드라마 첫 장면을 함께 보여줌(추정) | D8: 다음 화가 궁금한 스토리, 장소 복원 | E8: 에너지·아이템 인앱결제(추정) — 미국 5·브라질 4·일본 16·한국 12위 매출 | F8: 스토리 장면을 앞세운 광고(추정). 같은 회사의 Seaside Escape·Flambé도 매출 Top 100 | G8: 드라마 같은 인물 일러스트 + 아기자기한 아이템 | H8: 매출·차트 데이터 + 장르 추정
A9: MONOPOLY GO! | B9: 주사위 굴리기 → 칸 이동·보상 → 도시 짓기 | C9: 누구나 아는 모노폴리 규칙 | D9: 스티커 앨범 수집, 친구와 함께하는 이벤트(공개 정보 기반) | E9: 주사위·이벤트 상품 인앱결제 — 미국 매출 1위 | F9: 유명 IP + 대규모 광고, 친구 초대·스티커 교환 | G9: 밝은 보드게임 카툰, 미스터 모노폴리 캐릭터 | H9: 매출·차트 데이터 + 공개 게임 방식
A10: Whiteout Survival | B10: 건물 짓기 → 자원 모으기 → 영웅 성장 → 동맹 전투 | C10: 광고와 다른 미니게임·생존 연출로 시작하는 경우 많음(추정) | D10: 동맹, 서버 경쟁, 매일 하는 일과 | E10: 영웅·가속 아이템 인앱결제 — 미국 10·브라질 23·일본 9·한국 6위 매출 | F10: 같은 회사(Century Games)의 Kingshot·Tasty Travels와 대규모 UA | G10: 얼어붙은 세계의 3D 리얼 카툰 | H10: 매출·차트 데이터 + 장르 일반 지식
A11: Free Fire | B11: 낙하 → 장비 줍기 → 전투 → 마지막 생존 | C11: 짧은 한 판, 빠른 매칭(공개 정보 기반) | D11: 랭크 시스템, 캐릭터 수집, 친구와 스쿼드 | E11: 캐릭터·스킨 인앱결제, 콜라보(예: NARUTO) — 브라질 매출 1위 | F11: 저사양 폰 최적화, 브라질·태국에서 투표 인기 1위 수상 이력 | G11: 캐릭터 중심 3D, 화려한 콜라보 스킨 | H11: 매출·차트 데이터 + 외부 자료(Wikipedia)
A12: 치이카와 포켓 | B12: 캐릭터와 함께 미니게임·수집(추정, 확인 필요) | C12: 좋아하는 캐릭터를 바로 만나는 경험(추정) | D12: 캐릭터 수집·꾸미기(추정) | E12: 인앱결제(추정) — 일본 매출 81위 | F12: 원작 캐릭터 팬덤 | G12: 원작 그림체 그대로 | H12: 차트 데이터 + 추정(게임 방식 미확인)
A13: 후더덕 서바이벌 | B13: 켜두기 → 자동 전투·성장 → 뽑기로 강화(추정) | C13: 초반에 대량 뽑기 지급으로 강해지는 느낌(추정) | D13: 방치 보상, 매일 뽑기(추정) | E13: 뽑기·성장 패키지 인앱결제(추정) — 한국 매출 20위 | F13: 앱 이름에 '777뽑기 증정'을 넣어 스토어 자체를 광고판으로 사용. 같은 회사(Joy Nice Games)가 Legend of Mushroom·갓깨비 키우기 운영 | G13: 귀여운 2D 캐릭터(추정) | H13: 차트 데이터 + 추정
A15: '추정'은 차트 데이터와 게임명·장르, 일반적으로 알려진 게임 방식을 바탕으로 한 판단입니다. 직접 플레이로 확인이 필요합니다.

Sheet 1-5 성공 비결 확장
A1: 장르 그룹 | B1: 게임 | C1: 퍼블리셔 | D1: 차트 근거 (이번 조사에서 확인된 순위) | E1: ① 핵심 재미 루프 | F1: ③ 다시 오게 하는 장치 | G1: ④ 수익 모델(BM) | H1: ⑤ 마케팅 | I1: ⑥ 아트 | J1: 근거 수준
A2: 1. 글로벌 퍼즐 | B2: Block Out! | C2: Grand Games | D2: 미국 App Store 무료 2위 | E2: 블록을 같은 색 출구로 빼내는 정렬 퍼즐(게임명 기반 추정) | F2: 레벨 진행(추정) | G2: 미확인 (App Store 매출 데이터 미수집) | H2: 같은 회사 Magic Sort!와 함께 미국 상위권 | I2: 색 블록 위주(추정) | J2: 차트 데이터 + 게임명 추정
A3: 1. 글로벌 퍼즐 | B3: Vita Mahjong | C3: Vita Studio | D3: 무료: 미국 5, 캐나다 9, 브라질 29, 멕시코 15, 일본 34, 한국 26 | E3: 같은 타일 2개 짝 맞춰 없애기 | F3: 레벨 진행(추정) | G3: 미확인 | H3: 6개국 모두 Top 35 — 언어가 필요 없는 규칙 | I3: 큰 타일·깔끔한 판(시니어 친화로 알려짐, 확인 권장) | J3: 차트 데이터 + 공개 정보(확인 권장)
A4: 2. 퍼즐 + 메타 | B4: Candy Crush Saga | C4: King | D4: 매출: 미국 3, 브라질 5 / 무료: 미국 GP 48 | E4: 3개 맞추기 → 레벨 클리어 → 지도 따라 전진 | F4: 긴 레벨 지도, 이벤트, 친구 점수 비교 | G4: 목숨·부스터·이동 추가 인앱결제 | H4: 오래된 브랜드 인지도 | I4: 사탕 테마의 밝은 2D | J4: 매출 데이터 + 공개 게임 방식
A5: 2. 퍼즐 + 메타 | B5: Royal Kingdom | C5: Dream Games | D5: 매출: 미국 8 / 무료: 일본 5, 한국 17, 미국 GP 47 | E5: 3개 맞추기 → 보상 → 왕국 건설(추정 세부) | F5: 왕국 건설 메타(추정) | G5: 인앱결제 (미국 매출 8위) | H5: Royal Match 개발사의 후속작 | I5: 3D 카툰 판타지 | J5: 매출 데이터 + 일부 추정
A6: 3. 소셜 캐주얼 | B6: Coin Master | C6: Moon Active | D6: 매출: 미국 7, 브라질 3 / 무료: 미국 iOS 67 | E6: 슬롯 돌리기 → 코인 → 마을 건설, 다른 유저 공격·습격 | F6: 카드 수집, 친구와 공격·복수, 이벤트 | G6: 스핀·코인 인앱결제 | H6: 친구 초대·SNS 연동(공개 정보) | I6: 바이킹 테마 카툰 | J6: 매출 데이터 + 공개 게임 방식
A7: 3. 소셜 캐주얼 | B7: Dice Dreams | C7: SuperPlay | D7: 무료: 미국 iOS 73, GP 98 | E7: 주사위 굴리기 → 보드 칸 보상 → 왕국 건설, 다른 유저 공격 | F7: 이벤트(공개 정보), 카드 수집 여부는 확인 필요 | G7: 인앱결제 (매출 순위 미확인) | H7: 같은 회사가 Disney Solitaire도 운영 | I7: 동화풍 카툰 | J7: 차트 데이터 + 공개 게임 방식
A8: 4. 전략(4X 등) | B8: Kingshot | C8: Century Games | D8: 매출: 미국 9 / 무료: 미국 iOS 40 | E8: 건설 → 자원 → 영웅 성장 → 동맹 전투(장르 일반) | F8: 동맹, 서버 경쟁(장르 일반) | G8: 인앱결제 (미국 매출 9위) | H8: 같은 회사 Whiteout Survival과 같은 장르 | I8: 3D 카툰(추정) | J8: 매출 데이터 + 장르 일반 지식
A9: 4. 전략(4X 등) | B9: Clash Royale | C9: Supercell | D9: 무료: 미국 iOS 80 (매출 미확인) | E9: 카드 덱 → 3분 실시간 1:1 대전 → 트로피 | F9: 아레나 승급, 클랜, 시즌 | G9: 패스·보석 인앱결제(공개 정보) | H9: Clash of Clans 세계관·캐릭터 재사용 | I9: 클래시 시리즈 카툰 | J9: 차트 데이터 + 공개 게임 방식
A10: 5. 액션·슈팅 | B10: Fortnite | C10: Epic Games | D10: 무료: 미국 iOS 18, GP 25 (매출 미확인) | E10: 낙하 → 장비 줍기 → 건축·전투 → 최후 생존 | F10: 배틀패스 시즌, 라이브 이벤트, 유저 제작 모드 | G10: 스킨·배틀패스 (외형 아이템) | H10: 대형 IP 콜라보 | I10: 밝은 카툰 3D | J10: 차트 데이터 + 공개 게임 방식
A11: 5. 액션·슈팅 | B11: Brawl Stars | C11: Supercell | D11: 매출: 브라질 9 / 무료: 미국 iOS 66 | E11: 3대3 짧은 대전 → 트로피 → 캐릭터(브롤러) 해금 | F11: 브롤러 수집, 클럽, 패스 | G11: 패스·스킨 인앱결제 | H11: Supercell 세계관 | I11: 캐주얼 카툰 | J11: 매출 데이터 + 공개 게임 방식
A12: 6. 캐릭터 IP | B12: Pokémon GO | C12: Scopely | D12: 무료: 한국 3, 미국 iOS 76 | E12: 걸어 다니며 포켓몬 발견 → 포획 → 수집 | F12: 레이드, 커뮤니티 이벤트(공개 정보) | G12: 아이템 인앱결제 | H12: 포켓몬 IP + 실외 활동 | I12: AR + 포켓몬 원작 그림 | J12: 차트 데이터 + 공개 게임 방식
... A15: 7. 한국식 RPG | B15: 트릭컬 리바이브 | C15: Epid Games | D15: 매출: 한국 7 / 무료: 한국 44 | E15: 캐릭터 뽑기 → 육성 → 전투(세부 확인 필요) | F15: 캐릭터 수집, 이벤트 | G15: 뽑기 인앱결제 | H15: 게임명에 '600뽑기 증정' 표기 | I15: 귀여운 2D 캐릭터(확인 권장) | J15: 매출 데이터 + 일부 추정
A17: 기존 12개 게임은 '1-4 성공 비결 해부' 시트에 있습니다. 확장 게임은 차트 데이터를 다시 모으지 않아 '1-2 성공 점수표'에는 넣지 않았습니다.

Sheet 1-6 공통점 분석
A1: 장르 그룹 | B1: 게임 | C1: 매출 Top100 진입 (4개국 중 1곳 이상) | D1: 한 손가락 단순 조작 | E1: 짧은 한 판(몇 분) | F1: 메타 진행(꾸미기·건설·스토리·성장) | G1: 수집 요소 | H1: 친구·동맹·대전(소셜) | I1: 유명 IP·콜라보 | J1: 랜덤 보상(뽑기·슬롯·카드팩) | K1: 광고 수익 중심 | L1: 인앱결제 중심 | M1: 라이브 이벤트·시즌
A2: 1. 글로벌 퍼즐 | B2: Meowdoku | C2: 아니오 | D2: 1 | E2: 1 | F2: ? | G2: ? | H2: ? | I2: 0 | J2: 0 | K2: 1 | L2: 0 | M2: ?
A3: 1. 글로벌 퍼즐 | B3: Rotate Rings | C3: 아니오 | D3: 1 | E3: 1 | F3: ? | G3: ? | H3: ? | I3: 0 | J3: 0 | K3: 1 | L3: 0 | M3: ?
A4: 1. 글로벌 퍼즐 | B4: Block Blast! | C4: 아니오 | D4: 1 | E4: 1 | F4: ? | G4: 0 | H4: 0 | I4: 0 | J4: 0 | K4: 1 | L4: 0 | M4: ?
A5: 1. 글로벌 퍼즐 | B5: Magic Sort! | C5: 예 | D5: 1 | E5: 1 | F5: ? | G5: ? | H5: ? | I5: 0 | J5: 0 | K5: 1 | L5: 1 | M5: ?
A6: 1. 글로벌 퍼즐 | B6: Bus Fever Party! | C6: 아니오 | D6: 1 | E6: 1 | F6: ? | G6: ? | H6: ? | I6: 0 | J6: 0 | K6: 1 | L6: 0 | M6: ?
A7: 1. 글로벌 퍼즐 | B7: Block Out! | C7: 미확인 | D7: 1 | E7: 1 | F7: ? | G7: ? | H7: ? | I7: 0 | J7: 0 | K7: ? | L7: ? | M7: ?
A8: 1. 글로벌 퍼즐 | B8: Vita Mahjong | C8: 미확인 | D8: 1 | E8: 1 | F8: ? | G8: ? | H8: ? | I8: 0 | J8: 0 | K8: ? | L8: ? | M8: ?
A9: 2. 퍼즐 + 메타 | B9: Royal Match | C9: 예 | D9: 1 | E9: 1 | F9: 1 | G9: ? | H9: 1 | I9: 0 | J9: 0 | K9: 0 | L9: 1 | M9: 1
A10: 2. 퍼즐 + 메타 | B10: Gossip Harbor | C10: 예 | D10: 1 | E10: 1 | F10: 1 | G10: ? | H10: ? | I10: 0 | J10: 0 | K10: 0 | L10: 1 | M10: ?
A11: 2. 퍼즐 + 메타 | B11: Candy Crush Saga | C11: 예 | D11: 1 | E11: 1 | F11: 1 | G11: 0 | H11: 1 | I11: 0 | J11: 0 | K11: 0 | L11: 1 | M11: 1
A12: 2. 퍼즐 + 메타 | B12: Royal Kingdom | C12: 예 | D12: 1 | E12: 1 | F12: 1 | G12: ? | H12: ? | I12: 0 | J12: 0 | K12: 0 | L12: 1 | M12: ?
A13: 3. 소셜 캐주얼 | B13: MONOPOLY GO! | C13: 예 | D13: 1 | E13: 1 | F13: 1 | G13: 1 | H13: 1 | I13: 1 | J13: 1 | K13: 0 | L13: 1 | M13: 1
A14: 3. 소셜 캐주얼 | B14: Coin Master | C14: 예 | D14: 1 | E14: 1 | F14: 1 | G14: 1 | H14: 1 | I14: ? | J14: 1 | K14: 0 | L14: 1 | M14: 1
A15: 3. 소셜 캐주얼 | B15: Dice Dreams | C15: 미확인 | D15: 1 | E15: 1 | F15: 1 | G15: ? | H15: 1 | I15: 0 | J15: 1 | K15: 0 | L15: 1 | M15: 1
A16: 4. 전략(4X 등) | B16: Whiteout Survival | C16: 예 | D16: 0 | E16: 0 | F16: 1 | G16: 1 | H16: 1 | I16: 0 | J16: 1 | K16: 0 | L16: 1 | M16: 1
A17: 4. 전략(4X 등) | B17: Kingshot | C17: 예 | D17: 0 | E17: 0 | F17: 1 | G17: 1 | H17: 1 | I17: 0 | J17: ? | K17: 0 | L17: 1 | M17: ?
A18: 4. 전략(4X 등) | B18: Clash Royale | C18: 미확인 | D18: 0 | E18: 1 | F18: 1 | G18: 1 | H18: 1 | I18: 0 | J18: 1 | K18: 0 | L18: 1 | M18: 1
A19: 5. 액션·슈팅 | B19: Free Fire | C19: 예 | D19: 0 | E19: 1 | F19: 1 | G19: 1 | H19: 1 | I19: 1 | J19: ? | K19: 0 | L19: 1 | M19: 1
A20: 5. 액션·슈팅 | B20: Fortnite | C20: 미확인 | D20: 0 | E20: 0 | F20: 1 | G20: 1 | H20: 1 | I20: 1 | J20: 0 | K20: 0 | L20: 1 | M20: 1
A21: 5. 액션·슈팅 | B21: Brawl Stars | C21: 예 | D21: 0 | E21: 1 | F21: 1 | G21: 1 | H21: 1 | I21: ? | J21: ? | K21: 0 | L21: 1 | M21: 1
A22: 6. 캐릭터 IP | B22: 치이카와 포켓 | C22: 예 | D22: ? | E22: ? | F22: ? | G22: ? | H22: ? | I22: 1 | J22: ? | K22: 0 | L22: ? | M22: ?
A23: 6. 캐릭터 IP | B23: Pokémon GO | C23: 미확인 | D23: 1 | E23: 1 | F23: 1 | G23: 1 | H23: 1 | I23: 1 | J23: 0 | K23: 0 | L23: 1 | M23: 1
A24: 6. 캐릭터 IP | B24: Pokémon TCG Pocket | C24: 미확인 | D24: 1 | E24: 1 | F24: ? | G24: 1 | H24: 1 | I24: 1 | J24: 1 | K24: 0 | L24: 1 | M24: ?
A25: 7. 한국식 RPG | B25: 후더덕 서바이벌 | C25: 예 | D25: ? | E25: ? | F25: 1 | G25: ? | H25: ? | I25: 0 | J25: 1 | K25: 0 | L25: 1 | M25: ?
A26: 7. 한국식 RPG | B26: 메이플스토리 방치형 RPG | C26: 예 | D26: 1 | E26: ? | F26: 1 | G26: ? | H26: 1 | I26: 1 | J26: 1 | K26: 0 | L26: 1 | M26: ?
A27: 7. 한국식 RPG | B27: 트릭컬 리바이브 | C27: 예 | D27: ? | E27: ? | F27: 1 | G27: 1 | H27: ? | I27: 0 | J27: 1 | K27: 0 | L27: 1 | M27: 1
A29: 공통점 요약 (자동 계산)
A30: 요소 | B30: '예' 게임 수 | C30: 확인된 게임 중 비율 | D30: 매출 진입 게임 중 비율 | E30: 매출 미진입 게임 중 비율 | F30: 차이(매출 진입 − 미진입)
A31: 한 손가락 단순 조작 | B31: =COUNTIF($D$2:$D$27,1) -> 17 | C31: =IFERROR(COUNTIF($D$2:$D$27,1)/(COUNTIF($D$2:$D$27,1)+COUNTIF($D$2:$D$27,0)),"-") -> 0.73913043 | D31: =IFERROR(COUNTIFS($D$2:$D$27,1,$C$2:$C$27,"예")/(COUNTIFS($D$2:$D$27,1,$C$2:$C$27,"예")+COUNTIFS($D$2:$D$27,0,$C$2:$C$27,"예")),"-") -> 0.66666667 | E31: =IFERROR(COUNTIFS($D$2:$D$27,1,$C$2:$C$27,"아니오")/(COUNTIFS($D$2:$D$27,1,$C$2:$C$27,"아니오")+COUNTIFS($D$2:$D$27,0,$C$2:$C$27,"아니오")),"-") -> 1 | F31: =IFERROR(D31-E31,"-") -> -0.33333333
A32: 짧은 한 판(몇 분) | B32: =COUNTIF($E$2:$E$27,1) -> 19 | C32: =IFERROR(COUNTIF($E$2:$E$27,1)/(COUNTIF($E$2:$E$27,1)+COUNTIF($E$2:$E$27,0)),"-") -> 0.86363636 | D32: =IFERROR(COUNTIFS($E$2:$E$27,1,$C$2:$C$27,"예")/(COUNTIFS($E$2:$E$27,1,$C$2:$C$27,"예")+COUNTIFS($E$2:$E$27,0,$C$2:$C$27,"예")),"-") -> 0.81818182 | E32: =IFERROR(COUNTIFS($E$2:$E$27,1,$C$2:$C$27,"아니오")/(COUNTIFS($E$2:$E$27,1,$C$2:$C$27,"아니오")+COUNTIFS($E$2:$E$27,0,$C$2:$C$27,"아니오")),"-") -> 1 | F32: =IFERROR(D32-E32,"-") -> -0.18181818
A33: 메타 진행(꾸미기·건설·스토리·성장) | B33: =COUNTIF($F$2:$F$27,1) -> 17 | C33: =IFERROR(COUNTIF($F$2:$F$27,1)/(COUNTIF($F$2:$F$27,1)+COUNTIF($F$2:$F$27,0)),"-") -> 1 | D33: =IFERROR(COUNTIFS($F$2:$F$27,1,$C$2:$C$27,"예")/(COUNTIFS($F$2:$F$27,1,$C$2:$C$27,"예")+COUNTIFS($F$2:$F$27,0,$C$2:$C$27,"예")),"-") -> 1 | E33: =IFERROR(COUNTIFS($F$2:$F$27,1,$C$2:$C$27,"아니오")/(COUNTIFS($F$2:$F$27,1,$C$2:$C$27,"아니오")+COUNTIFS($F$2:$F$27,0,$C$2:$C$27,"아니오")),"-") -> - | F33: =IFERROR(D33-E33,"-") -> -
A34: 수집 요소 | B34: =COUNTIF($G$2:$G$27,1) -> 11 | C34: =IFERROR(COUNTIF($G$2:$G$27,1)/(COUNTIF($G$2:$G$27,1)+COUNTIF($G$2:$G$27,0)),"-") -> 0.84615385 | D34: =IFERROR(COUNTIFS($G$2:$G$27,1,$C$2:$C$27,"예")/(COUNTIFS($G$2:$G$27,1,$C$2:$C$27,"예")+COUNTIFS($G$2:$G$27,0,$C$2:$C$27,"예")),"-") -> 0.875 | E34: =IFERROR(COUNTIFS($G$2:$G$27,1,$C$2:$C$27,"아니오")/(COUNTIFS($G$2:$G$27,1,$C$2:$C$27,"아니오")+COUNTIFS($G$2:$G$27,0,$C$2:$C$27,"아니오")),"-") -> 0 | F34: =IFERROR(D34-E34,"-") -> 0.875
A35: 친구·동맹·대전(소셜) | B35: =COUNTIF($H$2:$H$27,1) -> 14 | C35: =IFERROR(COUNTIF($H$2:$H$27,1)/(COUNTIF($H$2:$H$27,1)+COUNTIF($H$2:$H$27,0)),"-") -> 0.93333333 | D35: =IFERROR(COUNTIFS($H$2:$H$27,1,$C$2:$C$27,"예")/(COUNTIFS($H$2:$H$27,1,$C$2:$C$27,"예")+COUNTIFS($H$2:$H$27,0,$C$2:$C$27,"예")),"-") -> 1 | E35: =IFERROR(COUNTIFS($H$2:$H$27,1,$C$2:$C$27,"아니오")/(COUNTIFS($H$2:$H$27,1,$C$2:$C$27,"아니오")+COUNTIFS($H$2:$H$27,0,$C$2:$C$27,"아니오")),"-") -> 0 | F35: =IFERROR(D35-E35,"-") -> 1
A36: 유명 IP·콜라보 | B36: =COUNTIF($I$2:$I$27,1) -> 7 | C36: =IFERROR(COUNTIF($I$2:$I$27,1)/(COUNTIF($I$2:$I$27,1)+COUNTIF($I$2:$I$27,0)),"-") -> 0.29166667 | D36: =IFERROR(COUNTIFS($I$2:$I$27,1,$C$2:$C$27,"예")/(COUNTIFS($I$2:$I$27,1,$C$2:$C$27,"예")+COUNTIFS($I$2:$I$27,0,$C$2:$C$27,"예")),"-") -> 0.30769231 | E36: =IFERROR(COUNTIFS($I$2:$I$27,1,$C$2:$C$27,"아니오")/(COUNTIFS($I$2:$I$27,1,$C$2:$C$27,"아니오")+COUNTIFS($I$2:$I$27,0,$C$2:$C$27,"아니오")),"-") -> 0 | F36: =IFERROR(D36-E36,"-") -> 0.30769231
A37: 랜덤 보상(뽑기·슬롯·카드팩) | B37: =COUNTIF($J$2:$J$27,1) -> 9 | C37: =IFERROR(COUNTIF($J$2:$J$27,1)/(COUNTIF($J$2:$J$27,1)+COUNTIF($J$2:$J$27,0)),"-") -> 0.40909091 | D37: =IFERROR(COUNTIFS($J$2:$J$27,1,$C$2:$C$27,"예")/(COUNTIFS($J$2:$J$27,1,$C$2:$C$27,"예")+COUNTIFS($J$2:$J$27,0,$C$2:$C$27,"예")),"-") -> 0.54545455 | E37: =IFERROR(COUNTIFS($J$2:$J$27,1,$C$2:$C$27,"아니오")/(COUNTIFS($J$2:$J$27,1,$C$2:$C$27,"아니오")+COUNTIFS($J$2:$J$27,0,$C$2:$C$27,"아니오")),"-") -> 0 | F37: =IFERROR(D37-E37,"-") -> 0.54545455
A38: 광고 수익 중심 | B38: =COUNTIF($K$2:$K$27,1) -> 5 | C38: =IFERROR(COUNTIF($K$2:$K$27,1)/(COUNTIF($K$2:$K$27,1)+COUNTIF($K$2:$K$27,0)),"-") -> 0.20833333 | D38: =IFERROR(COUNTIFS($K$2:$K$27,1,$C$2:$C$27,"예")/(COUNTIFS($K$2:$K$27,1,$C$2:$C$27,"예")+COUNTIFS($K$2:$K$27,0,$C$2:$C$27,"예")),"-") -> 0.066666667 | E38: =IFERROR(COUNTIFS($K$2:$K$27,1,$C$2:$C$27,"아니오")/(COUNTIFS($K$2:$K$27,1,$C$2:$C$27,"아니오")+COUNTIFS($K$2:$K$27,0,$C$2:$C$27,"아니오")),"-") -> 1 | F38: =IFERROR(D38-E38,"-") -> -0.93333333
A39: 인앱결제 중심 | B39: =COUNTIF($L$2:$L$27,1) -> 19 | C39: =IFERROR(COUNTIF($L$2:$L$27,1)/(COUNTIF($L$2:$L$27,1)+COUNTIF($L$2:$L$27,0)),"-") -> 0.82608696 | D39: =IFERROR(COUNTIFS($L$2:$L$27,1,$C$2:$C$27,"예")/(COUNTIFS($L$2:$L$27,1,$C$2:$C$27,"예")+COUNTIFS($L$2:$L$27,0,$C$2:$C$27,"예")),"-") -> 1 | E39: =IFERROR(COUNTIFS($L$2:$L$27,1,$C$2:$C$27,"아니오")/(COUNTIFS($L$2:$L$27,1,$C$2:$C$27,"아니오")+COUNTIFS($L$2:$L$27,0,$C$2:$C$27,"아니오")),"-") -> 0 | F39: =IFERROR(D39-E39,"-") -> 1
A40: 라이브 이벤트·시즌 | B40: =COUNTIF($M$2:$M$27,1) -> 12 | C40: =IFERROR(COUNTIF($M$2:$M$27,1)/(COUNTIF($M$2:$M$27,1)+COUNTIF($M$2:$M$27,0)),"-") -> 1 | D40: =IFERROR(COUNTIFS($M$2:$M$27,1,$C$2:$C$27,"예")/(COUNTIFS($M$2:$M$27,1,$C$2:$C$27,"예")+COUNTIFS($M$2:$M$27,0,$C$2:$C$27,"예")),"-") -> 1 | E40: =IFERROR(COUNTIFS($M$2:$M$27,1,$C$2:$C$27,"아니오")/(COUNTIFS($M$2:$M$27,1,$C$2:$C$27,"아니오")+COUNTIFS($M$2:$M$27,0,$C$2:$C$27,"아니오")),"-") -> - | F40: =IFERROR(D40-E40,"-") -> -
A42: 장르 그룹별 '예' 개수 (자동 계산)
...

Sheet 1-7 성공 공식 TOP5
A1: 순위 | B1: 성공 공식 | C1: 쉽게 말하면 | D1: 근거
A2: 1 | B2: 3초 안에 이해되는 규칙 | C2: 설명서 없이 보자마자 할 수 있어야 해요 | D2: 6개국 무료 Top 10에 공통으로 오른 Block Blast·Meowdoku·Bus Fever Party·Rotate Rings 모두 한 손가락·한 규칙 게임
A3: 2 | B3: '많이 받는 게임'과 '돈 버는 게임'은 다르다 | C3: 인기 1등이 꼭 부자는 아니에요 | D3: 무료 상위 퍼즐 5개 중 매출 Top 100은 Magic Sort(미국 56위) 1개뿐. 반대로 Whiteout은 무료 순위가 낮아도 4개국 매출 Top 25
A4: 3 | B4: 퍼즐 + 꾸미기/이야기 = 돈 | C4: 퍼즐만 있으면 심심, 내 성·드라마가 있으면 계속 와요 | D4: Royal Match(성 꾸미기)·Gossip Harbor(스토리)가 퍼즐 장르로 4개국 매출 모두 Top 25
A5: 4 | B5: 같이 하면 오래 간다 | C5: 친구·동맹과 함께하면 그만두기 어려워요 | D5: MONOPOLY GO!(친구 이벤트) 미국 매출 1위, Whiteout(동맹) 한국 매출 6위, Free Fire(스쿼드) 브라질 매출 1위
A6: 5 | B6: 현지 사람이 아는 얼굴(IP)을 빌린다 | C6: 유명한 캐릭터가 나오면 처음부터 믿고 받아요 | D6: Free Fire x NARUTO, MONOPOLY, 치이카와(일본 무료 20위), Disney Solitaire
A8: 가장 작게 시작할 수 있는 MVP 순위
A10: 순위 | B10: 게임 | C10: MVP 규모 | D10: 이유
A11: 1 | B11: Block Blast! | C11: S | D11: 판 하나·규칙 하나, 레벨 제작도 필요 없음
A12: 2 | B12: Rotate Rings | C12: S | D12: 조작 하나 + 레벨 데이터
A13: 3 | B13: Bus Fever Party! | C13: S | D13: 색 매칭 규칙 + 레벨
A14: 4 | B14: Meowdoku | C14: S | D14: 논리 퍼즐 엔진 + 레벨 생성기
A15: 5 | B15: Magic Sort! | C15: S | D15: 검증된 규칙, 연출 품질이 관건
A16: 6 | B16: Royal Match | C16: M | D16: 매치3 엔진 + 꾸미기 메타
A17: 7 | B17: 후더덕 서바이벌 | C17: M | D17: 방치 루프 + 뽑기, 밸런스 작업 많음
A18: 8 | B18: Gossip Harbor | C18: L | D18: 스토리·아트 콘텐츠 양이 많음
A19: 9 | B19: MONOPOLY GO! | C19: L | D19: IP + 실시간 이벤트
A20: 10 | B20: 치이카와 포켓 | C20: L | D20: IP 라이선스 필수
A21: 11 | B21: Whiteout Survival | C21: XL | D21: 서버·라이브 운영·마케팅 비용
A22: 12 | B22: Free Fire | C22: XL | D22: 실시간 멀티플레이 서버

Sheet 2-1 MVP 명세
A1: 게임 | B1: 꼭 필요 (Must) | C1: 있으면 좋음 (Should) | D1: 나중에 (Later) | E1: MVP 규모 | F1: 예상 인원·기간(추정) | G1: 출시 전후 확인할 숫자(검증 지표) | H1: 만들 때 가장 어려운 점
A2: Meowdoku | B2: 논리 퍼즐 규칙 엔진 + 정답 검증기, 고양이 아트 세트, 레벨 100개+, 힌트·되돌리기 | C2: 보상형 광고·전면 광고, 일일 퍼즐 | D2: 고양이 도감 수집, 시즌 이벤트 | E2: S | F2: 2~4명 / 2~3개월 | G2: D1·D7 리텐션, 레벨 이탈 구간, 광고 시청 수 | H2: 풀 수 있으면서 너무 쉽지 않은 레벨 대량 생성
A3: Rotate Rings | B3: 고리 회전 조작 + 색 정렬 판정, 레벨 100개+, 손맛 연출(사운드·진동) | C3: 광고, 힌트 아이템 | D3: 테마 스킨, 이벤트 레벨 | E3: S | F3: 2~4명 / 2~3개월 | G3: D1 리텐션, 첫 10레벨 완료율, 광고 시청 수 | H3: 조작감(회전·스냅)의 기분 좋은 손맛
A4: Block Blast! | B4: 8×8 판 + 블록 생성 규칙, 줄 지우기·콤보, 최고 점수 | C4: 광고(이어하기 보상 등) | D4: 모드 추가(레벨형), 테마 | E4: S | F4: 2~3명 / 1~2개월 | G4: 세션당 판 수, D1·D30 리텐션, 광고 수익/유저 | H4: 블록이 '공정하게' 나오는 생성 규칙
A5: Magic Sort! | B5: 병·액체 정렬 규칙, 레벨 150개+, 액체 연출 | C5: 광고 + 소액 인앱(힌트·빈 병) | D5: 시즌 이벤트, 꾸미기 메타 | E5: S | F5: 3~4명 / 2~3개월 | G5: 레벨 이탈 구간, 광고·결제 비율 | H5: 레벨 난이도 곡선 설계
A6: Bus Fever Party! | B6: 버스·승객 색 매칭 규칙, 주차 공간 제한, 레벨 100개+ | C6: 광고, 부스터(대기열 늘리기 등) | D6: 이벤트·수집 | E6: S | F6: 2~4명 / 2~3개월 | G6: D1 리텐션, 레벨당 실패율 | H6: 막히는 순간과 풀리는 순간의 균형
A7: Royal Match | B7: 매치3 엔진, 장애물 5~8종, 레벨 100개+, 성 꾸미기 1구역 | C7: 코인 상점·부스터, 목숨 시스템 | D7: 팀(길드), 경쟁 이벤트, 시즌 패스 | E7: M | F7: 5~10명 / 4~8개월 | G7: D1·D7 리텐션, 레벨당 시도 횟수, 첫 결제 전환율 | H7: 매치3 '손맛'과 연출 품질 (이미 강자 다수)
A8: Gossip Harbor | B8: 머지 보드 + 아이템 체인, 주문 시스템, 스토리 1~2장, 에너지 | C8: 에너지·아이템 상점, 스토리 연출 강화 | D8: 시즌 이벤트, 새 지역·장 추가 | E8: L | F8: 10~20명 / 8~12개월 | G8: D7·D30 리텐션, 스토리 장 완료율, 결제 전환율 | H8: 스토리·아트 콘텐츠를 계속 만들어야 하는 제작량
A9: MONOPOLY GO! | B9: 주사위 보드 루프, 도시 짓기, 친구 연동(최소) | C9: 이벤트·스티커 앨범, 주사위 상점 | D9: 파트너 이벤트, 앨범 교환, 대형 IP 계약 | E9: L | F9: 15~25명 / 10~15개월 (IP 제외) | G9: D1·D30 리텐션, 친구 초대율, 이벤트 참여율, ARPDAU | H9: IP 없이는 같은 효과를 내기 어려움 + 실시간 이벤트 운영
A10: Whiteout Survival | B10: 도시 건설·자원 루프, 영웅 1차 세트, 서버·동맹 기본 기능 | C10: 영웅 뽑기·가속 상점, 일일 퀘스트 | D10: 동맹 전쟁, 시즌 서버, 대형 이벤트 | E10: XL | F10: 30명 이상 / 1.5년 이상 | G10: D30·D90 리텐션, 상위 결제자 비중, 동맹 가입률 | H10: 서버·밸런스·라이브 운영 + 매우 큰 마케팅 비용
A11: Free Fire | B11: 실시간 멀티플레이 서버, 매칭, 맵 1개, 무기·캐릭터 기본 세트, 저사양 최적화 | C11: 랭크, 스킨 상점 | D11: 콜라보, e스포츠, 신규 모드 | E11: XL | F11: 40명 이상 / 2년 이상 | G11: 동시 접속자, 매칭 대기시간, D7 리텐션 | H11: 실시간 서버 + 핵·부정행위 대응 + 저사양 최적화
A12: 치이카와 포켓 | B12: IP 라이선스 확보, 원작 그림체 캐릭터, 미니게임·수집 루프(추정) | C12: 꾸미기 아이템 상점 | D12: IP 이벤트, 굿즈 연동 | E12: L | F12: 10~20명 / 8~12개월 + IP 계약 | G12: 팬 유입 대비 D7 리텐션, 결제 전환율 | H12: IP 확보 비용과 원작사 승인 절차
A13: 후더덕 서바이벌 | B13: 방치 성장 루프, 자동 전투, 뽑기·장비 시스템, 초반 대량 뽑기 지급(추정) | C13: 성장 패키지 상점, 출석 보상 | D13: 길드·랭킹, 시즌 콘텐츠 | E13: M | F13: 5~10명 / 4~8개월 | G13: D1·D7 리텐션, 첫 결제 전환율, 결제자당 매출 | H13: 뽑기 확률·성장 밸런스와 확률 공시 등 규제 대응
A15: 인원·기간은 분석자 추정입니다. 검증 지표의 목표 수치는 출처가 확인된 값만 '2-2 MVP 검증 목표' 시트에 정리했습니다(장르별 리텐션은 공식 숫자 자료가 없어, 2025 보고서 이미지 차트를 읽은 '판독값'을 '4-3 장르 판독 요약(참조)' 시트에 따로 정리).

Sheet 2-2 MVP 검증 목표
D1: D1 리텐션 | G1: D7 리텐션 | J1: D30 리텐션 | M1: 수익 참고 (AppsFlyer, D90, 글로벌)
A2: 게임 | B2: 주 타깃 지역 | C2: 수익 장르 분류 | D2: 합격선: 전체 상위 25% | E2: 목표: 타깃 지역 상위 10% | F2: 지역 중앙값 | G2: 합격선: 전체 상위 25% | H2: 목표: 타깃 지역 상위 10% | I2: 지역 중앙값 | J2: 합격선: 전체 상위 25% | K2: 목표: 타깃 지역 상위 10% | L2: 지역 중앙값 | M2: IAP ARPU | N2: 광고 ARPU | O2: IAP ARPPU | P2: 장르별 리텐션
A3: Meowdoku | B3: 북미 | C3: 캐주얼 | D3: 30% 약간 상회 | E3: =SUMIFS('4-1 지역 벤치마크(참조)'!$D$2:$D$28,'4-1 지역 벤치마크(참조)'!$A$2:$A$28,$B3,'4-1 지역 벤치마크(참조)'!$B$2:$B$28,"D1 리텐션") -> 0.369 | F3: =SUMIFS('4-1 지역 벤치마크(참조)'!$C$2:$C$28,'4-1 지역 벤치마크(참조)'!$A$2:$A$28,$B3,'4-1 지역 벤치마크(참조)'!$B$2:$B$28,"D1 리텐션") -> 0.2328 | G3: 6~7% | H3: =SUMIFS('4-1 지역 벤치마크(참조)'!$D$2:$D$28,'4-1 지역 벤치마크(참조)'!$A$2:$A$28,$B3,'4-1 지역 벤치마크(참조)'!$B$2:$B$28,"D7 리텐션") -> 0.1258 | I3: =SUMIFS('4-1 지역 벤치마크(참조)'!$C$2:$C$28,'4-1 지역 벤치마크(참조)'!$A$2:$A$28,$B3,'4-1 지역 벤치마크(참조)'!$B$2:$B$28,"D7 리텐션") -> 0.0497 | J3: 1.6~1.8% | K3: =SUMIFS('4-1 지역 벤치마크(참조)'!$D$2:$D$28,'4-1 지역 벤치마크(참조)'!$A$2:$A$28,$B3,'4-1 지역 벤치마크(참조)'!$B$2:$B$28,"D30 리텐션") -> 0.0478 | L3: =SUMIFS('4-1 지역 벤치마크(참조)'!$C$2:$C$28,'4-1 지역 벤치마크(참조)'!$A$2:$A$28,$B3,'4-1 지역 벤치마크(참조)'!$B$2:$B$28,"D30 리텐션") -> 0.0118 | M3: 1.34 | N3: 0.55 | O3: 7.26 | P3: 미공개
A4: Rotate Rings | B4: 북미 | C4: 캐주얼 | D4: 30% 약간 상회 | E4: =SUMIFS('4-1 지역 벤치마크(참조)'!$D$2:$D$28,'4-1 지역 벤치마크(참조)'!$A$2:$A$28,$B4,'4-1 지역 벤치마크(참조)'!$B$2:$B$28,"D1 리텐션") -> 0.369 | F4: =SUMIFS('4-1 지역 벤치마크(참조)'!$C$2:$C$28,'4-1 지역 벤치마크(참조)'!$A$2:$A$28,$B4,'4-1 지역 벤치마크(참조)'!$B$2:$B$28,"D1 리텐션") -> 0.2328 | G4: 6~7% | H4: =SUMIFS('4-1 지역 벤치마크(참조)'!$D$2:$D$28,'4-1 지역 벤치마크(참조)'!$A$2:$A$28,$B4,'4-1 지역 벤치마크(참조)'!$B$2:$B$28,"D7 리텐션") -> 0.1258 | I4: =SUMIFS('4-1 지역 벤치마크(참조)'!$C$2:$C$28,'4-1 지역 벤치마크(참조)'!$A$2:$A$28,$B4,'4-1 지역 벤치마크(참조)'!$B$2:$B$28,"D7 리텐션") -> 0.0497 | J4: 1.6~1.8% | K4: =SUMIFS('4-1 지역 벤치마크(참조)'!$D$2:$D$28,'4-1 지역 벤치마크(참조)'!$A$2:$A$28,$B4,'4-1 지역 벤치마크(참조)'!$B$2:$B$28,"D30 리텐션") -> 0.0478 | L4: =SUMIFS('4-1 지역 벤치마크(참조)'!$C$2:$C$28,'4-1 지역 벤치마크(참조)'!$A$2:$A$28,$B4,'4-1 지역 벤치마크(참조)'!$B$2:$B$28,"D30 리텐션") -> 0.0118 | M4: 1.34 | N4: 0.55 | O4: 7.26 | P4: 미공개
A5: Block Blast! | B5: 북미 | C5: 캐주얼 | D5: 30% 약간 상회 | E5: =SUMIFS('4-1 지역 벤치마크(참조)'!$D$2:$D$28,'4-1 지역 벤치마크(참조)'!$A$2:$A$28,$B5,'4-1 지역 벤치마크(참조)'!$B$2:$B$28,"D1 리텐션") -> 0.369 | F5: =SUMIFS('4-1 지역 벤치마크(참조)'!$C$2:$C$28,'4-1 지역 벤치마크(참조)'!$A$2:$A$28,$B5,'4-1 지역 벤치마크(참조)'!$B$2:$B$28,"D1 리텐션") -> 0.2328 | G5: 6~7% | H5: =SUMIFS('4-1 지역 벤치마크(참조)'!$D$2:$D$28,'4-1 지역 벤치마크(참조)'!$A$2:$A$28,$B5,'4-1 지역 벤치마크(참조)'!$B$2:$B$28,"D7 리텐션") -> 0.1258 | I5: =SUMIFS('4-1 지역 벤치마크(참조)'!$C$2:$C$28,'4-1 지역 벤치마크(참조)'!$A$2:$A$28,$B5,'4-1 지역 벤치마크(참조)'!$B$2:$B$28,"D7 리텐션") -> 0.0497 | J5: 1.6~1.8% | K5: =SUMIFS('4-1 지역 벤치마크(참조)'!$D$2:$D$28,'4-1 지역 벤치마크(참조)'!$A$2:$A$28,$B5,'4-1 지역 벤치마크(참조)'!$B$2:$B$28,"D30 리텐션") -> 0.0478 | L5: =SUMIFS('4-1 지역 벤치마크(참조)'!$C$2:$C$28,'4-1 지역 벤치마크(참조)'!$A$2:$A$28,$B5,'4-1 지역 벤치마크(참조)'!$B$2:$B$28,"D30 리텐션") -> 0.0118 | M5: 1.34 | N5: 0.55 | O5: 7.26 | P5: 미공개
A6: Magic Sort! | B6: 북미 | C6: 캐주얼 | D6: 30% 약간 상회 | E6: =SUMIFS('4-1 지역 벤치마크(참조)'!$D$2:$D$28,'4-1 지역 벤치마크(참조)'!$A$2:$A$28,$B6,'4-1 지역 벤치마크(참조)'!$B$2:$B$28,"D1 리텐션") -> 0.369 | F6: =SUMIFS('4-1 지역 벤치마크(참조)'!$C$2:$C$28,'4-1 지역 벤치마크(참조)'!$A$2:$A$28,$B6,'4-1 지역 벤치마크(참조)'!$B$2:$B$28,"D1 리텐션") -> 0.2328 | G6: 6~7% | H6: =SUMIFS('4-1 지역 벤치마크(참조)'!$D$2:$D$28,'4-1 지역 벤치마크(참조)'!$A$2:$A$28,$B6,'4-1 지역 벤치마크(참조)'!$B$2:$B$28,"D7 리텐션") -> 0.1258 | I6: =SUMIFS('4-1 지역 벤치마크(참조)'!$C$2:$C$28,'4-1 지역 벤치마크(참조)'!$A$2:$A$28,$B6,'4-1 지역 벤치마크(참조)'!$B$2:$B$28,"D7 리텐션") -> 0.0497 | J6: 1.6~1.8% | K6: =SUMIFS('4-1 지역 벤치마크(참조)'!$D$2:$D$28,'4-1 지역 벤치마크(참조)'!$A$2:$A$28,$B6,'4-1 지역 벤치마크(참조)'!$B$2:$B$28,"D30 리텐션") -> 0.0478 | L6: =SUMIFS('4-1 지역 벤치마크(참조)'!$C$2:$C$28,'4-1 지역 벤치마크(참조)'!$A$2:$A$28,$B6,'4-1 지역 벤치마크(참조)'!$B$2:$B$28,"D30 리텐션") -> 0.0118 | M6: 1.34 | N6: 0.55 | O6: 7.26 | P6: 미공개
A7: Bus Fever Party! | B7: 북미 | C7: 캐주얼 | D7: 30% 약간 상회 | E7: =SUMIFS('4-1 지역 벤치마크(참조)'!$D$2:$D$28,'4-1 지역 벤치마크(참조)'!$A$2:$A$28,$B7,'4-1 지역 벤치마크(참조)'!$B$2:$B$28,"D1 리텐션") -> 0.369 | F7: =SUMIFS('4-1 지역 벤치마크(참조)'!$C$2:$C$28,'4-1 지역 벤치마크(참조)'!$A$2:$A$28,$B7,'4-1 지역 벤치마크(참조)'!$B$2:$B$28,"D1 리텐션") -> 0.2328 | G7: 6~7% | H7: =SUMIFS('4-1 지역 벤치마크(참조)'!$D$2:$D$28,'4-1 지역 벤치마크(참조)'!$A$2:$A$28,$B7,'4-1 지역 벤치마크(참조)'!$B$2:$B$28,"D7 리텐션") -> 0.1258 | I7: =SUMIFS('4-1 지역 벤치마크(참조)'!$C$2:$C$28,'4-1 지역 벤치마크(참조)'!$A$2:$A$28,$B7,'4-1 지역 벤치마크(참조)'!$B$2:$B$28,"D7 리텐션") -> 0.0497 | J7: 1.6~1.8% | K7: =SUMIFS('4-1 지역 벤치마크(참조)'!$D$2:$D$28,'4-1 지역 벤치마크(참조)'!$A$2:$A$28,$B7,'4-1 지역 벤치마크(참조)'!$B$2:$B$28,"D30 리텐션") -> 0.0478 | L7: =SUMIFS('4-1 지역 벤치마크(참조)'!$C$2:$C$28,'4-1 지역 벤치마크(참조)'!$A$2:$A$28,$B7,'4-1 지역 벤치마크(참조)'!$B$2:$B$28,"D30 리텐션") -> 0.0118 | M7: 1.34 | N7: 0.55 | O7: 7.26 | P7: 미공개
A8: Royal Match | B8: 북미 | C8: 캐주얼 | D8: 30% 약간 상회 | E8: =SUMIFS('4-1 지역 벤치마크(참조)'!$D$2:$D$28,'4-1 지역 벤치마크(참조)'!$A$2:$A$28,$B8,'4-1 지역 벤치마크(참조)'!$B$2:$B$28,"D1 리텐션") -> 0.369 | F8: =SUMIFS('4-1 지역 벤치마크(참조)'!$C$2:$C$28,'4-1 지역 벤치마크(참조)'!$A$2:$A$28,$B8,'4-1 지역 벤치마크(참조)'!$B$2:$B$28,"D1 리텐션") -> 0.2328 | G8: 6~7% | H8: =SUMIFS('4-1 지역 벤치마크(참조)'!$D$2:$D$28,'4-1 지역 벤치마크(참조)'!$A$2:$A$28,$B8,'4-1 지역 벤치마크(참조)'!$B$2:$B$28,"D7 리텐션") -> 0.1258 | I8: =SUMIFS('4-1 지역 벤치마크(참조)'!$C$2:$C$28,'4-1 지역 벤치마크(참조)'!$A$2:$A$28,$B8,'4-1 지역 벤치마크(참조)'!$B$2:$B$28,"D7 리텐션") -> 0.0497 | J8: 1.6~1.8% | K8: =SUMIFS('4-1 지역 벤치마크(참조)'!$D$2:$D$28,'4-1 지역 벤치마크(참조)'!$A$2:$A$28,$B8,'4-1 지역 벤치마크(참조)'!$B$2:$B$28,"D30 리텐션") -> 0.0478 | L8: =SUMIFS('4-1 지역 벤치마크(참조)'!$C$2:$C$28,'4-1 지역 벤치마크(참조)'!$A$2:$A$28,$B8,'4-1 지역 벤치마크(참조)'!$B$2:$B$28,"D30 리텐션") -> 0.0118 | M8: 1.34 | N8: 0.55 | O8: 7.26 | P8: 미공개
A9: Gossip Harbor | B9: 북미 | C9: 캐주얼 | D9: 30% 약간 상회 | E9: =SUMIFS('4-1 지역 벤치마크(참조)'!$D$2:$D$28,'4-1 지역 벤치마크(참조)'!$A$2:$A$28,$B9,'4-1 지역 벤치마크(참조)'!$B$2:$B$28,"D1 리텐션") -> 0.369 | F9: =SUMIFS('4-1 지역 벤치마크(참조)'!$C$2:$C$28,'4-1 지역 벤치마크(참조)'!$A$2:$A$28,$B9,'4-1 지역 벤치마크(참조)'!$B$2:$B$28,"D1 리텐션") -> 0.2328 | G9: 6~7% | H9: =SUMIFS('4-1 지역 벤치마크(참조)'!$D$2:$D$28,'4-1 지역 벤치마크(참조)'!$A$2:$A$28,$B9,'4-1 지역 벤치마크(참조)'!$B$2:$B$28,"D7 리텐션") -> 0.1258 | I9: =SUMIFS('4-1 지역 벤치마크(참조)'!$C$2:$C$28,'4-1 지역 벤치마크(참조)'!$A$2:$A$28,$B9,'4-1 지역 벤치마크(참조)'!$B$2:$B$28,"D7 리텐션") -> 0.0497 | J9: 1.6~1.8% | K9: =SUMIFS('4-1 지역 벤치마크(참조)'!$D$2:$D$28,'4-1 지역 벤치마크(참조)'!$A$2:$A$28,$B9,'4-1 지역 벤치마크(참조)'!$B$2:$B$28,"D30 리텐션") -> 0.0478 | L9: =SUMIFS('4-1 지역 벤치마크(참조)'!$C$2:$C$28,'4-1 지역 벤치마크(참조)'!$A$2:$A$28,$B9,'4-1 지역 벤치마크(참조)'!$B$2:$B$28,"D30 리텐션") -> 0.0118 | M9: 1.34 | N9: 0.55 | O9: 7.26 | P9: 미공개
A10: MONOPOLY GO! | B10: 북미 | C10: 캐주얼 | D10: 30% 약간 상회 | E10: =SUMIFS('4-1 지역 벤치마크(참조)'!$D$2:$D$28,'4-1 지역 벤치마크(참조)'!$A$2:$A$28,$B10,'4-1 지역 벤치마크(참조)'!$B$2:$B$28,"D1 리텐션") -> 0.369 | F10: =SUMIFS('4-1 지역 벤치마크(참조)'!$C$2:$C$28,'4-1 지역 벤치마크(참조)'!$A$2:$A$28,$B10,'4-1 지역 벤치마크(참조)'!$B$2:$B$28,"D1 리텐션") -> 0.2328 | G10: 6~7% | H10: =SUMIFS('4-1 지역 벤치마크(참조)'!$D$2:$D$28,'4-1 지역 벤치마크(참조)'!$A$2:$A$28,$B10,'4-1 지역 벤치마크(참조)'!$B$2:$B$28,"D7 리텐션") -> 0.1258 | I10: =SUMIFS('4-1 지역 벤치마크(참조)'!$C$2:$C$28,'4-1 지역 벤치마크(참조)'!$A$2:$A$28,$B10,'4-1 지역 벤치마크(참조)'!$B$2:$B$28,"D7 리텐션") -> 0.0497 | J10: 1.6~1.8% | K10: =SUMIFS('4-1 지역 벤치마크(참조)'!$D$2:$D$28,'4-1 지역 벤치마크(참조)'!$A$2:$A$28,$B10,'4-1 지역 벤치마크(참조)'!$B$2:$B$28,"D30 리텐션") -> 0.0478 | L10: =SUMIFS('4-1 지역 벤치마크(참조)'!$C$2:$C$28,'4-1 지역 벤치마크(참조)'!$A$2:$A$28,$B10,'4-1 지역 벤치마크(참조)'!$B$2:$B$28,"D30 리텐션") -> 0.0118 | M10: 1.34 | N10: 0.55 | O10: 7.26 | P10: 미공개
A11: Whiteout Survival | B11: 북미 | C11: 미드코어 | D11: 30% 약간 상회 | E11: =SUMIFS('4-1 지역 벤치마크(참조)'!$D$2:$D$28,'4-1 지역 벤치마크(참조)'!$A$2:$A$28,$B11,'4-1 지역 벤치마크(참조)'!$B$2:$B$28,"D1 리텐션") -> 0.369 | F11: =SUMIFS('4-1 지역 벤치마크(참조)'!$C$2:$C$28,'4-1 지역 벤치마크(참조)'!$A$2:$A$28,$B11,'4-1 지역 벤치마크(참조)'!$B$2:$B$28,"D1 리텐션") -> 0.2328 | G11: 6~7% | H11: =SUMIFS('4-1 지역 벤치마크(참조)'!$D$2:$D$28,'4-1 지역 벤치마크(참조)'!$A$2:$A$28,$B11,'4-1 지역 벤치마크(참조)'!$B$2:$B$28,"D7 리텐션") -> 0.1258 | I11: =SUMIFS('4-1 지역 벤치마크(참조)'!$C$2:$C$28,'4-1 지역 벤치마크(참조)'!$A$2:$A$28,$B11,'4-1 지역 벤치마크(참조)'!$B$2:$B$28,"D7 리텐션") -> 0.0497 | J11: 1.6~1.8% | K11: =SUMIFS('4-1 지역 벤치마크(참조)'!$D$2:$D$28,'4-1 지역 벤치마크(참조)'!$A$2:$A$28,$B11,'4-1 지역 벤치마크(참조)'!$B$2:$B$28,"D30 리텐션") -> 0.0478 | L11: =SUMIFS('4-1 지역 벤치마크(참조)'!$C$2:$C$28,'4-1 지역 벤치마크(참조)'!$A$2:$A$28,$B11,'4-1 지역 벤치마크(참조)'!$B$2:$B$28,"D30 리텐션") -> 0.0118 | M11: 2.13 | N11: 0.4 | O11: 9.8 | P11: 미공개
A12: Free Fire | B12: 남미 | C12: 미드코어 | D12: 30% 약간 상회 | E12: =SUMIFS('4-1 지역 벤치마크(참조)'!$D$2:$D$28,'4-1 지역 벤치마크(참조)'!$A$2:$A$28,$B12,'4-1 지역 벤치마크(참조)'!$B$2:$B$28,"D1 리텐션") -> 0.3406 | F12: =SUMIFS('4-1 지역 벤치마크(참조)'!$C$2:$C$28,'4-1 지역 벤치마크(참조)'!$A$2:$A$28,$B12,'4-1 지역 벤치마크(참조)'!$B$2:$B$28,"D1 리텐션") -> 0.2009 | G12: 6~7% | H12: =SUMIFS('4-1 지역 벤치마크(참조)'!$D$2:$D$28,'4-1 지역 벤치마크(참조)'!$A$2:$A$28,$B12,'4-1 지역 벤치마크(참조)'!$B$2:$B$28,"D7 리텐션") -> 0.0914 | I12: =SUMIFS('4-1 지역 벤치마크(참조)'!$C$2:$C$28,'4-1 지역 벤치마크(참조)'!$A$2:$A$28,$B12,'4-1 지역 벤치마크(참조)'!$B$2:$B$28,"D7 리텐션") -> 0.0325 | J12: 1.6~1.8% | K12: =SUMIFS('4-1 지역 벤치마크(참조)'!$D$2:$D$28,'4-1 지역 벤치마크(참조)'!$A$2:$A$28,$B12,'4-1 지역 벤치마크(참조)'!$B$2:$B$28,"D30 리텐션") -> 0.0254 | L12: =SUMIFS('4-1 지역 벤치마크(참조)'!$C$2:$C$28,'4-1 지역 벤치마크(참조)'!$A$2:$A$28,$B12,'4-1 지역 벤치마크(참조)'!$B$2:$B$28,"D30 리텐션") -> 0.0065 | M12: 2.13 | N12: 0.4 | O12: 9.8 | P12: 미공개
A13: 치이카와 포켓 | B13: 아시아 | C13: 미정 (게임 방식 미확인) | D13: 30% 약간 상회 | E13: =SUMIFS('4-1 지역 벤치마크(참조)'!$D$2:$D$28,'4-1 지역 벤치마크(참조)'!$A$2:$A$28,$B13,'4-1 지역 벤치마크(참조)'!$B$2:$B$28,"D1 리텐션") -> 0.3277 | F13: =SUMIFS('4-1 지역 벤치마크(참조)'!$C$2:$C$28,'4-1 지역 벤치마크(참조)'!$A$2:$A$28,$B13,'4-1 지역 벤치마크(참조)'!$B$2:$B$28,"D1 리텐션") -> 0.175 | G13: 6~7% | H13: =SUMIFS('4-1 지역 벤치마크(참조)'!$D$2:$D$28,'4-1 지역 벤치마크(참조)'!$A$2:$A$28,$B13,'4-1 지역 벤치마크(참조)'!$B$2:$B$28,"D7 리텐션") -> 0.0865 | I13: =SUMIFS('4-1 지역 벤치마크(참조)'!$C$2:$C$28,'4-1 지역 벤치마크(참조)'!$A$2:$A$28,$B13,'4-1 지역 벤치마크(참조)'!$B$2:$B$28,"D7 리텐션") -> 0.0268 | J13: 1.6~1.8% | K13: =SUMIFS('4-1 지역 벤치마크(참조)'!$D$2:$D$28,'4-1 지역 벤치마크(참조)'!$A$2:$A$28,$B13,'4-1 지역 벤치마크(참조)'!$B$2:$B$28,"D30 리텐션") -> 0.0259 | L13: =SUMIFS('4-1 지역 벤치마크(참조)'!$C$2:$C$28,'4-1 지역 벤치마크(참조)'!$A$2:$A$28,$B13,'4-1 지역 벤치마크(참조)'!$B$2:$B$28,"D30 리텐션") -> 0.0053 | P13: 미공개
A14: 후더덕 서바이벌 | B14: 아시아 | C14: 미드코어 | D14: 30% 약간 상회 | E14: =SUMIFS('4-1 지역 벤치마크(참조)'!$D$2:$D$28,'4-1 지역 벤치마크(참조)'!$A$2:$A$28,$B14,'4-1 지역 벤치마크(참조)'!$B$2:$B$28,"D1 리텐션") -> 0.3277 | F14: =SUMIFS('4-1 지역 벤치마크(참조)'!$C$2:$C$28,'4-1 지역 벤치마크(참조)'!$A$2:$A$28,$B14,'4-1 지역 벤치마크(참조)'!$B$2:$B$28,"D1 리텐션") -> 0.175 | G14: 6~7% | H14: =SUMIFS('4-1 지역 벤치마크(참조)'!$D$2:$D$28,'4-1 지역 벤치마크(참조)'!$A$2:$A$28,$B14,'4-1 지역 벤치마크(참조)'!$B$2:$B$28,"D7 리텐션") -> 0.0865 | I14: =SUMIFS('4-1 지역 벤치마크(참조)'!$C$2:$C$28,'4-1 지역 벤치마크(참조)'!$A$2:$A$28,$B14,'4-1 지역 벤치마크(참조)'!$B$2:$B$28,"D7 리텐션") -> 0.0268 | J14: 1.6~1.8% | K14: =SUMIFS('4-1 지역 벤치마크(참조)'!$D$2:$D$28,'4-1 지역 벤치마크(참조)'!$A$2:$A$28,$B14,'4-1 지역 벤치마크(참조)'!$B$2:$B$28,"D30 리텐션") -> 0.0259 | L14: =SUMIFS('4-1 지역 벤치마크(참조)'!$C$2:$C$28,'4-1 지역 벤치마크(참조)'!$A$2:$A$28,$B14,'4-1 지역 벤치마크(참조)'!$B$2:$B$28,"D30 리텐션") -> 0.0053 | M14: 2.13 | N14: 0.4 | O14: 9.8 | P14: 미공개
A16: 모든 숫자는 시장조사.xlsx › '4-1 벤치마크 근거' 시트와 이 파일의 '4-1 지역 벤치마크(참조)' 시트의 출처값을 그대로 가져온 것이며, 새로 만든 수치는 없습니다.
A17: '합격선'과 '목표'를 어느 구간(P75·P90)으로 둘지는 분석자 제안입니다. 기준을 바꾸려면 D·G·J열 또는 '4-1 지역 벤치마크(참조)' 조회 열을 바꾸면 됩니다.
A18: 주 타깃 지역과 수익 장르 분류(캐주얼·미드코어)는 분석자 판단입니다(파란 글씨). 지역을 바꾸면 지역 수치가 자동으로 바뀝니다.
A19: 리텐션 수치는 전 장르 합산값입니다. 장르별 수치는 GameAnalytics 2026 보고서에 없고, 2025 보고서 이미지 차트에서 읽은 판독값은 '4-3 장르 판독 요약(참조)'·'2-3 장르 연결(추정)' 시트에 따로 두었습니다(이 표에는 섞지 않음).
A20: D30 리텐션은 2026 보고서 기준이며, 2025 보고서는 D28을 사용해 직접 비교에 주의가 필요합니다.
A21: 수익 수치(AppsFlyer)는 D90 기준 글로벌 평균이며, 지역·플랫폼에 따라 다릅니다(북미·유럽은 더 높다고 보고됨).

Sheet 2-3 장르 연결(추정)
A1: 우리 프로젝트 장르 그룹 ↔ GameAnalytics 장르 연결 (분석자 추정)
A2: ⚠ 연결(C열)은 분석자 추정입니다. 각 게임이 스토어에 어떤 장르로 등록됐는지는 이번에 확인하지 않았습니다. C열(노란 칸)을 목록에서 바꾸면 오른쪽 숫자가 자동으로 바뀝니다.
A4: 우리 장르 그룹 | B4: 대표 게임 | C4: 연결한 GA 장르 (바꿀 수 있음) | D4: 연결 근거 | E4: 신뢰도 | F4: 다른 후보 장르 | G4: D1 | H4: D7 | I4: D28 | J4: 하루 플레이(분) | K4: 세션 길이(분) | L4: 하루 세션 수 | M4: 쉬운 해설 (100명 설치 기준)
A5: 1. 글로벌 퍼즐 | B5: Block Blast!, Magic Sort!, Meowdoku 등 | C5: Puzzle | D5: 정렬·블록·스도쿠류 퍼즐이라 이름이 가장 가까움 | E5: 중간 | F5: Board (Vita Mahjong 같은 마작류), Casual | G5: =INDEX('4-3 장르 판독 요약(참조)'!$C$5:$C$20,MATCH($C5,'4-3 장르 판독 요약(참조)'!$A$5:$A$20,0)) -> 0.20205 | H5: =INDEX('4-3 장르 판독 요약(참조)'!$E$5:$E$20,MATCH($C5,'4-3 장르 판독 요약(참조)'!$A$5:$A$20,0)) -> 0.045358333 | I5: =INDEX('4-3 장르 판독 요약(참조)'!$G$5:$G$20,MATCH($C5,'4-3 장르 판독 요약(참조)'!$A$5:$A$20,0)) -> 0.0119 | J5: =INDEX('4-3 장르 판독 요약(참조)'!$I$5:$I$20,MATCH($C5,'4-3 장르 판독 요약(참조)'!$A$5:$A$20,0)) -> 30.191667 | K5: =INDEX('4-3 장르 판독 요약(참조)'!$K$5:$K$20,MATCH($C5,'4-3 장르 판독 요약(참조)'!$A$5:$A$20,0)) -> 5.6416667 | L5: =INDEX('4-3 장르 판독 요약(참조)'!$M$5:$M$20,MATCH($C5,'4-3 장르 판독 요약(참조)'!$A$5:$A$20,0)) -> 4.7758333 | M5: =INDEX('4-3 장르 판독 요약(참조)'!$O$5:$O$20,MATCH($C5,'4-3 장르 판독 요약(참조)'!$A$5:$A$20,0)) -> 다음날 20.2명 → 1주 뒤 4.5명 → 4주 뒤 1.2명이 다시 옴
A6: 2. 퍼즐 + 메타 | B6: Royal Match, Candy Crush Saga 등 | C6: Puzzle | D6: 3개 맞추기 퍼즐이 핵심 놀이 | E6: 중간 | F6: Casual | G6: =INDEX('4-3 장르 판독 요약(참조)'!$C$5:$C$20,MATCH($C6,'4-3 장르 판독 요약(참조)'!$A$5:$A$20,0)) -> 0.20205 | H6: =INDEX('4-3 장르 판독 요약(참조)'!$E$5:$E$20,MATCH($C6,'4-3 장르 판독 요약(참조)'!$A$5:$A$20,0)) -> 0.045358333 | I6: =INDEX('4-3 장르 판독 요약(참조)'!$G$5:$G$20,MATCH($C6,'4-3 장르 판독 요약(참조)'!$A$5:$A$20,0)) -> 0.0119 | J6: =INDEX('4-3 장르 판독 요약(참조)'!$I$5:$I$20,MATCH($C6,'4-3 장르 판독 요약(참조)'!$A$5:$A$20,0)) -> 30.191667 | K6: =INDEX('4-3 장르 판독 요약(참조)'!$K$5:$K$20,MATCH($C6,'4-3 장르 판독 요약(참조)'!$A$5:$A$20,0)) -> 5.6416667 | L6: =INDEX('4-3 장르 판독 요약(참조)'!$M$5:$M$20,MATCH($C6,'4-3 장르 판독 요약(참조)'!$A$5:$A$20,0)) -> 4.7758333 | M6: =INDEX('4-3 장르 판독 요약(참조)'!$O$5:$O$20,MATCH($C6,'4-3 장르 판독 요약(참조)'!$A$5:$A$20,0)) -> 다음날 20.2명 → 1주 뒤 4.5명 → 4주 뒤 1.2명이 다시 옴
A7: 3. 소셜 캐주얼 | B7: MONOPOLY GO!, Coin Master, Dice Dreams | C7: Board | D7: 주사위·보드판 칸 이동이 핵심인 게임이 2개 | E7: 낮음 | F7: Casual, Casino (Coin Master의 슬롯) | G7: =INDEX('4-3 장르 판독 요약(참조)'!$C$5:$C$20,MATCH($C7,'4-3 장르 판독 요약(참조)'!$A$5:$A$20,0)) -> 0.19099167 | H7: =INDEX('4-3 장르 판독 요약(참조)'!$E$5:$E$20,MATCH($C7,'4-3 장르 판독 요약(참조)'!$A$5:$A$20,0)) -> 0.058283333 | I7: =INDEX('4-3 장르 판독 요약(참조)'!$G$5:$G$20,MATCH($C7,'4-3 장르 판독 요약(참조)'!$A$5:$A$20,0)) -> 0.021716667 | J7: =INDEX('4-3 장르 판독 요약(참조)'!$I$5:$I$20,MATCH($C7,'4-3 장르 판독 요약(참조)'!$A$5:$A$20,0)) -> 41.058333 | K7: =INDEX('4-3 장르 판독 요약(참조)'!$K$5:$K$20,MATCH($C7,'4-3 장르 판독 요약(참조)'!$A$5:$A$20,0)) -> 7.2916667 | L7: =INDEX('4-3 장르 판독 요약(참조)'!$M$5:$M$20,MATCH($C7,'4-3 장르 판독 요약(참조)'!$A$5:$A$20,0)) -> 5.0883333 | M7: =INDEX('4-3 장르 판독 요약(참조)'!$O$5:$O$20,MATCH($C7,'4-3 장르 판독 요약(참조)'!$A$5:$A$20,0)) -> 다음날 19.1명 → 1주 뒤 5.8명 → 4주 뒤 2.2명이 다시 옴
A8: 4. 전략(4X 등) | B8: Whiteout Survival, Kingshot, Clash Royale | C8: Strategy | D8: 장르 이름이 같음 | E8: 중간 | F8: Multiplayer (Clash Royale 실시간 대전) | G8: =INDEX('4-3 장르 판독 요약(참조)'!$C$5:$C$20,MATCH($C8,'4-3 장르 판독 요약(참조)'!$A$5:$A$20,0)) -> 0.19899167 | H8: =INDEX('4-3 장르 판독 요약(참조)'!$E$5:$E$20,MATCH($C8,'4-3 장르 판독 요약(참조)'!$A$5:$A$20,0)) -> 0.03365 | I8: =INDEX('4-3 장르 판독 요약(참조)'!$G$5:$G$20,MATCH($C8,'4-3 장르 판독 요약(참조)'!$A$5:$A$20,0)) -> 0.0071416667 | J8: =INDEX('4-3 장르 판독 요약(참조)'!$I$5:$I$20,MATCH($C8,'4-3 장르 판독 요약(참조)'!$A$5:$A$20,0)) -> 23.5 | K8: =INDEX('4-3 장르 판독 요약(참조)'!$K$5:$K$20,MATCH($C8,'4-3 장르 판독 요약(참조)'!$A$5:$A$20,0)) -> 5.45 | L8: =INDEX('4-3 장르 판독 요약(참조)'!$M$5:$M$20,MATCH($C8,'4-3 장르 판독 요약(참조)'!$A$5:$A$20,0)) -> 4.2966667 | M8: =INDEX('4-3 장르 판독 요약(참조)'!$O$5:$O$20,MATCH($C8,'4-3 장르 판독 요약(참조)'!$A$5:$A$20,0)) -> 다음날 19.9명 → 1주 뒤 3.4명 → 4주 뒤 0.7명이 다시 옴
