Workbook

Sheet 0 목차
A1: 시장조사.xlsx — 목차
A2: 이 파일: 시장조사.xlsx / 짝 파일: 게임전략_MVP_마케팅.xlsx (성공 비결·MVP·마케팅 판단 자료) · 시트 이름을 누르면 그 시트로 이동합니다. 회색 줄은 다음 단계에서 만들 '예정' 시트입니다.
A4: 그룹 | B4: 시트 이름 | C4: 한 줄 설명 | D4: 상태 | E4: 비고
A5: 0 안내 | B5: 0 목차 | C5: 이 시트 | D5: 완료
A6: 0 안내 | B6: 0-1 개요 | C6: 분석 범위·기준일·출처 모음 | D6: 완료
A7: 1 미국 차트 | B7: 1-1 App Store Top100 | C7: 미국 App Store 무료 게임 1~100위와 장르 분류 (기준일 2026-10-03) | D7: 완료
A8: 1 미국 차트 | B8: 1-2 Google Play Top100 | C8: 미국 구글 플레이 무료 게임 1~100위와 장르 분류 (기준일 2026-10-04) | D8: 완료
A9: 1 미국 차트 | B9: 1-3 장르 분포 | C9: 두 스토어 Top100의 대분류별 게임 수·비율 (수식 자동 집계) | D9: 완료
A10: 1 미국 차트 | B10: 1-4 세부 장르 | C10: 대분류 안 세부 장르별 게임 수 (수식 자동 집계) | D10: 완료
A11: 1 미국 차트 | B11: 1-5 인사이트 | C11: 미국 차트에서 찾은 핵심 발견 | D11: 완료
A12: 1 미국 차트 | B12: 1-6 심층 분석 후보 | C12: 더 깊게 볼 게임 후보와 고른 이유 | D12: 완료
A13: 2 지역 | B13: 2-1 지역 비교 요약 | C13: 미국·캐나다 / 남미 / 아시아 / 동남아(인도네시아) 시장 한눈에 비교 | D13: 완료 | E13: 6단계-2에서 동남아 열(E) 추가함
A14: 2 지역 | B14: 2-2 국가별 Top20 | C14: 캐나다·브라질·멕시코·일본·한국 구글 플레이 무료 Top20 | D14: 완료
A15: 2 지역 | B15: 2-3 국가별 장르 분포 | C15: 국가별 Top20의 장르 집계 (수식 자동 집계) | D15: 완료
A16: 2 지역 | B16: 2-4 공통 인기 게임 | C16: 여러 나라에서 함께 순위권에 오른 게임 | D16: 완료
A17: 2 지역 | B17: 2-5 지역별 특징 | C17: 지역·국가별 특징과 근거 게임 | D17: 완료
A18: 2 지역 | B18: 2-6 대륙별 OS 분포 | C18: 대륙·국가별 Android/iOS 점유율, 스토어별 게임 매출·다운로드, OS 출시 우선순위(분석자 제안) | D18: 완료 | E18: 국가 12곳 포함 (StatCounter 2026-09)
A19: 2 지역 | B19: 2-7 동남아 분석 | C19: 인도네시아 Top20·장르 집계·공통 게임·특징 + 동남아 벤치마크(2025 보고서) | D19: 완료 | E19: 태국·베트남·필리핀·말레이시아 순위는 확인 불가
A20: 3 매출 | B20: 3-1 매출 순위 원자료 | C20: 미국·브라질·일본·한국 구글 플레이 매출 Top10 원자료 | D20: 완료
A21: 3 매출 | B21: 3-2 매출 Top100 | C21: 미국 구글 플레이 매출 Top100 장르 분류 (기준일 2026-10-04) + 무료 Top100과 장르 비교 | D21: 완료
A22: 3 매출 | B22: 3-3 매출-다운로드 비교 | C22: 매출 순위 vs 무료 순위·추정 설치 수 구간, 4가지 유형 자동 분류 | D22: 완료
A23: 4 벤치마크 | B23: 4-1 벤치마크 근거 | C23: 리텐션·수익 등 공개 벤치마크 수치와 출처 | D23: 완료
A24: 4 벤치마크 | B24: 4-2 지역 벤치마크 | C24: 지역별 지표 중앙값·상위 구간 표 | D24: 완료 | E24: 게임전략 파일 4-1에 참조용 복사본 있음
A25: 4 벤치마크 | B25: 4-3 장르 차트 판독값 | C25: GameAnalytics 2025 장르별 차트를 눈으로 읽은 값 (판독값) | D25: 완료 | E25: 게임전략 파일 4-2에 참조용 복사본 있음
A26: 4 벤치마크 | B26: 4-4 장르 판독 요약 | C26: 판독값의 12개월 평균과 장르 순위 (수식 자동 계산) | D26: 완료 | E26: 게임전략 파일 4-3에 참조용 복사본 있음
A27: 4 벤치마크 | B27: 4-5 제외한 자료 | C27: 출처가 약해 쓰지 않은 자료와 이유 | D27: 완료

Sheet 0-1 개요
A1: 모바일 게임 시장 분석 — 장르 분류 · 지역 비교 · 성공 비결 & MVP · 벤치마크
A3: 항목 | B3: 내용
A4: 분석 범위 | B4: 미국 App Store / Google Play 게임 카테고리 Top Free 1~100위
A5: App Store 기준일 | B5: 2026-10-03
A6: App Store 출처 | B6: GameDropDaily (Apple 공개 iTunes RSS 차트 기반) https://gamedropdaily.com/mobile/ · 퍼블리셔·국가 교차 확인: AppBrain https://www.appbrain.com/stats/appstore-rankings
A7: Google Play 기준일 | B7: 2026-10-04
A8: Google Play 출처 | B8: AppBrain 미국 Top Free Games https://www.appbrain.com/stats/google-play-rankings/top_free/game/us · 교차 확인: GameDropDaily https://gamedropdaily.com/android/
A9: 참고 | B9: 수집 시점 차이로 출처 간 순위가 1~5계단 다를 수 있음. Google Play 80위는 출처 페이지에서 누락되어 '확인 불가'로 표시.
A10: 장르 분류 | B10: 게임명, 스토어 카테고리, 공개 게임 정보 기반의 분석자 판단. 확신이 낮은 항목은 '비고'에 '확인 필요'로 표시하고 노란색으로 강조.
A11: 수정 방법 | B11: '1-1 App Store Top100' / '1-2 Google Play Top100' 시트의 '대분류', '세부 장르' 열을 수정하면 '1-3 장르 분포' 시트 집계가 자동으로 갱신됨(COUNTIF 수식).
A12: 시트 구성 | B12: [0 안내] 0-1 개요 / [1 미국 차트] 1-1 App Store Top100 · 1-2 Google Play Top100 · 1-3 장르 분포 · 1-4 세부 장르 · 1-5 인사이트 · 1-6 심층 분석 후보 / [2 지역] 2-1 지역 비교 요약 · 2-2 국가별 Top20 · 2-3 국가별 장르 분포 · 2-4 공통 인기 게임 · 2-5 지역별 특징 · 2-6 대륙별 OS 분포 · 2-7 동남아 분석 / [3 매출] 3-1 매출 순위 원자료 · 3-2 매출 Top100 · 3-3 매출-다운로드 비교 / [4 벤치마크] 4-1 벤치마크 근거 · 4-2 지역 벤치마크 · 4-3 장르 차트 판독값 · 4-4 장르 판독 요약 · 4-5 제외한 자료 ※ 성공 비결·MVP·마케팅 판단 자료은(는) '게임전략_MVP_마케팅.xlsx' 파일에 있음 (파일 사이 수식 연결 없음)
A13: 3단계 출처 | B13: GameAnalytics 2026·2025 벤치마크, AppsFlyer State of App Monetization 2026·Gaming App Marketing 2024, Appodeal Mobile Casual Benchmarks 2025. 출처 없는 수치는 '제외한 자료'에 기록.
A14: 2단계 출처 | B14: AppBrain 구글 플레이 매출 순위: 미국·한국 2026-10-03, 일본 2026-10-04, 브라질 2026-10-01. 외부 자료: Wikipedia(Free Fire). 별점·MVP 규모·인원·기간·게임 방식 일부는 분석자 추정.
... A18: 6단계-2 한계 | B18: 태국·베트남·필리핀·말레이시아 Top20은 공개 순위 출처가 없어 확인 불가. OS 값은 대륙 6곳·나라 12곳(싱가포르 참고 포함) 조사. 매출-다운로드 비교의 공식 설치 구간·출시일은 Kingshot만 확인. 위 '지역 비교 한계' 줄의 '동남아 미포함' 문구는 기존 칸이라 그대로 둠.

Sheet 1-1 App Store Top100
A1: 순위 | B1: 게임명 | C1: 퍼블리셔 | D1: 대분류 | E1: 세부 장르 | F1: 비고
A2: 1 | B2: Meowdoku! | C2: Oakever Games | D2: 퍼즐 | E2: 로직·두뇌 트릭 | F2: 스도쿠류
A3: 2 | B3: Block Out! - Color Sort Puzzle | C3: Grand Games | D3: 퍼즐 | E3: 정렬·잼
A4: 3 | B4: Rotate Rings | C4: Nebula Studio | D4: 퍼즐 | E4: 정렬·잼
A5: 4 | B5: Magic Sort! | C5: Grand Games | D5: 퍼즐 | E5: 정렬·잼
A6: 5 | B6: Colony Flow! | C6: ABI Global | D6: 퍼즐 | E6: 정렬·잼 | F6: 확인 필요
A7: 6 | B7: Smash Fest! | C7: Flow Games | D7: 하이퍼·하이브리드 캐주얼 | E7: 물리 파괴
A8: 7 | B8: CubeAway - 3DPuzzle | C8: GOODROID | D8: 퍼즐 | E8: 탭 탈출
A9: 8 | B9: Roblox | C9: Roblox Corporation | D9: 기타(UGC·리워드) | E9: UGC 플랫폼
A10: 9 | B10: Vita Mahjong | C10: Vita Studio | D10: 퍼즐 | E10: 타일·마작·트리플 매치
A11: 10 | B11: Brain Puzzle 3: Crazy Mind | C11: SmallStep Dev Team | D11: 퍼즐 | E11: 로직·두뇌 트릭
A12: 11 | B12: Woodoku Blast: Block Puzzle | C12: Tripledot Studios | D12: 퍼즐 | E12: 블록
A13: 12 | B13: Bus Fever Party! | C13: Lumi Games | D13: 퍼즐 | E13: 정렬·잼 | F13: 버스잼
A14: 13 | B14: Block Blast! | C14: Hungry Studio | D14: 퍼즐 | E14: 블록
A15: 14 | B15: Bus Traffic Fever! | C15: GOODROID | D15: 퍼즐 | E15: 정렬·잼 | F15: 버스잼
A16: 15 | B16: Amaze GO! | C16: Oakever Games | D16: 퍼즐 | E16: 탭 탈출
A17: 16 | B17: Colorever: Gem Art Puzzle | C17: Oakever Games | D17: 퍼즐 | E17: 픽셀·컬러 아트
A18: 17 | B18: Township | C18: Playrix | D18: 시뮬레이션 | E18: 농장·타운 빌딩
A19: 18 | B19: Fortnite | C19: Epic Games | D19: 액션·슈팅 | E19: 배틀로얄
A20: 19 | B20: Royal Match | C20: Dream Games | D20: 퍼즐 | E20: 매치3
A21: 20 | B21: Mahjong Blast | C21: Nebula Studio | D21: 퍼즐 | E21: 타일·마작·트리플 매치
A22: 21 | B22: Royal Smash! - Physics Puzzle | C22: Cypher Games | D22: 하이퍼·하이브리드 캐주얼 | E22: 물리 파괴
A23: 22 | B23: MONOPOLY GO! | C23: Scopely | D23: 카드·보드·카지노 | E23: 보드·주사위 소셜캐주얼
A24: 23 | B24: Whiteout Survival | C24: Century Games | D24: 전략 | E24: 4X·SLG
A25: 24 | B25: Gossip Harbor: Merge & Story | C25: Microfun | D25: 퍼즐 | E25: 머지 | F25: 스토리 결합
A26: 25 | B26: Solitaire Associations Journey | C26: Hitapps Games | D26: 퍼즐 | E26: 워드 | F26: 연상 퍼즐
A27: 26 | B27: Magic Tiles 3: Piano Game | C27: Amanotes | D27: 파티·음악 | E27: 리듬
A28: 27 | B28: CrownCards - Trading Cards | C28: CrownCards | D28: 카드·보드·카지노 | E28: 트레이딩 카드 | F28: 확인 필요
A29: 28 | B29: Food Hunt: Pixel Puzzle | C29: Funfinity | D29: 퍼즐 | E29: 픽셀·컬러 아트
A30: 29 | B30: Tasty Travels: Merge Game | C30: Century Games | D30: 퍼즐 | E30: 머지
A31: 30 | B31: Subway Surfers | C31: SYBO Games | D31: 하이퍼·하이브리드 캐주얼 | E31: 러너
A32: 31 | B32: Castle Busters | C32: Voodoo | D32: 하이퍼·하이브리드 캐주얼 | E32: 하이브리드 캐주얼
A33: 32 | B33: Sled Surfers | C33: CrazyLabs | D33: 하이퍼·하이브리드 캐주얼 | E33: 러너
A34: 33 | B34: Tang Luck: Casino Slots | C34: SpinShift | D34: 카드·보드·카지노 | E34: 소셜 카지노
A35: 34 | B35: Triumph Arcade | C35: Triumph Arcade | D35: 카드·보드·카지노 | E35: 리얼머니 스킬게임
A36: 35 | B36: Royal Kingdom | C36: Dream Games | D36: 퍼즐 | E36: 매치3
A37: 36 | B37: Arrows – Puzzle Escape | C37: Lessmore | D37: 퍼즐 | E37: 탭 탈출
A38: 37 | B38: Car Evolve | C38: Heseri Games | D38: 하이퍼·하이브리드 캐주얼 | E38: 러너 | F38: 진화 러너
A39: 38 | B39: Disney Solitaire | C39: SuperPlay | D39: 카드·보드·카지노 | E39: 솔리테어 | F39: IP 활용
A40: 39 | B40: PlayCash Rewards | C40: 확인 불가 | D40: 기타(UGC·리워드) | E40: 리워드 앱 | F40: 퍼블리셔 확인 필요
...

Sheet 1-2 Google Play Top100
A1: 순위 | B1: 게임명 | C1: 퍼블리셔 | D1: 대분류 | E1: 세부 장르 | F1: 비고
A2: 1 | B2: Rotate Rings | C2: Nebula Studio | D2: 퍼즐 | E2: 정렬·잼
A3: 2 | B3: Meowdoku: Brain Puzzle Games | C3: Oakever Games | D3: 퍼즐 | E3: 로직·두뇌 트릭 | F3: 스도쿠류
A4: 3 | B4: Angry Birds 2 | C4: Rovio | D4: 하이퍼·하이브리드 캐주얼 | E4: 물리 파괴
A5: 4 | B5: Roblox | C5: Roblox Corporation | D5: 기타(UGC·리워드) | E5: UGC 플랫폼
A6: 5 | B6: Vita Mahjong | C6: Vita Studio | D6: 퍼즐 | E6: 타일·마작·트리플 매치
A7: 6 | B7: Smash Land! | C7: Flow Games | D7: 하이퍼·하이브리드 캐주얼 | E7: 물리 파괴
A8: 7 | B8: Block Blast! | C8: Hungry Studio | D8: 퍼즐 | E8: 블록
A9: 8 | B9: Bus Fever Party! | C9: Lumi Games | D9: 퍼즐 | E9: 정렬·잼 | F9: 버스잼
A10: 9 | B10: Royal Smash! - Physics Puzzle | C10: Cypher Games | D10: 하이퍼·하이브리드 캐주얼 | E10: 물리 파괴
A11: 10 | B11: MemeMix Challenge: Funny Party | C11: Amobear VN | D11: 파티·음악 | E11: 밈 챌린지 | F11: 확인 필요
A12: 11 | B12: Magic Sort! | C12: Grand Games | D12: 퍼즐 | E12: 정렬·잼
A13: 12 | B13: Brain Puzzle 3: Crazy Mind | C13: JoyGame Studio | D13: 퍼즐 | E13: 로직·두뇌 트릭
A14: 13 | B14: Woodoku Blast | C14: Tripledot Studios | D14: 퍼즐 | E14: 블록
A15: 14 | B15: Amaze GO! | C15: Oakever Games | D15: 퍼즐 | E15: 탭 탈출
A16: 15 | B16: Block Craft 3D: Building Game | C16: Wildlife Studios | D16: 시뮬레이션 | E16: 샌드박스 | F16: 건설
A17: 16 | B17: Word Search Explorer | C17: PlaySimple | D17: 퍼즐 | E17: 워드
A18: 17 | B18: Gossip Harbor: Merge & Story | C18: Microfun | D18: 퍼즐 | E18: 머지 | F18: 스토리 결합
A19: 18 | B19: Fish Sort Puzzle | C19: Shycheese | D19: 퍼즐 | E19: 정렬·잼
A20: 19 | B20: Mahjong Blast | C20: Nebula Studio | D20: 퍼즐 | E20: 타일·마작·트리플 매치
A21: 20 | B21: Pocket Sort: Coin Merge Puzzle | C21: SayGames | D21: 퍼즐 | E21: 정렬·잼 | F21: 머지 요소
A22: 21 | B22: Colony Flow! | C22: ABI Games | D22: 퍼즐 | E22: 정렬·잼 | F22: 확인 필요
A23: 22 | B23: Township | C23: Playrix | D23: 시뮬레이션 | E23: 농장·타운 빌딩
A24: 23 | B24: Arrow Puzzle: Tap Puzzle Games | C24: Easybrain | D24: 퍼즐 | E24: 탭 탈출
A25: 24 | B25: Loop Sort | C25: Voodoo | D25: 퍼즐 | E25: 정렬·잼
A26: 25 | B26: Fortnite | C26: Epic Games | D26: 액션·슈팅 | E26: 배틀로얄
A27: 26 | B27: MONOPOLY GO! | C27: Scopely | D27: 카드·보드·카지노 | E27: 보드·주사위 소셜캐주얼
A28: 27 | B28: Cube Land Puzzle Game | C28: Rotatelab | D28: 퍼즐 | E28: 블록
A29: 28 | B29: Castle Busters | C29: Voodoo | D29: 하이퍼·하이브리드 캐주얼 | E29: 하이브리드 캐주얼
A30: 29 | B30: Bulldozer Master: Crush & Mine | C30: Supercent | D30: 하이퍼·하이브리드 캐주얼 | E30: 물리 파괴 | F30: 파괴·채굴
A31: 30 | B31: Mob Control | C31: Voodoo | D31: 하이퍼·하이브리드 캐주얼 | E31: 군중 러너·디펜스
A32: 31 | B32: CubeAway - 3DPuzzle | C32: GOODROID | D32: 퍼즐 | E32: 탭 탈출
A33: 32 | B33: Paper.io 2 | C33: Voodoo | D33: 하이퍼·하이브리드 캐주얼 | E33: io
A34: 33 | B34: Magic Tiles 3 - Piano Game | C34: Amanotes | D34: 파티·음악 | E34: 리듬
A35: 34 | B35: Arrows – Puzzle Escape | C35: Lessmore | D35: 퍼즐 | E35: 탭 탈출
A36: 35 | B36: Color Block Jam | C36: Rollic Games | D36: 퍼즐 | E36: 정렬·잼
A37: 36 | B37: 8 Ball Pool | C37: Miniclip | D37: 스포츠 | E37: 당구 PvP
A38: 37 | B38: Sled Surfers | C38: CrazyLabs | D38: 하이퍼·하이브리드 캐주얼 | E38: 러너
A39: 38 | B39: Jigsawcard Solitaire Puzzle | C39: Oakever Games | D39: 퍼즐 | E39: 직소·솔리테어 하이브리드
A40: 39 | B40: Color by Number: Coloring Games | C40: Wildlife Studios | D40: 퍼즐 | E40: 픽셀·컬러 아트
...

Sheet 1-3 장르 분포
A1: 대분류 | B1: App Store 수 | C1: App Store 비율 | D1: Google Play 수 | E1: Google Play 비율 | F1: 합계 | G1: 대표 게임
A2: 퍼즐 | B2: =COUNTIF('1-1 App Store Top100'!$D$2:$D$101,A2) -> 48 | C2: =B2/$B$13 -> 0.48 | D2: =COUNTIF('1-2 Google Play Top100'!$D$2:$D$101,A2) -> 53 | E2: =D2/$D$13 -> 0.53 | F2: =B2+D2 -> 101 | G2: Meowdoku, Block Blast, Royal Match
A3: 하이퍼·하이브리드 캐주얼 | B3: =COUNTIF('1-1 App Store Top100'!$D$2:$D$101,A3) -> 12 | C3: =B3/$B$13 -> 0.12 | D3: =COUNTIF('1-2 Google Play Top100'!$D$2:$D$101,A3) -> 17 | E3: =D3/$D$13 -> 0.17 | F3: =B3+D3 -> 29 | G3: Royal Smash, Mob Control, Subway Surfers
A4: 카드·보드·카지노 | B4: =COUNTIF('1-1 App Store Top100'!$D$2:$D$101,A4) -> 16 | C4: =B4/$B$13 -> 0.16 | D4: =COUNTIF('1-2 Google Play Top100'!$D$2:$D$101,A4) -> 7 | E4: =D4/$D$13 -> 0.07 | F4: =B4+D4 -> 23 | G4: MONOPOLY GO!, Solitaire Cash, Disney Solitaire
A5: 시뮬레이션 | B5: =COUNTIF('1-1 App Store Top100'!$D$2:$D$101,A5) -> 2 | C5: =B5/$B$13 -> 0.02 | D5: =COUNTIF('1-2 Google Play Top100'!$D$2:$D$101,A5) -> 6 | E5: =D5/$D$13 -> 0.06 | F5: =B5+D5 -> 8 | G5: Township, Melon Sandbox, Block Craft 3D
A6: 전략 | B6: =COUNTIF('1-1 App Store Top100'!$D$2:$D$101,A6) -> 4 | C6: =B6/$B$13 -> 0.04 | D6: =COUNTIF('1-2 Google Play Top100'!$D$2:$D$101,A6) -> 3 | E6: =D6/$D$13 -> 0.03 | F6: =B6+D6 -> 7 | G6: Whiteout Survival, Kingshot, Clash Royale
A7: 액션·슈팅 | B7: =COUNTIF('1-1 App Store Top100'!$D$2:$D$101,A7) -> 4 | C7: =B7/$B$13 -> 0.04 | D7: =COUNTIF('1-2 Google Play Top100'!$D$2:$D$101,A7) -> 5 | E7: =D7/$D$13 -> 0.05 | F7: =B7+D7 -> 9 | G7: Fortnite, Call of Duty: Mobile, Free Fire
A8: 스포츠 | B8: =COUNTIF('1-1 App Store Top100'!$D$2:$D$101,A8) -> 5 | C8: =B8/$B$13 -> 0.05 | D8: =COUNTIF('1-2 Google Play Top100'!$D$2:$D$101,A8) -> 2 | E8: =D8/$D$13 -> 0.02 | F8: =B8+D8 -> 7 | G8: EA FC Mobile 27, 8 Ball Pool, Retro Bowl
A9: RPG | B9: =COUNTIF('1-1 App Store Top100'!$D$2:$D$101,A9) -> 2 | C9: =B9/$B$13 -> 0.02 | D9: =COUNTIF('1-2 Google Play Top100'!$D$2:$D$101,A9) -> 2 | E9: =D9/$D$13 -> 0.02 | F9: =B9+D9 -> 4 | G9: Pokémon GO, Aniimo, Idle Cat Gunner
A10: 파티·음악 | B10: =COUNTIF('1-1 App Store Top100'!$D$2:$D$101,A10) -> 4 | C10: =B10/$B$13 -> 0.04 | D10: =COUNTIF('1-2 Google Play Top100'!$D$2:$D$101,A10) -> 3 | E10: =D10/$D$13 -> 0.03 | F10: =B10+D10 -> 7 | G10: Magic Tiles 3, Among Us
A11: 기타(UGC·리워드) | B11: =COUNTIF('1-1 App Store Top100'!$D$2:$D$101,A11) -> 3 | C11: =B11/$B$13 -> 0.03 | D11: =COUNTIF('1-2 Google Play Top100'!$D$2:$D$101,A11) -> 1 | E11: =D11/$D$13 -> 0.01 | F11: =B11+D11 -> 4 | G11: Roblox, PlayCash Rewards
A12: 확인 불가 | B12: =COUNTIF('1-1 App Store Top100'!$D$2:$D$101,A12) -> 0 | C12: =B12/$B$13 -> 0 | D12: =COUNTIF('1-2 Google Play Top100'!$D$2:$D$101,A12) -> 1 | E12: =D12/$D$13 -> 0.01 | F12: =B12+D12 -> 1 | G12: -
A13: 합계 | B13: =SUM(B2:B12) -> 100 | C13: =SUM(C2:C12) -> 1 | D13: =SUM(D2:D12) -> 100 | E13: =SUM(E2:E12) -> 1 | F13: =SUM(F2:F12) -> 200

Sheet 1-4 세부 장르
A1: 대분류 | B1: 세부 장르 | C1: App Store 수 | D1: Google Play 수 | E1: 합계
A2: 퍼즐 | B2: 정렬·잼 | C2: =COUNTIFS('1-1 App Store Top100'!$D$2:$D$101,A2,'1-1 App Store Top100'!$E$2:$E$101,B2) -> 11 | D2: =COUNTIFS('1-2 Google Play Top100'!$D$2:$D$101,A2,'1-2 Google Play Top100'!$E$2:$E$101,B2) -> 14 | E2: =C2+D2 -> 25
A3: 퍼즐 | B3: 블록 | C3: =COUNTIFS('1-1 App Store Top100'!$D$2:$D$101,A3,'1-1 App Store Top100'!$E$2:$E$101,B3) -> 5 | D3: =COUNTIFS('1-2 Google Play Top100'!$D$2:$D$101,A3,'1-2 Google Play Top100'!$E$2:$E$101,B3) -> 5 | E3: =C3+D3 -> 10
A4: 퍼즐 | B4: 워드 | C4: =COUNTIFS('1-1 App Store Top100'!$D$2:$D$101,A4,'1-1 App Store Top100'!$E$2:$E$101,B4) -> 5 | D4: =COUNTIFS('1-2 Google Play Top100'!$D$2:$D$101,A4,'1-2 Google Play Top100'!$E$2:$E$101,B4) -> 5 | E4: =C4+D4 -> 10
A5: 퍼즐 | B5: 타일·마작·트리플 매치 | C5: =COUNTIFS('1-1 App Store Top100'!$D$2:$D$101,A5,'1-1 App Store Top100'!$E$2:$E$101,B5) -> 4 | D5: =COUNTIFS('1-2 Google Play Top100'!$D$2:$D$101,A5,'1-2 Google Play Top100'!$E$2:$E$101,B5) -> 6 | E5: =C5+D5 -> 10
A6: 퍼즐 | B6: 로직·두뇌 트릭 | C6: =COUNTIFS('1-1 App Store Top100'!$D$2:$D$101,A6,'1-1 App Store Top100'!$E$2:$E$101,B6) -> 4 | D6: =COUNTIFS('1-2 Google Play Top100'!$D$2:$D$101,A6,'1-2 Google Play Top100'!$E$2:$E$101,B6) -> 4 | E6: =C6+D6 -> 8
A7: 퍼즐 | B7: 탭 탈출 | C7: =COUNTIFS('1-1 App Store Top100'!$D$2:$D$101,A7,'1-1 App Store Top100'!$E$2:$E$101,B7) -> 3 | D7: =COUNTIFS('1-2 Google Play Top100'!$D$2:$D$101,A7,'1-2 Google Play Top100'!$E$2:$E$101,B7) -> 5 | E7: =C7+D7 -> 8
A8: 하이퍼·하이브리드 캐주얼 | B8: 물리 파괴 | C8: =COUNTIFS('1-1 App Store Top100'!$D$2:$D$101,A8,'1-1 App Store Top100'!$E$2:$E$101,B8) -> 2 | D8: =COUNTIFS('1-2 Google Play Top100'!$D$2:$D$101,A8,'1-2 Google Play Top100'!$E$2:$E$101,B8) -> 6 | E8: =C8+D8 -> 8
A9: 카드·보드·카지노 | B9: 리얼머니 스킬게임 | C9: =COUNTIFS('1-1 App Store Top100'!$D$2:$D$101,A9,'1-1 App Store Top100'!$E$2:$E$101,B9) -> 6 | D9: =COUNTIFS('1-2 Google Play Top100'!$D$2:$D$101,A9,'1-2 Google Play Top100'!$E$2:$E$101,B9) -> 1 | E9: =C9+D9 -> 7
A10: 퍼즐 | B10: 매치3 | C10: =COUNTIFS('1-1 App Store Top100'!$D$2:$D$101,A10,'1-1 App Store Top100'!$E$2:$E$101,B10) -> 4 | D10: =COUNTIFS('1-2 Google Play Top100'!$D$2:$D$101,A10,'1-2 Google Play Top100'!$E$2:$E$101,B10) -> 3 | E10: =C10+D10 -> 7
A11: 퍼즐 | B11: 픽셀·컬러 아트 | C11: =COUNTIFS('1-1 App Store Top100'!$D$2:$D$101,A11,'1-1 App Store Top100'!$E$2:$E$101,B11) -> 3 | D11: =COUNTIFS('1-2 Google Play Top100'!$D$2:$D$101,A11,'1-2 Google Play Top100'!$E$2:$E$101,B11) -> 4 | E11: =C11+D11 -> 7
A12: 전략 | B12: 4X·SLG | C12: =COUNTIFS('1-1 App Store Top100'!$D$2:$D$101,A12,'1-1 App Store Top100'!$E$2:$E$101,B12) -> 3 | D12: =COUNTIFS('1-2 Google Play Top100'!$D$2:$D$101,A12,'1-2 Google Play Top100'!$E$2:$E$101,B12) -> 3 | E12: =C12+D12 -> 6
A13: 퍼즐 | B13: 머지 | C13: =COUNTIFS('1-1 App Store Top100'!$D$2:$D$101,A13,'1-1 App Store Top100'!$E$2:$E$101,B13) -> 4 | D13: =COUNTIFS('1-2 Google Play Top100'!$D$2:$D$101,A13,'1-2 Google Play Top100'!$E$2:$E$101,B13) -> 2 | E13: =C13+D13 -> 6
... A49: 파티·음악 | B49: 음악 퀴즈 | C49: =COUNTIFS('1-1 App Store Top100'!$D$2:$D$101,A49,'1-1 App Store Top100'!$E$2:$E$101,B49) -> 1 | D49: =COUNTIFS('1-2 Google Play Top100'!$D$2:$D$101,A49,'1-2 Google Play Top100'!$E$2:$E$101,B49) -> 0 | E49: =C49+D49 -> 1
A50: 합계 | C50: =SUM(C2:C49) -> 100 | D50: =SUM(D2:D49) -> 99 | E50: =SUM(E2:E49) -> 199

Sheet 1-5 인사이트
A1: 인사이트 | B1: 내용
A2: 1. 미국 무료 차트는 사실상 퍼즐 시장 | B2: 두 스토어 모두 절반 안팎이 퍼즐. App Store 1~20위 중 16개가 퍼즐. 매치3보다 정렬·잼(버스잼, 실·물고기·링 정렬)과 탭 탈출(Arrows류)이 압도적이며, 여러 회사가 같은 메커닉을 동시에 출시하는 패스트팔로우 경쟁이 치열함.
A3: 2. App Store에만 리얼머니·카지노가 두드러짐 | B3: 카드·보드·카지노가 App Store 16개 vs Google Play 7개. 리얼머니 스킬게임은 App Store 6개 vs Google Play 1개. Google Play의 리얼머니 게임 정책과 iOS 고결제 유저 대상 UA 집중이 원인으로 추정(검증 필요).
A4: 3. Google Play는 더 어리고 가벼운 취향 | B4: 하이퍼캐주얼(17 vs 12)과 샌드박스 시뮬레이션(Melon Sandbox, Block Craft 3D, Toca Boca World, Solar Smash)이 Google Play에 더 많음. 안드로이드 유저층이 상대적으로 어리다는 추정과 일치.
A5: 4. 두 스토어 간 중복이 큼 | B5: 약 54개 게임이 양쪽 Top 100에 동시 등장. 동일 퍼블리셔가 양 플랫폼에 동시 UA하는 구조로, 이후 단계는 게임별 전략 중심 분석이 효율적.
A6: 5. 상위권은 신작, 중위권은 장수작 | B6: 1~20위는 앱 ID로 보아 2025~2026년 출시로 추정되는 신작 위주(Meowdoku, Rotate Rings, CubeAway 등). Candy Crush, Subway Surfers, Royal Match 등 장수작은 20~50위권 유지. 신작 초기 대규모 UA vs 장수작 안정 유입 구조.
A7: 6. 미드코어는 소수지만 4X는 꾸준 | B7: 전략·액션·RPG 합계 약 10%. Century Games(Whiteout Survival, Kingshot, Lordrush) 등 4X는 공격적 UA로 무료 차트에도 등장. BM 분석 시 Top Grossing 차트 병행 필요.
A8: 7. 주요 퍼블리셔·튀르키예 스튜디오 강세 | B8: 다수 진입: Oakever Games, Voodoo, Century Games, Nebula Studio, PlaySimple, Dream Games, Hungry Studio, SuperPlay, Papaya·Aviagames. Dream Games, Peak, Grand Games, Flow Games, Loom Games, Rotatelab, Falcon 등 튀르키예 스튜디오가 퍼즐·캐주얼 상위권 다수 점유.

Sheet 1-6 심층 분석 후보
A1: 후보 | B1: 장르 | C1: 선정 이유
A2: Meowdoku! | B2: 퍼즐 / 로직 | C2: 양쪽 스토어 1~2위의 신작 로직 퍼즐, 신작 UA 성공 사례
A3: Rotate Rings / Arrows – Puzzle Escape | B3: 퍼즐 / 정렬·잼, 탭 탈출 | C3: 현재 최대 트렌드 메커닉의 대표작
A4: Block Blast! | B4: 퍼즐 / 블록 | C4: 장수 히트 블록 퍼즐, 광고 BM 중심 모델의 표본
A5: Royal Match / Royal Kingdom | B5: 퍼즐 / 매치3 | C5: 매치3 프리미엄 라이브옵스와 IAP의 정석
A6: Gossip Harbor | B6: 퍼즐 / 머지 | C6: 머지+스토리 결합 성공 공식, 미국 여성 유저 타깃
A7: MONOPOLY GO! / Dice Dreams | B7: 카드·보드·카지노 / 보드·주사위 소셜캐주얼 | C7: IP·주사위 소셜캐주얼, 이벤트 기반 고매출 BM
A8: Whiteout Survival / Kingshot | B8: 전략 / 4X·SLG | C8: 4X UA 전략(광고 소재와 실제 게임의 괴리)과 고과금 구조
A9: Royal Smash! / Smash Fest! | B9: 하이퍼·하이브리드 캐주얼 / 물리 파괴 | C9: 하이브리드 캐주얼 물리 파괴 장르의 급부상
A10: Solitaire Cash / Bingo Cash | B10: 카드·보드·카지노 / 리얼머니 스킬게임 | C10: 미국 특화 리얼머니 스킬게임 모델
A11: Vita Mahjong | B11: 퍼즐 / 타일·마작 | C11: 시니어 타깃 퍼즐로 양쪽 상위권 유지

Sheet 2-1 지역 비교 요약
A1: 항목 | B1: 미국·캐나다 | C1: 남미(브라질·멕시코) | D1: 아시아(일본·한국) | E1: 동남아 (인도네시아 기준)
A2: 한 줄 비유 | B2: 조용한 퍼즐 도서관 | C2: 시끌벅적한 운동장 | D2: 캐릭터 문구점 | E2: 모바일 PC방 (분석자 비유)
A3: 가장 좋아하는 것 | B3: 짧게 머리 쓰는 퍼즐(정렬·잼, 블록, 탭 탈출, 단어) | C3: 축구, 총싸움, 오토바이, 블록 쌓기, 가상 펫 | D3: 캐릭터 RPG, 뽑기(가챠), 유명 IP 게임 | E3: 5대5 대전(MOBA)·배틀로얄, 블록·두뇌 퍼즐, 악기·파티 미니게임
A4: 구글 플레이 1위 | B4: 캐나다 Meowdoku / 미국 Rotate Rings | C4: 브라질·멕시코 모두 Roblox | D4: 일본 Meowdoku / 한국 FORTBLOX | E4: 인도네시아 Roblox (2026-10-05)
A5: 우리만의 특징 | B5: 미국 iOS의 리얼머니 게임, 캐나다 온라인 카지노 앱 | C5: 브라질 오토바이 '그라우' 게임 6개·축구 게임 6개, 멕시코 축구팀(Chivas) 게임·베팅 앱 | D5: 일본: 만화·캐릭터 IP, 리듬 게임, 포인트 적립(포이카츠) 게임, 고양이 / 한국: '뽑기 증정' 방치형 RPG, 고스톱·포커 | E5: MOBA 2개(Mobile Legends 2위, Honor of Kings 18위), 현지 시뮬레이터(Bus Simulator Indonesia 31위, Ojol Life 65위), 드럼·피아노 앱
A6: 주로 하는 사람(추정) | B6: 쉬는 시간에 하는 어른 | C6: 10대·친구 그룹 | D6: 캐릭터 팬·수집가 | E6: 확인 불가 (연령 자료 없음)
A7: 휴대폰 환경 | B7: 아이폰 비중 높음 | C7: 가벼운 안드로이드 폰 많음(추정) | D7: 일본은 게임 다운로드의 55%가 iOS | E7: 안드로이드 79.16% (StatCounter 2026-09, 웹 방문 기준)
A8: 퍼즐 비중 | B8: 매우 높음(미국 구글 플레이 53%) | C8: 낮음(브라질 Top 20 중 8개) | D8: 상위권은 높음, 중하위권은 IP·RPG | E8: ="Top 20 중 "&'2-7 동남아 분석'!B28&"개 (인도네시아, 수식)" -> Top 20 중 6개 (인도네시아, 수식)
A9: 게임 개발 시사점 | B9: 말이 필요 없는 단순 퍼즐, 빠른 신작 출시와 대규모 UA | C9: 가벼운 용량, 친구와 함께하는 재미, 축구·현지 문화 결합 | D9: 귀여운 캐릭터·유명 IP 협업(일본), 방치형 성장과 초반 대량 뽑기 이벤트(한국) | E9: 가벼운 안드로이드 대응, 친구와 짧게 겨루는 재미, 현지 소재(오토바이·버스·배달) 결합 — 분석자 제안

Sheet 2-2 국가별 Top20
A1: 지역 | B1: 국가 | C1: 기준일 | D1: 순위 | E1: 게임명 | F1: 퍼블리셔 | G1: 대분류 | H1: 출처
A2: 미국·캐나다 | B2: 캐나다 | C2: 2026-10-04 | D2: 1 | E2: Meowdoku: Brain Puzzle Games | F2: Oakever Games | G2: 퍼즐 | H2: AppBrain Google Play Top Free Games Canada https://www.appbrain.com/stats/google-play-rankings/top_free/game/ca
A3: 미국·캐나다 | B3: 캐나다 | C3: 2026-10-04 | D3: 2 | E3: Rotate Rings | F3: Nebula Studio | G3: 퍼즐 | H3: AppBrain Google Play Top Free Games Canada https://www.appbrain.com/stats/google-play-rankings/top_free/game/ca
A4: 미국·캐나다 | B4: 캐나다 | C4: 2026-10-04 | D4: 3 | E4: Roblox | F4: Roblox Corporation | G4: 기타(UGC·리워드) | H4: AppBrain Google Play Top Free Games Canada https://www.appbrain.com/stats/google-play-rankings/top_free/game/ca
A5: 미국·캐나다 | B5: 캐나다 | C5: 2026-10-04 | D5: 4 | E5: Magic Sort! | F5: Grand Games | G5: 퍼즐 | H5: AppBrain Google Play Top Free Games Canada https://www.appbrain.com/stats/google-play-rankings/top_free/game/ca
A6: 미국·캐나다 | B6: 캐나다 | C6: 2026-10-04 | D6: 5 | E6: Amaze GO! | F6: Oakever Games | G6: 퍼즐 | H6: AppBrain Google Play Top Free Games Canada https://www.appbrain.com/stats/google-play-rankings/top_free/game/ca
A7: 미국·캐나다 | B7: 캐나다 | C7: 2026-10-04 | D7: 6 | E7: Bus Fever Party! | F7: Lumi Games | G7: 퍼즐 | H7: AppBrain Google Play Top Free Games Canada https://www.appbrain.com/stats/google-play-rankings/top_free/game/ca
A8: 미국·캐나다 | B8: 캐나다 | C8: 2026-10-04 | D8: 7 | E8: Block Blast! | F8: Hungry Studio | G8: 퍼즐 | H8: AppBrain Google Play Top Free Games Canada https://www.appbrain.com/stats/google-play-rankings/top_free/game/ca
A9: 미국·캐나다 | B9: 캐나다 | C9: 2026-10-04 | D9: 8 | E9: Brain Puzzle 3: Crazy Mind | F9: JoyGame Studio | G9: 퍼즐 | H9: AppBrain Google Play Top Free Games Canada https://www.appbrain.com/stats/google-play-rankings/top_free/game/ca
A10: 미국·캐나다 | B10: 캐나다 | C10: 2026-10-04 | D10: 9 | E10: Vita Mahjong | F10: Vita Studio | G10: 퍼즐 | H10: AppBrain Google Play Top Free Games Canada https://www.appbrain.com/stats/google-play-rankings/top_free/game/ca
A11: 미국·캐나다 | B11: 캐나다 | C11: 2026-10-04 | D11: 10 | E11: Search It - Hidden Objects | F11: Leap Game Studios | G11: 퍼즐 | H11: AppBrain Google Play Top Free Games Canada https://www.appbrain.com/stats/google-play-rankings/top_free/game/ca
A12: 미국·캐나다 | B12: 캐나다 | C12: 2026-10-04 | D12: 11 | E12: MemeMix Challenge: Funny Party | F12: Amobear VN | G12: 파티·음악 | H12: AppBrain Google Play Top Free Games Canada https://www.appbrain.com/stats/google-play-rankings/top_free/game/ca
A13: 미국·캐나다 | B13: 캐나다 | C13: 2026-10-04 | D13: 12 | E13: Fish Sort Puzzle | F13: Shycheese | G13: 퍼즐 | H13: AppBrain Google Play Top Free Games Canada https://www.appbrain.com/stats/google-play-rankings/top_free/game/ca
... A101: 아시아 | B101: 한국 | C101: 2026-10-03 | D101: 20 | E101: Gossip Harbor: Merge & Story | F101: Microfun | G101: 퍼즐 | H101: AppBrain Google Play Top Free Games South Korea https://www.appbrain.com/stats/google-play-rankings/top_free/game/kr

Sheet 2-3 국가별 장르 분포
A1: 대분류 (Top 20 기준) | B1: 캐나다 | C1: 브라질 | D1: 멕시코 | E1: 일본 | F1: 한국
A2: 퍼즐 | B2: =COUNTIFS('2-2 국가별 Top20'!$B$2:$B$101,B$1,'2-2 국가별 Top20'!$G$2:$G$101,$A2) -> 16 | C2: =COUNTIFS('2-2 국가별 Top20'!$B$2:$B$101,C$1,'2-2 국가별 Top20'!$G$2:$G$101,$A2) -> 8 | D2: =COUNTIFS('2-2 국가별 Top20'!$B$2:$B$101,D$1,'2-2 국가별 Top20'!$G$2:$G$101,$A2) -> 7 | E2: =COUNTIFS('2-2 국가별 Top20'!$B$2:$B$101,E$1,'2-2 국가별 Top20'!$G$2:$G$101,$A2) -> 14 | F2: =COUNTIFS('2-2 국가별 Top20'!$B$2:$B$101,F$1,'2-2 국가별 Top20'!$G$2:$G$101,$A2) -> 10
A3: 하이퍼·하이브리드 캐주얼 | B3: =COUNTIFS('2-2 국가별 Top20'!$B$2:$B$101,B$1,'2-2 국가별 Top20'!$G$2:$G$101,$A3) -> 2 | C3: =COUNTIFS('2-2 국가별 Top20'!$B$2:$B$101,C$1,'2-2 국가별 Top20'!$G$2:$G$101,$A3) -> 3 | D3: =COUNTIFS('2-2 국가별 Top20'!$B$2:$B$101,D$1,'2-2 국가별 Top20'!$G$2:$G$101,$A3) -> 2 | E3: =COUNTIFS('2-2 국가별 Top20'!$B$2:$B$101,E$1,'2-2 국가별 Top20'!$G$2:$G$101,$A3) -> 2 | F3: =COUNTIFS('2-2 국가별 Top20'!$B$2:$B$101,F$1,'2-2 국가별 Top20'!$G$2:$G$101,$A3) -> 0
A4: 카드·보드·카지노 | B4: =COUNTIFS('2-2 국가별 Top20'!$B$2:$B$101,B$1,'2-2 국가별 Top20'!$G$2:$G$101,$A4) -> 0 | C4: =COUNTIFS('2-2 국가별 Top20'!$B$2:$B$101,C$1,'2-2 국가별 Top20'!$G$2:$G$101,$A4) -> 0 | D4: =COUNTIFS('2-2 국가별 Top20'!$B$2:$B$101,D$1,'2-2 국가별 Top20'!$G$2:$G$101,$A4) -> 0 | E4: =COUNTIFS('2-2 국가별 Top20'!$B$2:$B$101,E$1,'2-2 국가별 Top20'!$G$2:$G$101,$A4) -> 0 | F4: =COUNTIFS('2-2 국가별 Top20'!$B$2:$B$101,F$1,'2-2 국가별 Top20'!$G$2:$G$101,$A4) -> 2
A5: 시뮬레이션 | B5: =COUNTIFS('2-2 국가별 Top20'!$B$2:$B$101,B$1,'2-2 국가별 Top20'!$G$2:$G$101,$A5) -> 0 | C5: =COUNTIFS('2-2 국가별 Top20'!$B$2:$B$101,C$1,'2-2 국가별 Top20'!$G$2:$G$101,$A5) -> 4 | D5: =COUNTIFS('2-2 국가별 Top20'!$B$2:$B$101,D$1,'2-2 국가별 Top20'!$G$2:$G$101,$A5) -> 4 | E5: =COUNTIFS('2-2 국가별 Top20'!$B$2:$B$101,E$1,'2-2 국가별 Top20'!$G$2:$G$101,$A5) -> 1 | F5: =COUNTIFS('2-2 국가별 Top20'!$B$2:$B$101,F$1,'2-2 국가별 Top20'!$G$2:$G$101,$A5) -> 0
A6: 전략 | B6: =COUNTIFS('2-2 국가별 Top20'!$B$2:$B$101,B$1,'2-2 국가별 Top20'!$G$2:$G$101,$A6) -> 0 | C6: =COUNTIFS('2-2 국가별 Top20'!$B$2:$B$101,C$1,'2-2 국가별 Top20'!$G$2:$G$101,$A6) -> 1 | D6: =COUNTIFS('2-2 국가별 Top20'!$B$2:$B$101,D$1,'2-2 국가별 Top20'!$G$2:$G$101,$A6) -> 1 | E6: =COUNTIFS('2-2 국가별 Top20'!$B$2:$B$101,E$1,'2-2 국가별 Top20'!$G$2:$G$101,$A6) -> 1 | F6: =COUNTIFS('2-2 국가별 Top20'!$B$2:$B$101,F$1,'2-2 국가별 Top20'!$G$2:$G$101,$A6) -> 1
A7: 액션·슈팅 | B7: =COUNTIFS('2-2 국가별 Top20'!$B$2:$B$101,B$1,'2-2 국가별 Top20'!$G$2:$G$101,$A7) -> 0 | C7: =COUNTIFS('2-2 국가별 Top20'!$B$2:$B$101,C$1,'2-2 국가별 Top20'!$G$2:$G$101,$A7) -> 1 | D7: =COUNTIFS('2-2 국가별 Top20'!$B$2:$B$101,D$1,'2-2 국가별 Top20'!$G$2:$G$101,$A7) -> 1 | E7: =COUNTIFS('2-2 국가별 Top20'!$B$2:$B$101,E$1,'2-2 국가별 Top20'!$G$2:$G$101,$A7) -> 0 | F7: =COUNTIFS('2-2 국가별 Top20'!$B$2:$B$101,F$1,'2-2 국가별 Top20'!$G$2:$G$101,$A7) -> 0
A8: 스포츠 | B8: =COUNTIFS('2-2 국가별 Top20'!$B$2:$B$101,B$1,'2-2 국가별 Top20'!$G$2:$G$101,$A8) -> 0 | C8: =COUNTIFS('2-2 국가별 Top20'!$B$2:$B$101,C$1,'2-2 국가별 Top20'!$G$2:$G$101,$A8) -> 1 | D8: =COUNTIFS('2-2 국가별 Top20'!$B$2:$B$101,D$1,'2-2 국가별 Top20'!$G$2:$G$101,$A8) -> 3 | E8: =COUNTIFS('2-2 국가별 Top20'!$B$2:$B$101,E$1,'2-2 국가별 Top20'!$G$2:$G$101,$A8) -> 0 | F8: =COUNTIFS('2-2 국가별 Top20'!$B$2:$B$101,F$1,'2-2 국가별 Top20'!$G$2:$G$101,$A8) -> 0
A9: RPG | B9: =COUNTIFS('2-2 국가별 Top20'!$B$2:$B$101,B$1,'2-2 국가별 Top20'!$G$2:$G$101,$A9) -> 0 | C9: =COUNTIFS('2-2 국가별 Top20'!$B$2:$B$101,C$1,'2-2 국가별 Top20'!$G$2:$G$101,$A9) -> 0 | D9: =COUNTIFS('2-2 국가별 Top20'!$B$2:$B$101,D$1,'2-2 국가별 Top20'!$G$2:$G$101,$A9) -> 0 | E9: =COUNTIFS('2-2 국가별 Top20'!$B$2:$B$101,E$1,'2-2 국가별 Top20'!$G$2:$G$101,$A9) -> 1 | F9: =COUNTIFS('2-2 국가별 Top20'!$B$2:$B$101,F$1,'2-2 국가별 Top20'!$G$2:$G$101,$A9) -> 4
A10: 파티·음악 | B10: =COUNTIFS('2-2 국가별 Top20'!$B$2:$B$101,B$1,'2-2 국가별 Top20'!$G$2:$G$101,$A10) -> 1 | C10: =COUNTIFS('2-2 국가별 Top20'!$B$2:$B$101,C$1,'2-2 국가별 Top20'!$G$2:$G$101,$A10) -> 0 | D10: =COUNTIFS('2-2 국가별 Top20'!$B$2:$B$101,D$1,'2-2 국가별 Top20'!$G$2:$G$101,$A10) -> 1 | E10: =COUNTIFS('2-2 국가별 Top20'!$B$2:$B$101,E$1,'2-2 국가별 Top20'!$G$2:$G$101,$A10) -> 0 | F10: =COUNTIFS('2-2 국가별 Top20'!$B$2:$B$101,F$1,'2-2 국가별 Top20'!$G$2:$G$101,$A10) -> 0
A11: 기타(UGC·리워드) | B11: =COUNTIFS('2-2 국가별 Top20'!$B$2:$B$101,B$1,'2-2 국가별 Top20'!$G$2:$G$101,$A11) -> 1 | C11: =COUNTIFS('2-2 국가별 Top20'!$B$2:$B$101,C$1,'2-2 국가별 Top20'!$G$2:$G$101,$A11) -> 1 | D11: =COUNTIFS('2-2 국가별 Top20'!$B$2:$B$101,D$1,'2-2 국가별 Top20'!$G$2:$G$101,$A11) -> 1 | E11: =COUNTIFS('2-2 국가별 Top20'!$B$2:$B$101,E$1,'2-2 국가별 Top20'!$G$2:$G$101,$A11) -> 1 | F11: =COUNTIFS('2-2 국가별 Top20'!$B$2:$B$101,F$1,'2-2 국가별 Top20'!$G$2:$G$101,$A11) -> 1
A12: 확인 불가 | B12: =COUNTIFS('2-2 국가별 Top20'!$B$2:$B$101,B$1,'2-2 국가별 Top20'!$G$2:$G$101,$A12) -> 0 | C12: =COUNTIFS('2-2 국가별 Top20'!$B$2:$B$101,C$1,'2-2 국가별 Top20'!$G$2:$G$101,$A12) -> 0 | D12: =COUNTIFS('2-2 국가별 Top20'!$B$2:$B$101,D$1,'2-2 국가별 Top20'!$G$2:$G$101,$A12) -> 0 | E12: =COUNTIFS('2-2 국가별 Top20'!$B$2:$B$101,E$1,'2-2 국가별 Top20'!$G$2:$G$101,$A12) -> 0 | F12: =COUNTIFS('2-2 국가별 Top20'!$B$2:$B$101,F$1,'2-2 국가별 Top20'!$G$2:$G$101,$A12) -> 0
A13: 확인 필요 | B13: =COUNTIFS('2-2 국가별 Top20'!$B$2:$B$101,B$1,'2-2 국가별 Top20'!$G$2:$G$101,$A13) -> 0 | C13: =COUNTIFS('2-2 국가별 Top20'!$B$2:$B$101,C$1,'2-2 국가별 Top20'!$G$2:$G$101,$A13) -> 1 | D13: =COUNTIFS('2-2 국가별 Top20'!$B$2:$B$101,D$1,'2-2 국가별 Top20'!$G$2:$G$101,$A13) -> 0 | E13: =COUNTIFS('2-2 국가별 Top20'!$B$2:$B$101,E$1,'2-2 국가별 Top20'!$G$2:$G$101,$A13) -> 0 | F13: =COUNTIFS('2-2 국가별 Top20'!$B$2:$B$101,F$1,'2-2 국가별 Top20'!$G$2:$G$101,$A13) -> 2
A14: 합계 | B14: =SUM(B2:B13) -> 20 | C14: =SUM(C2:C13) -> 20 | D14: =SUM(D2:D13) -> 20 | E14: =SUM(E2:E13) -> 20 | F14: =SUM(F2:F13) -> 20
A16: 참고: 각 국가 구글 플레이 Top 20만 분류한 값입니다. 미국 전체 Top 100 분포는 '1-3 장르 분포' 시트를 보세요.

Sheet 2-4 공통 인기 게임
A1: 게임명 | B1: 미국 GP | C1: 캐나다 | D1: 브라질 | E1: 멕시코 | F1: 일본 | G1: 한국 | H1: 등장 국가 수 (6개국 중)
A2: Block Blast! | B2: 7 | C2: 7 | D2: 9 | E2: 4 | F2: 3 | G2: 8 | H2: =COUNT(B2:G2) -> 6
A3: Meowdoku | B3: 2 | C3: 1 | D3: 4 | E3: 39 | F3: 1 | G3: 18 | H3: =COUNT(B3:G3) -> 6
A4: Magic Sort! | B4: 11 | C4: 4 | D4: 50 | E4: 33 | F4: 36 | G4: 7 | H4: =COUNT(B4:G4) -> 6
A5: Bus Fever Party! | B5: 8 | C5: 6 | D5: 3 | E5: 2 | F5: 10 | G5: 38 | H5: =COUNT(B5:G5) -> 6
A6: Roblox | B6: 4 | C6: 3 | D6: 1 | E6: 1 | F6: 13 | G6: 10 | H6: =COUNT(B6:G6) -> 6
A7: Vita Mahjong | B7: 5 | C7: 9 | D7: 29 | E7: 15 | F7: 34 | G7: 26 | H7: =COUNT(B7:G7) -> 6
A8: Rotate Rings | B8: 1 | C8: 2 | D8: 8 | E8: - | F8: 2 | G8: 5 | H8: =COUNT(B8:G8) -> 5
A9: Royal Match | B9: 42 | C9: 25 | D9: - | E9: - | F9: 16 | G9: 21 | H9: =COUNT(B9:G9) -> 4
A11: 숫자는 각 국가 구글 플레이 Top Free Games 순위, '-'는 Top 100 밖.
A12: Rotate Rings가 멕시코에 없는 것은 멕시코 자료가 9/25 기준으로 더 오래됐기 때문일 수 있음.
A13: 정정: 이전 답변에서 Royal Match를 '모든 지역 공통'으로 소개했으나, 브라질·멕시코 Top 100에는 없음.

Sheet 2-5 지역별 특징
A1: 지역 | B1: 국가 | C1: 특징 | D1: 근거 게임 (순위) | E1: 분류
A2: 미국·캐나다 | B2: 캐나다 | C2: 미국과 거의 동일한 퍼즐 중심 차트 | D2: Meowdoku(1), Rotate Rings(2), Magic Sort(4), Amaze GO!(5), Block Blast(7) | E2: 데이터
A3: 미국·캐나다 | B3: 캐나다 | C3: 온라인 카지노 앱 진입 | D3: Jackpot City: Online Casino(33) | E3: 데이터
A4: 미국·캐나다 | B4: 캐나다 | C4: 단어 퍼즐 인기 | D4: Word Tiles(20), Crossword Go!(44), Words of Wonders(60, 74) | E4: 데이터
A5: 남미 | B5: 브라질 | C5: Roblox·Free Fire가 1·2위 | D5: Roblox(1), Free Fire x NARUTO(2) | E5: 데이터
A6: 남미 | B6: 브라질 | C6: Free Fire는 저사양 폰에서도 잘 돌아간다는 평가, 브라질 투표 인기 1위 수상 이력 | D6: Wikipedia Free Fire 문서 | E6: 외부 자료
A7: 남미 | B7: 브라질 | C7: 축구 게임 6개 | D7: Football League 2026(10), eFootball(27), EA FC 27(34), Soccer Superstar(40), Mini Soccer(60), Dream League Soccer(94) | E7: 데이터
A8: 남미 | B8: 브라질 | C8: 오토바이 앞바퀴 들기(그라우) 게임 6개 | D8: Moto Wheelie 3D(28), Elite Auto Brazil(31), Wheelie Master(43), Wheelie Life(46), Moto Wheelie Traffic(55), Projeto Grau(100) | E8: 데이터
A9: 남미 | B9: 브라질 | C9: 블록 쌓기·샌드박스 | D9: Minecraft Trial(12), Block World(15), Craft World(19), School Party Craft(21), Block Craft 3D(26) | E9: 데이터
A10: 남미 | B10: 브라질 | C10: 가상 펫·키즈 게임 | D10: Pou(24), My Talking Tom 2(37), My Talking Angela 2(42), Piano Kids(32), Bluey(76), BabyBus(82) | E10: 데이터
A11: 남미 | B11: 브라질 | C11: 온라인 롤플레이 라이프 시뮬 | D11: BLACK RUSSIA(7), Rio Rise(83) | E11: 데이터
A12: 남미 | B12: 멕시코 | C12: 미국식 퍼즐 + 남미식 축구·Free Fire 혼합 | D12: Bus Fever Party(2), Block Blast(4), Free Fire(3), Chivas(6), EA FC 27(12) | E12: 데이터
... A27: 아시아 | B27: 한국 | C27: 해외 SLG/RPG의 한국어 현지화 출시 | D27: X 클래시(66), 라스트 에코(93), 삼국지: 제후의 전쟁(42) | E27: 데이터

Sheet 2-6 대륙별 OS 분포
A1: 표 A. 모바일 OS 사용 점유율 — StatCounter (웹사이트 방문(페이지뷰) 기준이라 '기기 대수'와 다를 수 있음)
A2: 구분 | B2: 지역 | C2: Android | D2: iOS | E2: 기타 (수식) | F2: 더 많은 OS (수식) | G2: 기준 월 | H2: 출처 | I2: 비고
A3: 세계 | B3: 세계 | C3: 0.6917 | D3: 0.3081 | E3: =IF(ISNUMBER(C3),1-C3-D3,"") -> 0.0002 | F3: =IF(ISNUMBER(C3),IF(C3>=D3,"Android","iOS"),"미조사") -> Android | G3: 2026-09 | H3: https://gs.statcounter.com/os-market-share/mobile/worldwide
A4: 대륙 | B4: 북미 | C4: 0.4695 | D4: 0.5303 | E4: =IF(ISNUMBER(C4),1-C4-D4,"") -> 0.0002 | F4: =IF(ISNUMBER(C4),IF(C4>=D4,"Android","iOS"),"미조사") -> iOS | G4: 2026-09 | H4: https://gs.statcounter.com/os-market-share/mobile/north-america | I4: StatCounter는 멕시코를 북미에 포함
A5: 대륙 | B5: 남미 | C5: 0.8353 | D5: 0.1646 | E5: =IF(ISNUMBER(C5),1-C5-D5,"") -> 0.0001 | F5: =IF(ISNUMBER(C5),IF(C5>=D5,"Android","iOS"),"미조사") -> Android | G5: 2026-09 | H5: https://gs.statcounter.com/os-market-share/mobile/south-america
A6: 대륙 | B6: 유럽 | C6: 0.6468 | D6: 0.3531 | E6: =IF(ISNUMBER(C6),1-C6-D6,"") -> 0.0001 | F6: =IF(ISNUMBER(C6),IF(C6>=D6,"Android","iOS"),"미조사") -> Android | G6: 2026-09 | H6: https://gs.statcounter.com/os-market-share/mobile/europe
A7: 대륙 | B7: 아시아 | C7: 0.7847 | D7: 0.2149 | E7: =IF(ISNUMBER(C7),1-C7-D7,"") -> 0.0004 | F7: =IF(ISNUMBER(C7),IF(C7>=D7,"Android","iOS"),"미조사") -> Android | G7: 2026-09 | H7: https://gs.statcounter.com/os-market-share/mobile/asia
A8: 대륙 | B8: 오세아니아 | C8: 0.3825 | D8: 0.6173 | E8: =IF(ISNUMBER(C8),1-C8-D8,"") -> 0.0002 | F8: =IF(ISNUMBER(C8),IF(C8>=D8,"Android","iOS"),"미조사") -> iOS | G8: 2026-08 | H8: https://gs.statcounter.com/os-market-share/mobile/oceania | I8: 조회 시점 페이지에 9월 값이 아직 없어 8월 값 사용
A9: 대륙 | B9: 아프리카 | C9: 0.8338 | D9: 0.1658 | E9: =IF(ISNUMBER(C9),1-C9-D9,"") -> 0.0004 | F9: =IF(ISNUMBER(C9),IF(C9>=D9,"Android","iOS"),"미조사") -> Android | G9: 2026-09 | H9: https://gs.statcounter.com/os-market-share/mobile/africa
A10: 국가 | B10: 미국 | C10: 0.4639 | D10: 0.5359 | E10: =IF(ISNUMBER(C10),1-C10-D10,"") -> 0.0002 | F10: =IF(ISNUMBER(C10),IF(C10>=D10,"Android","iOS"),"미조사") -> iOS | G10: 2026-09 | H10: https://gs.statcounter.com/os-market-share/mobile/united-states-of-america
A11: 국가 | B11: 캐나다 | C11: 0.3513 | D11: 0.6487 | E11: =IF(ISNUMBER(C11),1-C11-D11,"") -> 0 | F11: =IF(ISNUMBER(C11),IF(C11>=D11,"Android","iOS"),"미조사") -> iOS | G11: 2026-09 | H11: https://gs.statcounter.com/os-market-share/mobile/canada
A12: 국가 | B12: 브라질 | C12: 0.7878 | D12: 0.2121 | E12: =IF(ISNUMBER(C12),1-C12-D12,"") -> 0.0001 | F12: =IF(ISNUMBER(C12),IF(C12>=D12,"Android","iOS"),"미조사") -> Android | G12: 2026-09 | H12: https://gs.statcounter.com/os-market-share/mobile/brazil
A13: 국가 | B13: 멕시코 | C13: 0.7204 | D13: 0.2796 | E13: =IF(ISNUMBER(C13),1-C13-D13,"") -> 0 | F13: =IF(ISNUMBER(C13),IF(C13>=D13,"Android","iOS"),"미조사") -> Android | G13: 2026-09 | H13: https://gs.statcounter.com/os-market-share/mobile/mexico
A14: 국가 | B14: 일본 | C14: 0.3949 | D14: 0.6051 | E14: =IF(ISNUMBER(C14),1-C14-D14,"") -> 0 | F14: =IF(ISNUMBER(C14),IF(C14>=D14,"Android","iOS"),"미조사") -> iOS | G14: 2026-09 | H14: https://gs.statcounter.com/os-market-share/mobile/japan | I14: 아시아 평균(안드로이드 78%)과 반대로 아이폰이 더 많음
A15: 국가 | B15: 한국 | C15: 0.6218 | D15: 0.3782 | E15: =IF(ISNUMBER(C15),1-C15-D15,"") -> 0 | F15: =IF(ISNUMBER(C15),IF(C15>=D15,"Android","iOS"),"미조사") -> Android | G15: 2026-09 | H15: https://gs.statcounter.com/os-market-share/mobile/south-korea
A16: 국가 | B16: 인도네시아 | C16: 0.7916 | D16: 0.2079 | E16: =IF(ISNUMBER(C16),1-C16-D16,"") -> 0.0005 | F16: =IF(ISNUMBER(C16),IF(C16>=D16,"Android","iOS"),"미조사") -> Android | G16: 2026-09 | H16: https://gs.statcounter.com/os-market-share/mobile/indonesia
A17: 국가 | B17: 태국 | C17: 0.7396 | D17: 0.2601 | E17: =IF(ISNUMBER(C17),1-C17-D17,"") -> 0.0003 | F17: =IF(ISNUMBER(C17),IF(C17>=D17,"Android","iOS"),"미조사") -> Android | G17: 2026-09 | H17: https://gs.statcounter.com/os-market-share/mobile/thailand
A18: 국가 | B18: 베트남 | C18: 0.5979 | D18: 0.4019 | E18: =IF(ISNUMBER(C18),1-C18-D18,"") -> 0.0002 | F18: =IF(ISNUMBER(C18),IF(C18>=D18,"Android","iOS"),"미조사") -> Android | G18: 2026-09 | H18: https://gs.statcounter.com/os-market-share/mobile/viet-nam
A19: 국가 | B19: 필리핀 | C19: 0.8653 | D19: 0.1347 | E19: =IF(ISNUMBER(C19),1-C19-D19,"") -> 0 | F19: =IF(ISNUMBER(C19),IF(C19>=D19,"Android","iOS"),"미조사") -> Android | G19: 2026-09 | H19: https://gs.statcounter.com/os-market-share/mobile/philippines
A20: 국가 | B20: 말레이시아 | C20: 0.5523 | D20: 0.4475 | E20: =IF(ISNUMBER(C20),1-C20-D20,"") -> 0.0002 | F20: =IF(ISNUMBER(C20),IF(C20>=D20,"Android","iOS"),"미조사") -> Android | G20: 2026-09 | H20: https://gs.statcounter.com/os-market-share/mobile/malaysia
A21: 국가(참고) | B21: 싱가포르 | C21: 0.5625 | D21: 0.4369 | E21: =IF(ISNUMBER(C21),1-C21-D21,"") -> 0.0006 | F21: =IF(ISNUMBER(C21),IF(C21>=D21,"Android","iOS"),"미조사") -> Android | G21: 2026-09 | H21: https://gs.statcounter.com/os-market-share/mobile/singapore | I21: Top20 조사에서는 제외, OS만 참고
A23: 표 B. 게임 이용자 중 OS별 비율
A24: 구분 | B24: 지역 | C24: Android | D24: iOS | E24: 비고
B25: 세계 | C25: 확인 불가 | D25: 확인 불가 | E25: 공개 자료를 찾지 못함 (표 A의 웹 점유율과 다른 숫자라 대신 쓰지 않음)
B26: 북미 | C26: 확인 불가 | D26: 확인 불가 | E26: 공개 자료를 찾지 못함 (표 A의 웹 점유율과 다른 숫자라 대신 쓰지 않음)
B27: 남미 | C27: 확인 불가 | D27: 확인 불가 | E27: 공개 자료를 찾지 못함 (표 A의 웹 점유율과 다른 숫자라 대신 쓰지 않음)
B28: 유럽 | C28: 확인 불가 | D28: 확인 불가 | E28: 공개 자료를 찾지 못함 (표 A의 웹 점유율과 다른 숫자라 대신 쓰지 않음)
B29: 아시아 | C29: 확인 불가 | D29: 확인 불가 | E29: 공개 자료를 찾지 못함 (표 A의 웹 점유율과 다른 숫자라 대신 쓰지 않음)
B30: 오세아니아 | C30: 확인 불가 | D30: 확인 불가 | E30: 공개 자료를 찾지 못함 (표 A의 웹 점유율과 다른 숫자라 대신 쓰지 않음)
B31: 아프리카 | C31: 확인 불가 | D31: 확인 불가 | E31: 공개 자료를 찾지 못함 (표 A의 웹 점유율과 다른 숫자라 대신 쓰지 않음)
A33: 표 C. OS(스토어)별 모바일 게임 매출 — 2025년, 세계
A34: 지역 | B34: App Store 매출 ($B) | C34: Google Play 매출 ($B) | D34: App Store 비율 (수식) | E34: Google Play 비율 (수식) | F34: 출처
A35: 세계 | B35: 52.5 | C35: 30 | D35: =B35/(B35+C35) -> 0.63636364 | E35: =C35/(B35+C35) -> 0.36363636 | F35: Sensor Tower State of Gaming 2026 (2025년 데이터) — 9to5Mac 보도 https://9to5mac.com/?p=1040750
A36: 대륙·국가별 | B36: 확인 불가 | C36: 확인 불가 | F36: 공개 자료를 찾지 못함
A37: Google Play 매출에는 중국 안드로이드 마켓이 포함되지 않음(Google Play만 집계). App Store 매출은 중국 포함.
A39: 표 D (참고). OS(스토어)별 모바일 게임 다운로드 — 2025년, 세계 (표 A·B·C와 또 다른 숫자)
A40: 지역 | B40: App Store 다운로드 (억 건) | C40: Google Play 다운로드 (억 건) | D40: App Store 비율 (수식) | E40: Google Play 비율 (수식) | F40: 출처
A41: 세계 | B41: 78 | C41: 424 | D41: =B41/(B41+C41) -> 0.15537849 | E41: =C41/(B41+C41) -> 0.84462151 | F41: Sensor Tower State of Gaming 2026 — 9to5Mac 보도 (App Store 7.8B, Google Play 42.4B)
A43: OS 출시 우선순위 — 분석자 제안 (사실이 아닌 판단)
A44: iOS 먼저(또는 동시) 기준: iOS 점유율이 이 값 이상 | C44: 0.5 | D44: ← 가정값(분석자 제안). 바꾸면 아래 판단이 자동으로 바뀜
...

Sheet 2-7 동남아 분석
A1: ① 인도네시아 구글 플레이 무료 게임 Top20
A2: 지역 | B2: 국가 | C2: 기준일 | D2: 순위 | E2: 게임명 | F2: 퍼블리셔 | G2: 대분류 | H2: 출처 | I2: 비고
A3: 동남아 | B3: 인도네시아 | C3: 2026-10-05 | D3: 1 | E3: Roblox | F3: Roblox Corporation | G3: 기타(UGC·리워드) | H3: AppBrain Google Play Top Free Games Indonesia https://www.appbrain.com/stats/google-play-rankings/top_free/game/id
A4: 동남아 | B4: 인도네시아 | C4: 2026-10-05 | D4: 2 | E4: Mobile Legends: Bang Bang | F4: MOONTON | G4: 액션·슈팅 | H4: AppBrain Google Play Top Free Games Indonesia https://www.appbrain.com/stats/google-play-rankings/top_free/game/id | I4: MOBA — 기존 분류표에 MOBA 칸이 없어 '액션·슈팅'에 넣음(분석자 판단)
A5: 동남아 | B5: 인도네시아 | C5: 2026-10-05 | D5: 3 | E5: Block Blast! | F5: HungryStudio | G5: 퍼즐 | H5: AppBrain Google Play Top Free Games Indonesia https://www.appbrain.com/stats/google-play-rankings/top_free/game/id
A6: 동남아 | B6: 인도네시아 | C6: 2026-10-05 | D6: 4 | E6: Free Fire x NARUTO SHIPPUDEN | F6: Garena | G6: 액션·슈팅 | H6: AppBrain Google Play Top Free Games Indonesia https://www.appbrain.com/stats/google-play-rankings/top_free/game/id | I6: 배틀로얄
A7: 동남아 | B7: 인도네시아 | C7: 2026-10-05 | D7: 5 | E7: Easy Drum - Real Music Drum | F7: AVA GAMES | G7: 파티·음악 | H7: AppBrain Google Play Top Free Games Indonesia https://www.appbrain.com/stats/google-play-rankings/top_free/game/id | I7: 확인 필요 — 악기 연주 앱
A8: 동남아 | B8: 인도네시아 | C8: 2026-10-05 | D8: 6 | E8: Brain Puzzle 2: Logic Twist | F8: JoyGame Studio | G8: 퍼즐 | H8: AppBrain Google Play Top Free Games Indonesia https://www.appbrain.com/stats/google-play-rankings/top_free/game/id
A9: 동남아 | B9: 인도네시아 | C9: 2026-10-05 | D9: 7 | E9: Color Block: Combo Blast | F9: Ivy | G9: 퍼즐 | H9: AppBrain Google Play Top Free Games Indonesia https://www.appbrain.com/stats/google-play-rankings/top_free/game/id
A10: 동남아 | B10: 인도네시아 | C10: 2026-10-05 | D10: 8 | E10: Fruit Wins | F10: Buddyplay Limited | G10: 확인 필요 | H10: AppBrain Google Play Top Free Games Indonesia https://www.appbrain.com/stats/google-play-rankings/top_free/game/id | I10: 확인 필요 — 게임 방식 확인 안 됨
A11: 동남아 | B11: 인도네시아 | C11: 2026-10-05 | D11: 9 | E11: Brain Puzzle 3: Crazy Mind | F11: JoyGame Studio | G11: 퍼즐 | H11: AppBrain Google Play Top Free Games Indonesia https://www.appbrain.com/stats/google-play-rankings/top_free/game/id
A12: 동남아 | B12: 인도네시아 | C12: 2026-10-05 | D12: 10 | E12: Gossip Harbor: Merge & Story | F12: Microfun | G12: 퍼즐 | H12: AppBrain Google Play Top Free Games Indonesia https://www.appbrain.com/stats/google-play-rankings/top_free/game/id | I12: 머지
A13: 동남아 | B13: 인도네시아 | C13: 2026-10-05 | D13: 11 | E13: Water Go | F13: MicroSurge | G13: 확인 필요 | H13: AppBrain Google Play Top Free Games Indonesia https://www.appbrain.com/stats/google-play-rankings/top_free/game/id | I13: 확인 필요 — 게임 방식 확인 안 됨
A14: 동남아 | B14: 인도네시아 | C14: 2026-10-05 | D14: 12 | E14: Stickman Party 234 MiniGames | F14: PlayMax Game Studio | G14: 파티·음악 | H14: AppBrain Google Play Top Free Games Indonesia https://www.appbrain.com/stats/google-play-rankings/top_free/game/id | I14: 로컬 멀티 미니게임
A15: 동남아 | B15: 인도네시아 | C15: 2026-10-05 | D15: 13 | E15: Bus Fever Party! | F15: Lumi Games | G15: 퍼즐 | H15: AppBrain Google Play Top Free Games Indonesia https://www.appbrain.com/stats/google-play-rankings/top_free/game/id | I15: 버스잼
A16: 동남아 | B16: 인도네시아 | C16: 2026-10-05 | D16: 14 | E16: School Party Craft | F16: Candy Room Games & RabbitCo | G16: 시뮬레이션 | H16: AppBrain Google Play Top Free Games Indonesia https://www.appbrain.com/stats/google-play-rankings/top_free/game/id | I16: 샌드박스
A17: 동남아 | B17: 인도네시아 | C17: 2026-10-05 | D17: 15 | E17: MemeMix Challenge: Funny Party | F17: Amobear VN Game Global | G17: 파티·음악 | H17: AppBrain Google Play Top Free Games Indonesia https://www.appbrain.com/stats/google-play-rankings/top_free/game/id
A18: 동남아 | B18: 인도네시아 | C18: 2026-10-05 | D18: 16 | E18: My Talking Tom 2: Pet Game | F18: Outfit7 | G18: 시뮬레이션 | H18: AppBrain Google Play Top Free Games Indonesia https://www.appbrain.com/stats/google-play-rankings/top_free/game/id | I18: 가상 펫
A19: 동남아 | B19: 인도네시아 | C19: 2026-10-05 | D19: 17 | E19: Football League 2026 | F19: MOBILE SOCCER | G19: 스포츠 | H19: AppBrain Google Play Top Free Games Indonesia https://www.appbrain.com/stats/google-play-rankings/top_free/game/id | I19: 축구
A20: 동남아 | B20: 인도네시아 | C20: 2026-10-05 | D20: 18 | E20: Honor of Kings | F20: Level Infinite | G20: 액션·슈팅 | H20: AppBrain Google Play Top Free Games Indonesia https://www.appbrain.com/stats/google-play-rankings/top_free/game/id | I20: MOBA — 위 Mobile Legends와 같은 기준
A21: 동남아 | B21: 인도네시아 | C21: 2026-10-05 | D21: 19 | E21: Super Bear Adventure | F21: Earthkwak Games | G21: 하이퍼·하이브리드 캐주얼 | H21: AppBrain Google Play Top Free Games Indonesia https://www.appbrain.com/stats/google-play-rankings/top_free/game/id | I21: 3D 플랫포머 (1-2의 플랫포머 분류 기준을 따름)
A22: 동남아 | B22: 인도네시아 | C22: 2026-10-05 | D22: 20 | E22: 8 Ball Pool | F22: Miniclip.com | G22: 스포츠 | H22: AppBrain Google Play Top Free Games Indonesia https://www.appbrain.com/stats/google-play-rankings/top_free/game/id | I22: 당구 PvP
A24: 태국·베트남·필리핀·말레이시아 Top20: 확인 불가 — AppBrain 국가 목록(30개국)에 이 4개국이 없음(2026-10-05 확인). 42matters 공개 페이지는 'Last update 16 Feb 2025'에 Top10만 있음, appfigures·FoxData는 로그인/스크립트가 필요해 읽지 못함. 싱가포르는 제외(분석자 제안대로).
A26: ② 장르 집계 (Top 20 기준, 수식)
A27: 대분류 (Top 20 기준) | B27: 인도네시아 | C27: 태국 | D27: 베트남 | E27: 필리핀 | F27: 말레이시아
A28: 퍼즐 | B28: =COUNTIFS($B$3:$B$22,B$27,$G$3:$G$22,$A28) -> 6 | C28: 확인 불가 | D28: 확인 불가 | E28: 확인 불가 | F28: 확인 불가
A29: 하이퍼·하이브리드 캐주얼 | B29: =COUNTIFS($B$3:$B$22,B$27,$G$3:$G$22,$A29) -> 1 | C29: 확인 불가 | D29: 확인 불가 | E29: 확인 불가 | F29: 확인 불가
A30: 카드·보드·카지노 | B30: =COUNTIFS($B$3:$B$22,B$27,$G$3:$G$22,$A30) -> 0 | C30: 확인 불가 | D30: 확인 불가 | E30: 확인 불가 | F30: 확인 불가
A31: 시뮬레이션 | B31: =COUNTIFS($B$3:$B$22,B$27,$G$3:$G$22,$A31) -> 2 | C31: 확인 불가 | D31: 확인 불가 | E31: 확인 불가 | F31: 확인 불가
A32: 전략 | B32: =COUNTIFS($B$3:$B$22,B$27,$G$3:$G$22,$A32) -> 0 | C32: 확인 불가 | D32: 확인 불가 | E32: 확인 불가 | F32: 확인 불가
A33: 액션·슈팅 | B33: =COUNTIFS($B$3:$B$22,B$27,$G$3:$G$22,$A33) -> 3 | C33: 확인 불가 | D33: 확인 불가 | E33: 확인 불가 | F33: 확인 불가
A34: 스포츠 | B34: =COUNTIFS($B$3:$B$22,B$27,$G$3:$G$22,$A34) -> 2 | C34: 확인 불가 | D34: 확인 불가 | E34: 확인 불가 | F34: 확인 불가
A35: RPG | B35: =COUNTIFS($B$3:$B$22,B$27,$G$3:$G$22,$A35) -> 0 | C35: 확인 불가 | D35: 확인 불가 | E35: 확인 불가 | F35: 확인 불가
A36: 파티·음악 | B36: =COUNTIFS($B$3:$B$22,B$27,$G$3:$G$22,$A36) -> 3 | C36: 확인 불가 | D36: 확인 불가 | E36: 확인 불가 | F36: 확인 불가
A37: 기타(UGC·리워드) | B37: =COUNTIFS($B$3:$B$22,B$27,$G$3:$G$22,$A37) -> 1 | C37: 확인 불가 | D37: 확인 불가 | E37: 확인 불가 | F37: 확인 불가
A38: 확인 불가 | B38: =COUNTIFS($B$3:$B$22,B$27,$G$3:$G$22,$A38) -> 0 | C38: 확인 불가 | D38: 확인 불가 | E38: 확인 불가 | F38: 확인 불가
A39: 확인 필요 | B39: =COUNTIFS($B$3:$B$22,B$27,$G$3:$G$22,$A39) -> 2 | C39: 확인 불가 | D39: 확인 불가 | E39: 확인 불가 | F39: 확인 불가
A40: 합계 | B40: =SUM(B28:B39) -> 20 | C40: 확인 불가 | D40: 확인 불가 | E40: 확인 불가 | F40: 확인 불가
A42: ③ 공통 인기 게임 — 기존 6개국 공통 게임이 인도네시아에서는 몇 위인가
A43: 게임명 | B43: 기존 6개국 등장 수 (2-4에서 가져옴) | C43: 인도네시아 순위 (Top100) | D43: 7개국 등장 수 (수식)
...

Sheet 3-1 매출 순위 원자료
A1: 국가 | B1: 기준일 | C1: 출처 | D1: Top 10 (구글 플레이 매출)
A2: 미국 | B2: 2026-10-03 | C2: https://www.appbrain.com/stats/google-play-rankings/top_grossing/game/us | D2: 1 MONOPOLY GO!, 2 Roblox, 3 Candy Crush Saga, 4 Royal Match, 5 Gossip Harbor, 6 Township, 7 Coin Master, 8 Royal Kingdom, 9 Kingshot, 10 Whiteout Survival
A3: 브라질 | B3: 2026-10-01 | C3: https://www.appbrain.com/stats/google-play-rankings/top_grossing/game/br | D3: 1 Free Fire, 2 Roblox, 3 Coin Master, 4 Gossip Harbor, 5 Candy Crush Saga, 6 eFootball, 7 Royal Match, 8 Minecraft, 9 Brawl Stars, 11 Gardenscapes
A4: 일본 | B4: 2026-10-04 | C4: https://www.appbrain.com/stats/google-play-rankings/top_grossing/game/jp | D4: 1 SD건담 G제네레이션 이터널, 2 Wuthering Waves, 3 Honkai: Star Rail, 4 홀로라이브 드림즈, 5 몬스터 스트라이크, 6 드래곤볼Z 돗칸배틀, 7 우마무스메, 8 원신, 9 Whiteout Survival, 10 디즈니 츠무츠무
A5: 한국 | B5: 2026-10-03 | C5: https://www.appbrain.com/stats/google-play-rankings/top_grossing/game/kr | D5: 1 제우스: 오만의 신, 2 리니지M, 3 Wuthering Waves, 4 이클립스: 더 어웨이크닝, 5 오딘, 6 Whiteout Survival, 7 트릭컬 리바이브, 8 메이플스토리 방치형 RPG, 9 Roblox, 10 SOL: enchant

Sheet 3-2 매출 Top100
A1: 순위 | B1: 게임명 | C1: 퍼블리셔 | D1: 대분류 | E1: 세부 장르 | F1: 비고 | H1: 대분류 | I1: 매출 Top100 수 | J1: 매출 비율 | K1: 무료 Top100 수 (1-2) | L1: 무료 비율 | M1: 차이 (매출-무료)
A2: 1 | B2: MONOPOLY GO! | C2: Scopely | D2: 카드·보드·카지노 | E2: 보드·주사위 소셜캐주얼 | H2: 퍼즐 | I2: =COUNTIF($D$2:$D$101,H2) -> 31 | J2: =I2/$I$13 -> 0.31 | K2: =COUNTIF('1-2 Google Play Top100'!$D$2:$D$101,H2) -> 53 | L2: =K2/$K$13 -> 0.53 | M2: =J2-L2 -> -0.22
A3: 2 | B3: Roblox | C3: Roblox Corporation | D3: 기타(UGC·리워드) | E3: UGC 플랫폼 | H3: 하이퍼·하이브리드 캐주얼 | I3: =COUNTIF($D$2:$D$101,H3) -> 3 | J3: =I3/$I$13 -> 0.03 | K3: =COUNTIF('1-2 Google Play Top100'!$D$2:$D$101,H3) -> 17 | L3: =K3/$K$13 -> 0.17 | M3: =J3-L3 -> -0.14
A4: 3 | B4: Candy Crush Saga | C4: King | D4: 퍼즐 | E4: 매치3 | H4: 카드·보드·카지노 | I4: =COUNTIF($D$2:$D$101,H4) -> 23 | J4: =I4/$I$13 -> 0.23 | K4: =COUNTIF('1-2 Google Play Top100'!$D$2:$D$101,H4) -> 7 | L4: =K4/$K$13 -> 0.07 | M4: =J4-L4 -> 0.16
A5: 4 | B5: Royal Match | C5: Dream Games | D5: 퍼즐 | E5: 매치3 | H5: 시뮬레이션 | I5: =COUNTIF($D$2:$D$101,H5) -> 3 | J5: =I5/$I$13 -> 0.03 | K5: =COUNTIF('1-2 Google Play Top100'!$D$2:$D$101,H5) -> 6 | L5: =K5/$K$13 -> 0.06 | M5: =J5-L5 -> -0.03
A6: 5 | B6: Gossip Harbor: Merge & Story | C6: Microfun | D6: 퍼즐 | E6: 머지 | F6: 스토리 결합 | H6: 전략 | I6: =COUNTIF($D$2:$D$101,H6) -> 17 | J6: =I6/$I$13 -> 0.17 | K6: =COUNTIF('1-2 Google Play Top100'!$D$2:$D$101,H6) -> 3 | L6: =K6/$K$13 -> 0.03 | M6: =J6-L6 -> 0.14
A7: 6 | B7: Township | C7: Playrix | D7: 시뮬레이션 | E7: 농장·타운 빌딩 | H7: 액션·슈팅 | I7: =COUNTIF($D$2:$D$101,H7) -> 4 | J7: =I7/$I$13 -> 0.04 | K7: =COUNTIF('1-2 Google Play Top100'!$D$2:$D$101,H7) -> 5 | L7: =K7/$K$13 -> 0.05 | M7: =J7-L7 -> -0.01
A8: 7 | B8: Coin Master | C8: Moon Active | D8: 카드·보드·카지노 | E8: 보드·주사위 소셜캐주얼 | H8: 스포츠 | I8: =COUNTIF($D$2:$D$101,H8) -> 2 | J8: =I8/$I$13 -> 0.02 | K8: =COUNTIF('1-2 Google Play Top100'!$D$2:$D$101,H8) -> 2 | L8: =K8/$K$13 -> 0.02 | M8: =J8-L8 -> 0
A9: 8 | B9: Kingshot | C9: Century Games | D9: 전략 | E9: 4X·SLG | H9: RPG | I9: =COUNTIF($D$2:$D$101,H9) -> 12 | J9: =I9/$I$13 -> 0.12 | K9: =COUNTIF('1-2 Google Play Top100'!$D$2:$D$101,H9) -> 2 | L9: =K9/$K$13 -> 0.02 | M9: =J9-L9 -> 0.1
A10: 9 | B10: Royal Kingdom | C10: Dream Games | D10: 퍼즐 | E10: 매치3 | H10: 파티·음악 | I10: =COUNTIF($D$2:$D$101,H10) -> 0 | J10: =I10/$I$13 -> 0 | K10: =COUNTIF('1-2 Google Play Top100'!$D$2:$D$101,H10) -> 3 | L10: =K10/$K$13 -> 0.03 | M10: =J10-L10 -> -0.03
A11: 10 | B11: Whiteout Survival | C11: Century Games | D11: 전략 | E11: 4X·SLG | H11: 기타(UGC·리워드) | I11: =COUNTIF($D$2:$D$101,H11) -> 1 | J11: =I11/$I$13 -> 0.01 | K11: =COUNTIF('1-2 Google Play Top100'!$D$2:$D$101,H11) -> 1 | L11: =K11/$K$13 -> 0.01 | M11: =J11-L11 -> 0
A12: 11 | B12: Pokémon GO | C12: Scopely Explore | D12: RPG | E12: 위치기반 수집 | H12: 확인 불가 | I12: =COUNTIF($D$2:$D$101,H12) -> 4 | J12: =I12/$I$13 -> 0.04 | K12: =COUNTIF('1-2 Google Play Top100'!$D$2:$D$101,H12) -> 1 | L12: =K12/$K$13 -> 0.01 | M12: =J12-L12 -> 0.03
A13: 12 | B13: Last War:Survival Game | C13: FUNFLY | D13: 전략 | E13: 4X·SLG | H13: 합계 | I13: =SUM(I2:I12) -> 100 | J13: =SUM(J2:J12) -> 1 | K13: =SUM(K2:K12) -> 100 | L13: =SUM(L2:L12) -> 1
A14: 13 | B14: DRAGON BALL Z DOKKAN BATTLE | C14: Bandai Namco | D14: RPG | E14: 수집형(가챠) RPG | F14: IP 활용
A15: 14 | B15: Toon Blast | C15: Peak | D15: 퍼즐 | E15: 매치3 | F15: 블라스트 | H15: 출처: AppBrain Google Play Top Grossing Games United States https://www.appbrain.com/stats/google-play-rankings/top_grossing/game/us · 기준일 2026-10-04 (AppBrain 페이지 'Last updated: October 4, 2026', 2026-10-05 조회)
A16: 15 | B16: Total Battle: War Strategy | C16: Scorewarrior | D16: 전략 | E16: 4X·SLG | H16: 26위·65위는 AppBrain 목록에 줄이 없어 '확인 불가'로 둠 (1-2 Google Play Top100의 80위와 같은 현상).
A17: 16 | B17: Last Z: Survival Shooter | C17: Omnilojo | D17: 전략 | E17: 4X·SLG | H17: 장르 분류: 1-1·1-2에 이미 있는 게임은 같은 분류를 그대로 씀. 새 게임은 게임명·스토어 카테고리 기반 분석자 판단. 확신이 낮으면 비고 '확인 필요' + 노란 칸.
A18: 17 | B18: Evony: The King's Return | C18: TG Inc. | D18: 전략 | E18: 4X·SLG | H18: 새로 생긴 세부 장르: 수집형(가챠) RPG · 방치형 RPG · 빙고 · 포커 · 골프 (1-4 세부 장르 시트에는 없음 — 1-4는 1-1·1-2만 집계).
A19: 18 | B19: RAID: Shadow Legends | C19: Plarium | D19: RPG | E19: 수집형(가챠) RPG | H19: '3-1 매출 순위 원자료'의 미국 Top10(2026-10-03)과 순서가 조금 다름 — 하루 차이. 3-1은 그대로 둠.
A20: 19 | B20: Gardenscapes | C20: Playrix | D20: 퍼즐 | E20: 매치3 | H20: App Store 매출 순위: 이번 단계 미조사. 후보 공개 출처 — AppBrain App Store ranking https://www.appbrain.com/stats/appstore-rankings (다음 단계 확인 필요).
A21: 20 | B21: Dice Dreams | C21: SuperPlay | D21: 카드·보드·카지노 | E21: 보드·주사위 소셜캐주얼 | H21: 무료 비율 열은 1-2(같은 날 2026-10-04 미국 무료 Top100)를 수식으로 세어 비교한 것.
A22: 21 | B22: Bingo Blitz - Bingo Games | C22: Playtika Santa Monica | D22: 카드·보드·카지노 | E22: 빙고
A23: 22 | B23: Jackpot Party Casino Slots | C23: SciPlay | D23: 카드·보드·카지노 | E23: 소셜 카지노
A24: 23 | B24: Last Asylum: Plague | C24: 37GAMES GLOBAL | D24: 전략 | E24: 4X·SLG | F24: 확인 필요
A25: 24 | B25: Fishdom | C25: Playrix | D25: 퍼즐 | E25: 매치3
A26: 25 | B26: Cashman Casino Slots Games | C26: Product Madness | D26: 카드·보드·카지노 | E26: 소셜 카지노
A27: 26 | B27: 확인 불가 (AppBrain 목록에 26위 없음) | C27: - | D27: 확인 불가 | E27: - | F27: 출처 페이지 누락
A28: 27 | B28: Match Factory! | C28: Peak | D28: 퍼즐 | E28: 타일·마작·트리플 매치 | F28: 3D 트리플 매치
A29: 28 | B29: Free Fire x NARUTO SHIPPUDEN | C29: Garena | D29: 액션·슈팅 | E29: 배틀로얄
A30: 29 | B30: Pokémon TCG Pocket | C30: The Pokémon Company | D30: 카드·보드·카지노 | E30: 트레이딩 카드 | F30: 디지털 TCG
A31: 30 | B31: Tasty Travels: Merge Game | C31: Century Games | D31: 퍼즐 | E31: 머지
A32: 31 | B32: Clash of Clans | C32: Supercell | D32: 전략 | E32: 4X·SLG | F32: 기지 건설·공성
A33: 32 | B33: Candy Crush Soda Saga | C33: King | D33: 퍼즐 | E33: 매치3
A34: 33 | B34: Lightning Link Casino Slots | C34: Product Madness | D34: 카드·보드·카지노 | E34: 소셜 카지노
A35: 34 | B35: Sword x Staff | C35: BOLTRAY GAMES | D35: RPG | E35: 방치형 RPG | F35: 확인 필요
A36: 35 | B36: Pixel Flow! | C36: Loom Games | D36: 퍼즐 | E36: 픽셀·컬러 아트
A37: 36 | B37: Lotsa Slots - Casino Games | C37: SpinX Games | D37: 카드·보드·카지노 | E37: 소셜 카지노
A38: 37 | B38: Homescapes | C38: Playrix | D38: 퍼즐 | E38: 매치3
A39: 38 | B39: Dark War Survival | C39: Omnilojo | D39: 전략 | E39: 4X·SLG
A40: 39 | B40: Yarn Loop | C40: Combo Game | D40: 퍼즐 | E40: 정렬·잼 | F40: 확인 필요
...

Sheet 3-3 매출-다운로드 비교
A1: 미국 구글 플레이: 매출 순위 vs 무료(다운로드) 순위 — 같은 날(2026-10-04) 두 차트를 합친 목록
A2: 매출 '높음' 기준 (매출 순위가 이 숫자 이내) | B2: 30 | C2: ← 파란 글씨 = 바꿀 수 있는 가정값(분석자 제안). 바꾸면 H열 분류가 자동으로 바뀜
A3: 다운로드 '높음' 기준 (무료 순위가 이 숫자 이내) | B3: 30
A5: 게임명 | B5: 매출 순위 | C5: 무료 순위 | D5: AppBrain 추정 누적 설치 수 (추정) | E5: 추정 설치 구간 (수식) | F5: Google Play 공식 설치 구간 | G5: 출시일 (Google Play 등록) | H5: 분류 (수식) | I5: 비고 | K5: 분류 | L5: 게임 수 | M5: 쉬운 뜻
A6: MONOPOLY GO! | B6: 1 | C6: 26 | D6: 130000000 | E6: =IF(D6="","",IF(D6>=1000000000,"1B+",IF(D6>=500000000,"500M+",IF(D6>=100000000,"100M+",IF(D6>=50000000,"50M+",IF(D6>=10000000,"10M+",IF(D6>=5000000,"5M+",IF(D6>=1000000,"1M+","1M 미만")))))))) -> 100M+ | F6: 미조사 | G6: 미조사 | H6: =IF(AND(ISNUMBER(B6),B6<=$B$2,ISNUMBER(C6),C6<=$B$3),"① 둘 다 높음",IF(AND(ISNUMBER(B6),B6<=$B$2),"② 매출만 높음",IF(AND(ISNUMBER(C6),C6<=$B$3),"③ 다운로드만 높음","④ 둘 다 기준 밖"))) -> ① 둘 다 높음 | K6: ① 둘 다 높음 | L6: =COUNTIF($H$6:$H$177,K6) -> 4 | M6: 많이 받고 돈도 많이 버는 게임
A7: Roblox | B7: 2 | C7: 4 | D7: 1700000000 | E7: =IF(D7="","",IF(D7>=1000000000,"1B+",IF(D7>=500000000,"500M+",IF(D7>=100000000,"100M+",IF(D7>=50000000,"50M+",IF(D7>=10000000,"10M+",IF(D7>=5000000,"5M+",IF(D7>=1000000,"1M+","1M 미만")))))))) -> 1B+ | F7: 미조사 | G7: 미조사 | H7: =IF(AND(ISNUMBER(B7),B7<=$B$2,ISNUMBER(C7),C7<=$B$3),"① 둘 다 높음",IF(AND(ISNUMBER(B7),B7<=$B$2),"② 매출만 높음",IF(AND(ISNUMBER(C7),C7<=$B$3),"③ 다운로드만 높음","④ 둘 다 기준 밖"))) -> ① 둘 다 높음 | K7: ② 매출만 높음 | L7: =COUNTIF($H$6:$H$177,K7) -> 25 | M7: 받는 사람은 적어도 결제를 많이 하는 게임 (인앱 결제형)
A8: Candy Crush Saga | B8: 3 | C8: 48 | D8: 2300000000 | E8: =IF(D8="","",IF(D8>=1000000000,"1B+",IF(D8>=500000000,"500M+",IF(D8>=100000000,"100M+",IF(D8>=50000000,"50M+",IF(D8>=10000000,"10M+",IF(D8>=5000000,"5M+",IF(D8>=1000000,"1M+","1M 미만")))))))) -> 1B+ | F8: 미조사 | G8: 미조사 | H8: =IF(AND(ISNUMBER(B8),B8<=$B$2,ISNUMBER(C8),C8<=$B$3),"① 둘 다 높음",IF(AND(ISNUMBER(B8),B8<=$B$2),"② 매출만 높음",IF(AND(ISNUMBER(C8),C8<=$B$3),"③ 다운로드만 높음","④ 둘 다 기준 밖"))) -> ② 매출만 높음 | K8: ③ 다운로드만 높음 | L8: =COUNTIF($H$6:$H$177,K8) -> 26 | M8: 많이 받지만 결제 순위는 낮은 게임 — 광고 수익형일 가능성 (추정)
A9: Royal Match | B9: 4 | C9: 42 | D9: 370000000 | E9: =IF(D9="","",IF(D9>=1000000000,"1B+",IF(D9>=500000000,"500M+",IF(D9>=100000000,"100M+",IF(D9>=50000000,"50M+",IF(D9>=10000000,"10M+",IF(D9>=5000000,"5M+",IF(D9>=1000000,"1M+","1M 미만")))))))) -> 100M+ | F9: 미조사 | G9: 미조사 | H9: =IF(AND(ISNUMBER(B9),B9<=$B$2,ISNUMBER(C9),C9<=$B$3),"① 둘 다 높음",IF(AND(ISNUMBER(B9),B9<=$B$2),"② 매출만 높음",IF(AND(ISNUMBER(C9),C9<=$B$3),"③ 다운로드만 높음","④ 둘 다 기준 밖"))) -> ② 매출만 높음 | K9: ④ 둘 다 기준 밖 | L9: =COUNTIF($H$6:$H$177,K9) -> 117 | M9: 두 차트 Top100 안이지만 기준 순위 밖
A10: Gossip Harbor: Merge & Story | B10: 5 | C10: 17 | D10: 91000000 | E10: =IF(D10="","",IF(D10>=1000000000,"1B+",IF(D10>=500000000,"500M+",IF(D10>=100000000,"100M+",IF(D10>=50000000,"50M+",IF(D10>=10000000,"10M+",IF(D10>=5000000,"5M+",IF(D10>=1000000,"1M+","1M 미만")))))))) -> 50M+ | F10: 미조사 | G10: 미조사 | H10: =IF(AND(ISNUMBER(B10),B10<=$B$2,ISNUMBER(C10),C10<=$B$3),"① 둘 다 높음",IF(AND(ISNUMBER(B10),B10<=$B$2),"② 매출만 높음",IF(AND(ISNUMBER(C10),C10<=$B$3),"③ 다운로드만 높음","④ 둘 다 기준 밖"))) -> ① 둘 다 높음 | K10: 합계 | L10: =SUM(L6:L9) -> 172
A11: Township | B11: 6 | C11: 22 | D11: 520000000 | E11: =IF(D11="","",IF(D11>=1000000000,"1B+",IF(D11>=500000000,"500M+",IF(D11>=100000000,"100M+",IF(D11>=50000000,"50M+",IF(D11>=10000000,"10M+",IF(D11>=5000000,"5M+",IF(D11>=1000000,"1M+","1M 미만")))))))) -> 500M+ | F11: 미조사 | G11: 미조사 | H11: =IF(AND(ISNUMBER(B11),B11<=$B$2,ISNUMBER(C11),C11<=$B$3),"① 둘 다 높음",IF(AND(ISNUMBER(B11),B11<=$B$2),"② 매출만 높음",IF(AND(ISNUMBER(C11),C11<=$B$3),"③ 다운로드만 높음","④ 둘 다 기준 밖"))) -> ① 둘 다 높음
A12: Coin Master | B12: 7 | C12: - | D12: 350000000 | E12: =IF(D12="","",IF(D12>=1000000000,"1B+",IF(D12>=500000000,"500M+",IF(D12>=100000000,"100M+",IF(D12>=50000000,"50M+",IF(D12>=10000000,"10M+",IF(D12>=5000000,"5M+",IF(D12>=1000000,"1M+","1M 미만")))))))) -> 100M+ | F12: 미조사 | G12: 미조사 | H12: =IF(AND(ISNUMBER(B12),B12<=$B$2,ISNUMBER(C12),C12<=$B$3),"① 둘 다 높음",IF(AND(ISNUMBER(B12),B12<=$B$2),"② 매출만 높음",IF(AND(ISNUMBER(C12),C12<=$B$3),"③ 다운로드만 높음","④ 둘 다 기준 밖"))) -> ② 매출만 높음 | K12: 출처: 매출 순위 — AppBrain Google Play Top Grossing Games United States https://www.appbrain.com/stats/google-play-rankings/top_grossing/game/us / 무료 순위 — AppBrain Google Play Top Free Games United States https://www.appbrain.com/stats/google-play-rankings/top_free/game/us (둘 다 2026-10-04, 1-2와 같은 날 같은 목록)
A13: Kingshot | B13: 8 | C13: - | D13: 59000000 | E13: =IF(D13="","",IF(D13>=1000000000,"1B+",IF(D13>=500000000,"500M+",IF(D13>=100000000,"100M+",IF(D13>=50000000,"50M+",IF(D13>=10000000,"10M+",IF(D13>=5000000,"5M+",IF(D13>=1000000,"1M+","1M 미만")))))))) -> 50M+ | F13: 50,000,000+ | G13: 2025-02 (Google Play 등록 월) | H13: =IF(AND(ISNUMBER(B13),B13<=$B$2,ISNUMBER(C13),C13<=$B$3),"① 둘 다 높음",IF(AND(ISNUMBER(B13),B13<=$B$2),"② 매출만 높음",IF(AND(ISNUMBER(C13),C13<=$B$3),"③ 다운로드만 높음","④ 둘 다 기준 밖"))) -> ② 매출만 높음 | I13: AppBrain 앱 상세 https://www.appbrain.com/app/kingshot/com.run.tower.defense (페이지 갱신 2026-09-20) | K13: '-' = 그 차트 Top100 밖(또는 AppBrain 목록 누락: 매출 26·65위, 무료 80위). 순위 숫자만 비교함.
A14: Royal Kingdom | B14: 9 | C14: 47 | D14: 110000000 | E14: =IF(D14="","",IF(D14>=1000000000,"1B+",IF(D14>=500000000,"500M+",IF(D14>=100000000,"100M+",IF(D14>=50000000,"50M+",IF(D14>=10000000,"10M+",IF(D14>=5000000,"5M+",IF(D14>=1000000,"1M+","1M 미만")))))))) -> 100M+ | F14: 미조사 | G14: 미조사 | H14: =IF(AND(ISNUMBER(B14),B14<=$B$2,ISNUMBER(C14),C14<=$B$3),"① 둘 다 높음",IF(AND(ISNUMBER(B14),B14<=$B$2),"② 매출만 높음",IF(AND(ISNUMBER(C14),C14<=$B$3),"③ 다운로드만 높음","④ 둘 다 기준 밖"))) -> ② 매출만 높음 | K14: D열 '추정 누적 설치 수'는 AppBrain이 공개한 추정치(Installs 열)이며 Google Play 공식 숫자가 아님. E열은 그 추정치를 Google Play식 구간으로 나눈 것(역시 추정).
A15: Whiteout Survival | B15: 10 | C15: 63 | D15: 100000000 | E15: =IF(D15="","",IF(D15>=1000000000,"1B+",IF(D15>=500000000,"500M+",IF(D15>=100000000,"100M+",IF(D15>=50000000,"50M+",IF(D15>=10000000,"10M+",IF(D15>=5000000,"5M+",IF(D15>=1000000,"1M+","1M 미만")))))))) -> 100M+ | F15: 미조사 | G15: 미조사 | H15: =IF(AND(ISNUMBER(B15),B15<=$B$2,ISNUMBER(C15),C15<=$B$3),"① 둘 다 높음",IF(AND(ISNUMBER(B15),B15<=$B$2),"② 매출만 높음",IF(AND(ISNUMBER(C15),C15<=$B$3),"③ 다운로드만 높음","④ 둘 다 기준 밖"))) -> ② 매출만 높음 | K15: F·G열(공식 설치 구간·출시일)은 게임별 상세 페이지를 하나씩 열어야 해서 이번에는 Kingshot 1개만 확인. 나머지는 '미조사'(다음 단계).
A16: Pokémon GO | B16: 11 | C16: - | D16: 560000000 | E16: =IF(D16="","",IF(D16>=1000000000,"1B+",IF(D16>=500000000,"500M+",IF(D16>=100000000,"100M+",IF(D16>=50000000,"50M+",IF(D16>=10000000,"10M+",IF(D16>=5000000,"5M+",IF(D16>=1000000,"1M+","1M 미만")))))))) -> 500M+ | F16: 미조사 | G16: 미조사 | H16: =IF(AND(ISNUMBER(B16),B16<=$B$2,ISNUMBER(C16),C16<=$B$3),"① 둘 다 높음",IF(AND(ISNUMBER(B16),B16<=$B$2),"② 매출만 높음",IF(AND(ISNUMBER(C16),C16<=$B$3),"③ 다운로드만 높음","④ 둘 다 기준 밖"))) -> ② 매출만 높음 | K16: 실제 매출액·실제 다운로드 수: 비공개 (공개 출처 없음). 이 표는 순위와 공개 추정치로만 비교함.
A17: Last War:Survival Game | B17: 12 | C17: - | D17: 110000000 | E17: =IF(D17="","",IF(D17>=1000000000,"1B+",IF(D17>=500000000,"500M+",IF(D17>=100000000,"100M+",IF(D17>=50000000,"50M+",IF(D17>=10000000,"10M+",IF(D17>=5000000,"5M+",IF(D17>=1000000,"1M+","1M 미만")))))))) -> 100M+ | F17: 미조사 | G17: 미조사 | H17: =IF(AND(ISNUMBER(B17),B17<=$B$2,ISNUMBER(C17),C17<=$B$3),"① 둘 다 높음",IF(AND(ISNUMBER(B17),B17<=$B$2),"② 매출만 높음",IF(AND(ISNUMBER(C17),C17<=$B$3),"③ 다운로드만 높음","④ 둘 다 기준 밖"))) -> ② 매출만 높음 | K17: ③ '광고 수익형'은 순위 패턴에서 나온 추정이며, 실제 수익 구조는 게임별 확인이 필요함.
